package appalachia.rtg.world.gen.feature.tree.rtg;

import java.util.ArrayList;
import java.util.Random;

import net.minecraft.block.BlockLeaves;
import net.minecraft.block.BlockLog;
import net.minecraft.block.state.IBlockState;
import net.minecraft.util.math.BlockPos;
import net.minecraft.world.World;

import appalachia.api.AppalachiaBlocks;

/**
 * Celtis Occidentalis (Hackberry)
 * <p>
 * This tree was designed by Lentebriesje and released as part of the 'Custom Tree Repository' project
 * on Planet Minecraft (http://www.planetminecraft.com/project/native-trees-of-europe-template-repository-1779952/).
 * It was converted into Java from its original schematic using the 'Schematic To Java Converter [For Modders]' program
 * by ThisIsMika (http://www.minecraftforum.net/forums/mapping-and-modding/minecraft-tools/2193206-schematic-to-java-converter-for-modders).
 * It has been modified slightly by WhichOnesPink to allow for random variation when generating in the world.
 */
public class TreeCeltisOccidentalis extends AppalachiaTree {

    World world;
    Random rand;
    boolean shortVersion = false;

    public TreeCeltisOccidentalis() {
        super();
        this.setLogBlock(AppalachiaBlocks.log_hackberry_01.getDefaultState());
        this.setLeavesBlock(AppalachiaBlocks.leaves_hackberry_01.getDefaultState());
        this.setFallenLeavesBlock(AppalachiaBlocks.leaves_hackberry_01_fallen.getDefaultState());
        this.setSaplingBlock(AppalachiaBlocks.sapling_hackberry_01.getDefaultState());
    }

    public TreeCeltisOccidentalis(boolean shortVersion) {
        this();
        this.shortVersion = shortVersion;
    }

    @Override
    public boolean generate(World world, Random rand, BlockPos pos) {

        this.crownSize = this.getSizeFromMinMax(rand, this.minCrownSize, this.maxCrownSize);
        this.trunkSize = this.getSizeFromMinMax(rand, this.minTrunkSize, this.maxTrunkSize);

        this.world = world;
        this.rand = rand;
        int x = pos.getX();
        int y = pos.getY();
        int z = pos.getZ();

        ArrayList<BlockPos> groundPos = new ArrayList<BlockPos>(){};

        if (shortVersion) {
            groundPos.add(new BlockPos(x+6, y, z+5));
            groundPos.add(new BlockPos(x+4, y, z+6));
            groundPos.add(new BlockPos(x+5, y, z+6));
            groundPos.add(new BlockPos(x+6, y, z+6));
            groundPos.add(new BlockPos(x+5, y, z+7));
            groundPos.add(new BlockPos(x+6, y, z+7));
            groundPos.add(new BlockPos(x+6, y, z+8));
        }
        else {
            groundPos.add(new BlockPos(x+8, y, z+9));
            groundPos.add(new BlockPos(x+8, y, z+10));
            groundPos.add(new BlockPos(x+10, y, z+10));
            groundPos.add(new BlockPos(x+9, y, z+11));
            groundPos.add(new BlockPos(x+10, y, z+11));
            groundPos.add(new BlockPos(x+9, y, z+12));
            groundPos.add(new BlockPos(x+10, y, z+12));
            groundPos.add(new BlockPos(x+12, y, z+12));
            groundPos.add(new BlockPos(x+8, y, z+13));
            groundPos.add(new BlockPos(x+10, y, z+13));
            groundPos.add(new BlockPos(x+11, y, z+13));
            groundPos.add(new BlockPos(x+9, y, z+14));
        }

        for (int i = 0; i < groundPos.size(); i++) {
            if (!isValidGroundBlock(world, rand, groundPos.get(i), 1)) {
                return false;
            }
        }

        IBlockState leaves = this.leavesBlock.withProperty(BlockLeaves.CHECK_DECAY, false);
        //IBlockState leaves = this.leavesBlock.withProperty(BlockLeaves.DECAYABLE, false);

        if (shortVersion) {
            this.spawnShort(world, x, y - 2, z, this.logBlock, leaves);
        }
        else {
            this.spawn(world, x, y - 2, z, this.logBlock, leaves);
        }

        return true;
    }

    protected void spawn(World world, int x, int y, int z, IBlockState log, IBlockState leaves) {

        int currentY = y;

        this.setBlockState(new BlockPos(x+9, y+0, z+11), log.withProperty(BlockLog.LOG_AXIS, BlockLog.EnumAxis.NONE));
        this.setBlockMetadataWithNotify(x+9, y+0, z+11, 12, 12);
        this.setBlockState(new BlockPos(x+12, y+0, z+12), log.withProperty(BlockLog.LOG_AXIS, BlockLog.EnumAxis.NONE));
        this.setBlockMetadataWithNotify(x+12, y+0, z+12, 12, 12);
        this.setBlockState(new BlockPos(x+8, y+0, z+13), log.withProperty(BlockLog.LOG_AXIS, BlockLog.EnumAxis.NONE));
        this.setBlockMetadataWithNotify(x+8, y+0, z+13, 12, 12);
        this.setBlockState(new BlockPos(x+10, y+0, z+13), log.withProperty(BlockLog.LOG_AXIS, BlockLog.EnumAxis.NONE));
        this.setBlockMetadataWithNotify(x+10, y+0, z+13, 12, 12);
        this.setBlockState(new BlockPos(x+8, y+1, z+10), log.withProperty(BlockLog.LOG_AXIS, BlockLog.EnumAxis.NONE));
        this.setBlockMetadataWithNotify(x+8, y+1, z+10, 12, 12);
        this.setBlockState(new BlockPos(x+9, y+1, z+11), log.withProperty(BlockLog.LOG_AXIS, BlockLog.EnumAxis.NONE));
        this.setBlockMetadataWithNotify(x+9, y+1, z+11, 12, 12);
        this.setBlockState(new BlockPos(x+10, y+1, z+12), log.withProperty(BlockLog.LOG_AXIS, BlockLog.EnumAxis.NONE));
        this.setBlockMetadataWithNotify(x+10, y+1, z+12, 12, 12);
        this.setBlockState(new BlockPos(x+12, y+1, z+12), log.withProperty(BlockLog.LOG_AXIS, BlockLog.EnumAxis.NONE));
        this.setBlockMetadataWithNotify(x+12, y+1, z+12, 12, 12);
        this.setBlockState(new BlockPos(x+8, y+1, z+13), log.withProperty(BlockLog.LOG_AXIS, BlockLog.EnumAxis.NONE));
        this.setBlockMetadataWithNotify(x+8, y+1, z+13, 12, 12);
        this.setBlockState(new BlockPos(x+10, y+1, z+13), log.withProperty(BlockLog.LOG_AXIS, BlockLog.EnumAxis.NONE));
        this.setBlockMetadataWithNotify(x+10, y+1, z+13, 12, 12);
        this.setBlockState(new BlockPos(x+11, y+1, z+13), log.withProperty(BlockLog.LOG_AXIS, BlockLog.EnumAxis.NONE));
        this.setBlockMetadataWithNotify(x+11, y+1, z+13, 12, 12);
        this.setBlockState(new BlockPos(x+9, y+1, z+14), log.withProperty(BlockLog.LOG_AXIS, BlockLog.EnumAxis.NONE));
        this.setBlockMetadataWithNotify(x+9, y+1, z+14, 12, 12);
        this.setBlockState(new BlockPos(x+8, y+2, z+9), log.withProperty(BlockLog.LOG_AXIS, BlockLog.EnumAxis.NONE));
        this.setBlockMetadataWithNotify(x+8, y+2, z+9, 12, 12);
        this.setBlockState(new BlockPos(x+8, y+2, z+10), log.withProperty(BlockLog.LOG_AXIS, BlockLog.EnumAxis.NONE));
        this.setBlockMetadataWithNotify(x+8, y+2, z+10, 12, 12);
        this.setBlockState(new BlockPos(x+10, y+2, z+10), log.withProperty(BlockLog.LOG_AXIS, BlockLog.EnumAxis.NONE));
        this.setBlockMetadataWithNotify(x+10, y+2, z+10, 12, 12);
        this.setBlockState(new BlockPos(x+9, y+2, z+11), log.withProperty(BlockLog.LOG_AXIS, BlockLog.EnumAxis.NONE));
        this.setBlockMetadataWithNotify(x+9, y+2, z+11, 12, 12);
        this.setBlockState(new BlockPos(x+10, y+2, z+11), log.withProperty(BlockLog.LOG_AXIS, BlockLog.EnumAxis.NONE));
        this.setBlockMetadataWithNotify(x+10, y+2, z+11, 12, 12);
        this.setBlockState(new BlockPos(x+9, y+2, z+12), log.withProperty(BlockLog.LOG_AXIS, BlockLog.EnumAxis.NONE));
        this.setBlockMetadataWithNotify(x+9, y+2, z+12, 12, 12);
        this.setBlockState(new BlockPos(x+10, y+2, z+12), log.withProperty(BlockLog.LOG_AXIS, BlockLog.EnumAxis.NONE));
        this.setBlockMetadataWithNotify(x+10, y+2, z+12, 12, 12);
        this.setBlockState(new BlockPos(x+12, y+2, z+12), log.withProperty(BlockLog.LOG_AXIS, BlockLog.EnumAxis.NONE));
        this.setBlockMetadataWithNotify(x+12, y+2, z+12, 12, 12);
        this.setBlockState(new BlockPos(x+8, y+2, z+13), log.withProperty(BlockLog.LOG_AXIS, BlockLog.EnumAxis.NONE));
        this.setBlockMetadataWithNotify(x+8, y+2, z+13, 12, 12);
        this.setBlockState(new BlockPos(x+10, y+2, z+13), log.withProperty(BlockLog.LOG_AXIS, BlockLog.EnumAxis.NONE));
        this.setBlockMetadataWithNotify(x+10, y+2, z+13, 12, 12);
        this.setBlockState(new BlockPos(x+11, y+2, z+13), log.withProperty(BlockLog.LOG_AXIS, BlockLog.EnumAxis.NONE));
        this.setBlockMetadataWithNotify(x+11, y+2, z+13, 12, 12);
        this.setBlockState(new BlockPos(x+9, y+2, z+14), log.withProperty(BlockLog.LOG_AXIS, BlockLog.EnumAxis.NONE));
        this.setBlockMetadataWithNotify(x+9, y+2, z+14, 12, 12);
        this.setBlockState(new BlockPos(x+8, y+3, z+9), log.withProperty(BlockLog.LOG_AXIS, BlockLog.EnumAxis.NONE));
        this.setBlockMetadataWithNotify(x+8, y+3, z+9, 12, 12);
        this.setBlockState(new BlockPos(x+8, y+3, z+10), log.withProperty(BlockLog.LOG_AXIS, BlockLog.EnumAxis.NONE));
        this.setBlockMetadataWithNotify(x+8, y+3, z+10, 12, 12);
        this.setBlockState(new BlockPos(x+10, y+3, z+10), log.withProperty(BlockLog.LOG_AXIS, BlockLog.EnumAxis.NONE));
        this.setBlockMetadataWithNotify(x+10, y+3, z+10, 12, 12);
        this.setBlockState(new BlockPos(x+9, y+3, z+11), log.withProperty(BlockLog.LOG_AXIS, BlockLog.EnumAxis.NONE));
        this.setBlockMetadataWithNotify(x+9, y+3, z+11, 12, 12);
        this.setBlockState(new BlockPos(x+9, y+3, z+12), log.withProperty(BlockLog.LOG_AXIS, BlockLog.EnumAxis.NONE));
        this.setBlockMetadataWithNotify(x+9, y+3, z+12, 12, 12);
        this.setBlockState(new BlockPos(x+10, y+3, z+12), log.withProperty(BlockLog.LOG_AXIS, BlockLog.EnumAxis.NONE));
        this.setBlockMetadataWithNotify(x+10, y+3, z+12, 12, 12);
        this.setBlockState(new BlockPos(x+12, y+3, z+12), log.withProperty(BlockLog.LOG_AXIS, BlockLog.EnumAxis.NONE));
        this.setBlockMetadataWithNotify(x+12, y+3, z+12, 12, 12);
        this.setBlockState(new BlockPos(x+8, y+3, z+13), log.withProperty(BlockLog.LOG_AXIS, BlockLog.EnumAxis.NONE));
        this.setBlockMetadataWithNotify(x+8, y+3, z+13, 12, 12);
        this.setBlockState(new BlockPos(x+9, y+3, z+13), log.withProperty(BlockLog.LOG_AXIS, BlockLog.EnumAxis.NONE));
        this.setBlockMetadataWithNotify(x+9, y+3, z+13, 12, 12);
        this.setBlockState(new BlockPos(x+10, y+3, z+13), log.withProperty(BlockLog.LOG_AXIS, BlockLog.EnumAxis.NONE));
        this.setBlockMetadataWithNotify(x+10, y+3, z+13, 12, 12);
        this.setBlockState(new BlockPos(x+11, y+3, z+13), log.withProperty(BlockLog.LOG_AXIS, BlockLog.EnumAxis.NONE));
        this.setBlockMetadataWithNotify(x+11, y+3, z+13, 12, 12);
        this.setBlockState(new BlockPos(x+9, y+3, z+14), log.withProperty(BlockLog.LOG_AXIS, BlockLog.EnumAxis.NONE));
        this.setBlockMetadataWithNotify(x+9, y+3, z+14, 12, 12);
        this.setBlockState(new BlockPos(x+9, y+4, z+12), log);
        this.setBlockState(new BlockPos(x+10, y+4, z+12), log);
        this.setBlockState(new BlockPos(x+9, y+4, z+13), log);
        this.setBlockState(new BlockPos(x+10, y+4, z+13), log);
        this.setBlockState(new BlockPos(x+9, y+5, z+12), log);
        this.setBlockState(new BlockPos(x+10, y+5, z+12), log);
        this.setBlockState(new BlockPos(x+9, y+5, z+13), log);
        this.setBlockState(new BlockPos(x+10, y+5, z+13), log);
        this.setBlockState(new BlockPos(x+6, y+6, z+11), leaves);
        this.setBlockMetadataWithNotify(x+6, y+6, z+11, 4, 4);
        this.setBlockState(new BlockPos(x+8, y+6, z+12), leaves);
        this.setBlockMetadataWithNotify(x+8, y+6, z+12, 4, 4);
        this.setBlockState(new BlockPos(x+9, y+6, z+12), log);
        this.setBlockState(new BlockPos(x+10, y+6, z+12), log);
        this.setBlockState(new BlockPos(x+9, y+6, z+13), log);
        this.setBlockState(new BlockPos(x+10, y+6, z+13), log);
        this.setBlockState(new BlockPos(x+10, y+6, z+14), log);
        this.setBlockState(new BlockPos(x+8, y+6, z+18), leaves);
        this.setBlockMetadataWithNotify(x+8, y+6, z+18, 4, 4);
        this.setBlockState(new BlockPos(x+2, y+7, z+5), leaves);
        this.setBlockMetadataWithNotify(x+2, y+7, z+5, 4, 4);
        this.setBlockState(new BlockPos(x+3, y+7, z+6), leaves);
        this.setBlockState(new BlockPos(x+3, y+7, z+7), leaves);
        this.setBlockMetadataWithNotify(x+3, y+7, z+7, 4, 4);
        this.setBlockState(new BlockPos(x+4, y+7, z+7), leaves);
        this.setBlockMetadataWithNotify(x+4, y+7, z+7, 4, 4);
        this.setBlockState(new BlockPos(x+5, y+7, z+8), leaves);
        this.setBlockMetadataWithNotify(x+5, y+7, z+8, 4, 4);
        this.setBlockState(new BlockPos(x+7, y+7, z+8), leaves);
        this.setBlockMetadataWithNotify(x+7, y+7, z+8, 4, 4);
        this.setBlockState(new BlockPos(x+7, y+7, z+9), leaves);
        this.setBlockMetadataWithNotify(x+7, y+7, z+9, 4, 4);
        this.setBlockState(new BlockPos(x+7, y+7, z+11), leaves);
        this.setBlockMetadataWithNotify(x+7, y+7, z+11, 4, 4);
        this.setBlockState(new BlockPos(x+9, y+7, z+11), log);
        this.setBlockState(new BlockPos(x+10, y+7, z+11), log);
        this.setBlockState(new BlockPos(x+5, y+7, z+12), leaves);
        this.setBlockMetadataWithNotify(x+5, y+7, z+12, 8, 8);
        this.setBlockState(new BlockPos(x+9, y+7, z+12), log);
        this.setBlockState(new BlockPos(x+10, y+7, z+12), log);
        this.setBlockState(new BlockPos(x+7, y+7, z+13), leaves);
        this.setBlockMetadataWithNotify(x+7, y+7, z+13, 4, 4);
        this.setBlockState(new BlockPos(x+8, y+7, z+13), log);
        this.setBlockState(new BlockPos(x+9, y+7, z+13), log);
        this.setBlockState(new BlockPos(x+10, y+7, z+13), log);
        this.setBlockState(new BlockPos(x+11, y+7, z+13), log);
        this.setBlockState(new BlockPos(x+10, y+7, z+14), log);
        this.setBlockState(new BlockPos(x+11, y+7, z+14), log);
        this.setBlockState(new BlockPos(x+8, y+7, z+17), leaves);
        this.setBlockMetadataWithNotify(x+8, y+7, z+17, 4, 4);
        this.setBlockState(new BlockPos(x+9, y+7, z+17), leaves);
        this.setBlockMetadataWithNotify(x+9, y+7, z+17, 4, 4);
        this.setBlockState(new BlockPos(x+7, y+7, z+18), leaves);
        this.setBlockMetadataWithNotify(x+7, y+7, z+18, 4, 4);
        this.setBlockState(new BlockPos(x+8, y+7, z+19), leaves);
        this.setBlockMetadataWithNotify(x+8, y+7, z+19, 4, 4);
        this.setBlockState(new BlockPos(x+8, y+7, z+20), leaves);
        this.setBlockMetadataWithNotify(x+8, y+7, z+20, 4, 4);
        this.setBlockState(new BlockPos(x+7, y+7, z+21), leaves);
        this.setBlockMetadataWithNotify(x+7, y+7, z+21, 4, 4);
        this.setBlockState(new BlockPos(x+7, y+8, z+6), leaves);
        this.setBlockMetadataWithNotify(x+7, y+8, z+6, 4, 4);
        this.setBlockState(new BlockPos(x+5, y+8, z+7), leaves);
        this.setBlockMetadataWithNotify(x+5, y+8, z+7, 4, 4);
        this.setBlockState(new BlockPos(x+6, y+8, z+7), leaves);
        this.setBlockMetadataWithNotify(x+6, y+8, z+7, 4, 4);
        this.setBlockState(new BlockPos(x+2, y+8, z+8), leaves);
        this.setBlockMetadataWithNotify(x+2, y+8, z+8, 4, 4);
        this.setBlockState(new BlockPos(x+3, y+8, z+10), leaves);
        this.setBlockMetadataWithNotify(x+3, y+8, z+10, 4, 4);
        this.setBlockState(new BlockPos(x+5, y+8, z+10), leaves);
        this.setBlockMetadataWithNotify(x+5, y+8, z+10, 4, 4);
        this.setBlockState(new BlockPos(x+6, y+8, z+10), leaves);
        this.setBlockMetadataWithNotify(x+6, y+8, z+10, 4, 4);
        this.setBlockState(new BlockPos(x+8, y+8, z+10), leaves);
        this.setBlockMetadataWithNotify(x+8, y+8, z+10, 4, 4);
        this.setBlockState(new BlockPos(x+5, y+8, z+11), leaves);
        this.setBlockMetadataWithNotify(x+5, y+8, z+11, 12, 12);
        this.setBlockState(new BlockPos(x+6, y+8, z+11), leaves);
        this.setBlockMetadataWithNotify(x+6, y+8, z+11, 12, 12);
        this.setBlockState(new BlockPos(x+8, y+8, z+11), log);
        this.setBlockState(new BlockPos(x+9, y+8, z+11), log);
        this.setBlockState(new BlockPos(x+10, y+8, z+11), log);
        this.setBlockState(new BlockPos(x+8, y+8, z+12), log);
        this.setBlockState(new BlockPos(x+9, y+8, z+12), log);
        this.setBlockState(new BlockPos(x+10, y+8, z+12), log);
        this.setBlockState(new BlockPos(x+5, y+8, z+13), leaves);
        this.setBlockMetadataWithNotify(x+5, y+8, z+13, 12, 12);
        this.setBlockState(new BlockPos(x+9, y+8, z+13), log);
        this.setBlockState(new BlockPos(x+10, y+8, z+13), log);
        this.setBlockState(new BlockPos(x+10, y+8, z+14), log);
        this.setBlockState(new BlockPos(x+11, y+8, z+14), log);
        this.setBlockState(new BlockPos(x+11, y+8, z+15), log);
        this.setBlockState(new BlockPos(x+8, y+8, z+17), leaves);
        this.setBlockMetadataWithNotify(x+8, y+8, z+17, 4, 4);
        this.setBlockState(new BlockPos(x+8, y+8, z+18), leaves);
        this.setBlockMetadataWithNotify(x+8, y+8, z+18, 4, 4);
        this.setBlockState(new BlockPos(x+11, y+8, z+19), leaves);
        this.setBlockMetadataWithNotify(x+11, y+8, z+19, 4, 4);
        this.setBlockState(new BlockPos(x+5, y+8, z+20), leaves);
        this.setBlockMetadataWithNotify(x+5, y+8, z+20, 4, 4);
        this.setBlockState(new BlockPos(x+8, y+8, z+20), leaves);
        this.setBlockMetadataWithNotify(x+8, y+8, z+20, 4, 4);
        this.setBlockState(new BlockPos(x+7, y+8, z+21), leaves);
        this.setBlockMetadataWithNotify(x+7, y+8, z+21, 4, 4);
        this.setBlockState(new BlockPos(x+11, y+9, z+3), leaves);
        this.setBlockMetadataWithNotify(x+11, y+9, z+3, 4, 4);
        this.setBlockState(new BlockPos(x+3, y+9, z+4), leaves);
        this.setBlockMetadataWithNotify(x+3, y+9, z+4, 4, 4);
        this.setBlockState(new BlockPos(x+4, y+9, z+4), leaves);
        this.setBlockMetadataWithNotify(x+4, y+9, z+4, 4, 4);
        this.setBlockState(new BlockPos(x+12, y+9, z+4), leaves);
        this.setBlockMetadataWithNotify(x+12, y+9, z+4, 4, 4);
        this.setBlockState(new BlockPos(x+2, y+9, z+7), leaves);
        this.setBlockMetadataWithNotify(x+2, y+9, z+7, 4, 4);
        this.setBlockState(new BlockPos(x+5, y+9, z+9), leaves);
        this.setBlockMetadataWithNotify(x+5, y+9, z+9, 4, 4);
        this.setBlockState(new BlockPos(x+9, y+9, z+9), leaves);
        this.setBlockMetadataWithNotify(x+9, y+9, z+9, 4, 4);
        this.setBlockState(new BlockPos(x+6, y+9, z+10), leaves);
        this.setBlockMetadataWithNotify(x+6, y+9, z+10, 4, 4);
        this.setBlockState(new BlockPos(x+8, y+9, z+10), log);
        this.setBlockState(new BlockPos(x+9, y+9, z+10), log);
        this.setBlockState(new BlockPos(x+8, y+9, z+11), log);
        this.setBlockState(new BlockPos(x+9, y+9, z+11), log);
        this.setBlockState(new BlockPos(x+9, y+9, z+12), log);
        this.setBlockState(new BlockPos(x+20, y+9, z+12), leaves);
        this.setBlockMetadataWithNotify(x+20, y+9, z+12, 4, 4);
        this.setBlockState(new BlockPos(x+19, y+9, z+13), leaves);
        this.setBlockMetadataWithNotify(x+19, y+9, z+13, 4, 4);
        this.setBlockState(new BlockPos(x+11, y+9, z+14), log);
        this.setBlockState(new BlockPos(x+10, y+9, z+15), log);
        this.setBlockState(new BlockPos(x+11, y+9, z+15), log);
        this.setBlockState(new BlockPos(x+7, y+9, z+16), leaves);
        this.setBlockMetadataWithNotify(x+7, y+9, z+16, 4, 4);
        this.setBlockState(new BlockPos(x+11, y+9, z+16), log);
        this.setBlockState(new BlockPos(x+12, y+9, z+16), log);
        this.setBlockState(new BlockPos(x+7, y+9, z+17), leaves);
        this.setBlockMetadataWithNotify(x+7, y+9, z+17, 4, 4);
        this.setBlockState(new BlockPos(x+10, y+9, z+17), leaves);
        this.setBlockMetadataWithNotify(x+10, y+9, z+17, 4, 4);
        this.setBlockState(new BlockPos(x+12, y+9, z+17), log);
        this.setBlockState(new BlockPos(x+7, y+9, z+19), leaves);
        this.setBlockMetadataWithNotify(x+7, y+9, z+19, 4, 4);
        this.setBlockState(new BlockPos(x+8, y+9, z+19), leaves);
        this.setBlockMetadataWithNotify(x+8, y+9, z+19, 4, 4);
        this.setBlockState(new BlockPos(x+9, y+9, z+19), leaves);
        this.setBlockMetadataWithNotify(x+9, y+9, z+19, 4, 4);
        this.setBlockState(new BlockPos(x+11, y+9, z+19), leaves);
        this.setBlockMetadataWithNotify(x+11, y+9, z+19, 4, 4);
        this.setBlockState(new BlockPos(x+5, y+9, z+20), leaves);
        this.setBlockMetadataWithNotify(x+5, y+9, z+20, 4, 4);
        this.setBlockState(new BlockPos(x+11, y+9, z+20), leaves);
        this.setBlockMetadataWithNotify(x+11, y+9, z+20, 4, 4);
        this.setBlockState(new BlockPos(x+8, y+9, z+21), leaves);
        this.setBlockMetadataWithNotify(x+8, y+9, z+21, 4, 4);
        this.setBlockState(new BlockPos(x+7, y+9, z+22), leaves);
        this.setBlockMetadataWithNotify(x+7, y+9, z+22, 4, 4);
        this.setBlockState(new BlockPos(x+7, y+9, z+25), leaves);
        this.setBlockMetadataWithNotify(x+7, y+9, z+25, 12, 12);
        this.setBlockState(new BlockPos(x+9, y+9, z+25), leaves);
        this.setBlockMetadataWithNotify(x+9, y+9, z+25, 8, 8);
        this.setBlockState(new BlockPos(x+19, y+10, z+2), leaves);
        this.setBlockMetadataWithNotify(x+19, y+10, z+2, 4, 4);
        this.setBlockState(new BlockPos(x+6, y+10, z+5), leaves);
        this.setBlockMetadataWithNotify(x+6, y+10, z+5, 4, 4);
        this.setBlockState(new BlockPos(x+12, y+10, z+5), leaves);
        this.setBlockMetadataWithNotify(x+12, y+10, z+5, 12, 12);
        this.setBlockState(new BlockPos(x+4, y+10, z+6), leaves);
        this.setBlockMetadataWithNotify(x+4, y+10, z+6, 4, 4);
        this.setBlockState(new BlockPos(x+6, y+10, z+6), leaves);
        this.setBlockMetadataWithNotify(x+6, y+10, z+6, 4, 4);
        this.setBlockState(new BlockPos(x+11, y+10, z+6), leaves);
        this.setBlockMetadataWithNotify(x+11, y+10, z+6, 8, 8);
        this.setBlockState(new BlockPos(x+4, y+10, z+7), leaves);
        this.setBlockMetadataWithNotify(x+4, y+10, z+7, 4, 4);
        this.setBlockState(new BlockPos(x+6, y+10, z+7), leaves);
        this.setBlockMetadataWithNotify(x+6, y+10, z+7, 4, 4);
        this.setBlockState(new BlockPos(x+5, y+10, z+10), leaves);
        this.setBlockMetadataWithNotify(x+5, y+10, z+10, 4, 4);
        this.setBlockState(new BlockPos(x+8, y+10, z+10), log);
        this.setBlockState(new BlockPos(x+9, y+10, z+10), log);
        this.setBlockState(new BlockPos(x+8, y+10, z+11), log);
        this.setBlockState(new BlockPos(x+9, y+10, z+11), log);
        this.setBlockState(new BlockPos(x+11, y+10, z+14), leaves);
        this.setBlockMetadataWithNotify(x+11, y+10, z+14, 4, 4);
        this.setBlockState(new BlockPos(x+20, y+10, z+14), leaves);
        this.setBlockMetadataWithNotify(x+20, y+10, z+14, 4, 4);
        this.setBlockState(new BlockPos(x+13, y+10, z+15), leaves);
        this.setBlockMetadataWithNotify(x+13, y+10, z+15, 4, 4);
        this.setBlockState(new BlockPos(x+20, y+10, z+15), leaves);
        this.setBlockMetadataWithNotify(x+20, y+10, z+15, 4, 4);
        this.setBlockState(new BlockPos(x+21, y+10, z+15), leaves);
        this.setBlockMetadataWithNotify(x+21, y+10, z+15, 4, 4);
        this.setBlockState(new BlockPos(x+12, y+10, z+16), log);
        this.setBlockState(new BlockPos(x+20, y+10, z+16), leaves);
        this.setBlockMetadataWithNotify(x+20, y+10, z+16, 4, 4);
        this.setBlockState(new BlockPos(x+10, y+10, z+17), leaves);
        this.setBlockMetadataWithNotify(x+10, y+10, z+17, 4, 4);
        this.setBlockState(new BlockPos(x+11, y+10, z+17), log);
        this.setBlockState(new BlockPos(x+12, y+10, z+17), log);
        this.setBlockState(new BlockPos(x+11, y+10, z+18), log);
        this.setBlockState(new BlockPos(x+12, y+10, z+18), log);
        this.setBlockState(new BlockPos(x+14, y+10, z+18), leaves);
        this.setBlockMetadataWithNotify(x+14, y+10, z+18, 4, 4);
        this.setBlockState(new BlockPos(x+15, y+10, z+18), leaves);
        this.setBlockMetadataWithNotify(x+15, y+10, z+18, 12, 12);
        this.setBlockState(new BlockPos(x+6, y+10, z+19), leaves);
        this.setBlockMetadataWithNotify(x+6, y+10, z+19, 4, 4);
        this.setBlockState(new BlockPos(x+11, y+10, z+19), log);
        this.setBlockState(new BlockPos(x+12, y+10, z+19), log);
        this.setBlockState(new BlockPos(x+9, y+10, z+20), leaves);
        this.setBlockMetadataWithNotify(x+9, y+10, z+20, 4, 4);
        this.setBlockState(new BlockPos(x+12, y+10, z+20), log);
        this.setBlockState(new BlockPos(x+7, y+10, z+22), leaves);
        this.setBlockMetadataWithNotify(x+7, y+10, z+22, 4, 4);
        this.setBlockState(new BlockPos(x+9, y+10, z+22), leaves);
        this.setBlockMetadataWithNotify(x+9, y+10, z+22, 4, 4);
        this.setBlockState(new BlockPos(x+8, y+10, z+23), leaves);
        this.setBlockMetadataWithNotify(x+8, y+10, z+23, 4, 4);
        this.setBlockState(new BlockPos(x+10, y+10, z+23), leaves);
        this.setBlockMetadataWithNotify(x+10, y+10, z+23, 4, 4);
        this.setBlockState(new BlockPos(x+8, y+10, z+26), leaves);
        this.setBlockMetadataWithNotify(x+8, y+10, z+26, 8, 8);
        this.setBlockState(new BlockPos(x+11, y+10, z+26), leaves);
        this.setBlockMetadataWithNotify(x+11, y+10, z+26, 4, 4);
        this.setBlockState(new BlockPos(x+11, y+10, z+27), leaves);
        this.setBlockMetadataWithNotify(x+11, y+10, z+27, 4, 4);
        this.setBlockState(new BlockPos(x+12, y+11, z+0), leaves);
        this.setBlockMetadataWithNotify(x+12, y+11, z+0, 4, 4);
        this.setBlockState(new BlockPos(x+10, y+11, z+1), leaves);
        this.setBlockMetadataWithNotify(x+10, y+11, z+1, 4, 4);
        this.setBlockState(new BlockPos(x+11, y+11, z+1), leaves);
        this.setBlockMetadataWithNotify(x+11, y+11, z+1, 4, 4);
        this.setBlockState(new BlockPos(x+16, y+11, z+1), leaves);
        this.setBlockMetadataWithNotify(x+16, y+11, z+1, 8, 8);
        this.setBlockState(new BlockPos(x+19, y+11, z+1), leaves);
        this.setBlockMetadataWithNotify(x+19, y+11, z+1, 4, 4);
        this.setBlockState(new BlockPos(x+11, y+11, z+2), leaves);
        this.setBlockState(new BlockPos(x+17, y+11, z+2), leaves);
        this.setBlockMetadataWithNotify(x+17, y+11, z+2, 12, 12);
        this.setBlockState(new BlockPos(x+17, y+11, z+3), leaves);
        this.setBlockMetadataWithNotify(x+17, y+11, z+3, 12, 12);
        this.setBlockState(new BlockPos(x+14, y+11, z+4), leaves);
        this.setBlockMetadataWithNotify(x+14, y+11, z+4, 8, 8);
        this.setBlockState(new BlockPos(x+21, y+11, z+4), leaves);
        this.setBlockMetadataWithNotify(x+21, y+11, z+4, 4, 4);
        this.setBlockState(new BlockPos(x+12, y+11, z+7), leaves);
        this.setBlockMetadataWithNotify(x+12, y+11, z+7, 8, 8);
        this.setBlockState(new BlockPos(x+3, y+11, z+8), leaves);
        this.setBlockMetadataWithNotify(x+3, y+11, z+8, 4, 4);
        this.setBlockState(new BlockPos(x+4, y+11, z+8), leaves);
        this.setBlockMetadataWithNotify(x+4, y+11, z+8, 4, 4);
        this.setBlockState(new BlockPos(x+8, y+11, z+10), log);
        this.setBlockState(new BlockPos(x+9, y+11, z+10), log);
        this.setBlockState(new BlockPos(x+20, y+11, z+10), leaves);
        this.setBlockMetadataWithNotify(x+20, y+11, z+10, 4, 4);
        this.setBlockState(new BlockPos(x+8, y+11, z+11), log);
        this.setBlockState(new BlockPos(x+21, y+11, z+11), leaves);
        this.setBlockMetadataWithNotify(x+21, y+11, z+11, 4, 4);
        this.setBlockState(new BlockPos(x+22, y+11, z+11), leaves);
        this.setBlockMetadataWithNotify(x+22, y+11, z+11, 4, 4);
        this.setBlockState(new BlockPos(x+19, y+11, z+12), leaves);
        this.setBlockMetadataWithNotify(x+19, y+11, z+12, 4, 4);
        this.setBlockState(new BlockPos(x+22, y+11, z+12), leaves);
        this.setBlockMetadataWithNotify(x+22, y+11, z+12, 4, 4);
        this.setBlockState(new BlockPos(x+13, y+11, z+13), leaves);
        this.setBlockMetadataWithNotify(x+13, y+11, z+13, 4, 4);
        this.setBlockState(new BlockPos(x+22, y+11, z+13), leaves);
        this.setBlockMetadataWithNotify(x+22, y+11, z+13, 4, 4);
        this.setBlockState(new BlockPos(x+15, y+11, z+14), leaves);
        this.setBlockMetadataWithNotify(x+15, y+11, z+14, 4, 4);
        this.setBlockState(new BlockPos(x+20, y+11, z+14), leaves);
        this.setBlockMetadataWithNotify(x+20, y+11, z+14, 4, 4);
        this.setBlockState(new BlockPos(x+14, y+11, z+15), leaves);
        this.setBlockMetadataWithNotify(x+14, y+11, z+15, 4, 4);
        this.setBlockState(new BlockPos(x+12, y+11, z+16), leaves);
        this.setBlockMetadataWithNotify(x+12, y+11, z+16, 4, 4);
        this.setBlockState(new BlockPos(x+13, y+11, z+16), log);
        this.setBlockState(new BlockPos(x+16, y+11, z+16), leaves);
        this.setBlockMetadataWithNotify(x+16, y+11, z+16, 4, 4);
        this.setBlockState(new BlockPos(x+20, y+11, z+16), leaves);
        this.setBlockMetadataWithNotify(x+20, y+11, z+16, 4, 4);
        this.setBlockState(new BlockPos(x+6, y+11, z+17), leaves);
        this.setBlockMetadataWithNotify(x+6, y+11, z+17, 4, 4);
        this.setBlockState(new BlockPos(x+7, y+11, z+18), leaves);
        this.setBlockMetadataWithNotify(x+7, y+11, z+18, 4, 4);
        this.setBlockState(new BlockPos(x+8, y+11, z+18), leaves);
        this.setBlockMetadataWithNotify(x+8, y+11, z+18, 4, 4);
        this.setBlockState(new BlockPos(x+12, y+11, z+18), log);
        this.setBlockState(new BlockPos(x+15, y+11, z+18), leaves);
        this.setBlockMetadataWithNotify(x+15, y+11, z+18, 12, 12);
        this.setBlockState(new BlockPos(x+7, y+11, z+19), leaves);
        this.setBlockMetadataWithNotify(x+7, y+11, z+19, 4, 4);
        this.setBlockState(new BlockPos(x+8, y+11, z+19), leaves);
        this.setBlockMetadataWithNotify(x+8, y+11, z+19, 4, 4);
        this.setBlockState(new BlockPos(x+10, y+11, z+19), leaves);
        this.setBlockMetadataWithNotify(x+10, y+11, z+19, 4, 4);
        this.setBlockState(new BlockPos(x+12, y+11, z+19), log);
        this.setBlockState(new BlockPos(x+16, y+11, z+19), leaves);
        this.setBlockMetadataWithNotify(x+16, y+11, z+19, 8, 8);
        this.setBlockState(new BlockPos(x+7, y+11, z+20), leaves);
        this.setBlockMetadataWithNotify(x+7, y+11, z+20, 4, 4);
        this.setBlockState(new BlockPos(x+11, y+11, z+20), log);
        this.setBlockState(new BlockPos(x+12, y+11, z+20), log);
        this.setBlockState(new BlockPos(x+13, y+11, z+20), log);
        this.setBlockState(new BlockPos(x+17, y+11, z+20), leaves);
        this.setBlockMetadataWithNotify(x+17, y+11, z+20, 12, 12);
        this.setBlockState(new BlockPos(x+7, y+11, z+21), leaves);
        this.setBlockMetadataWithNotify(x+7, y+11, z+21, 4, 4);
        this.setBlockState(new BlockPos(x+12, y+11, z+21), log);
        this.setBlockState(new BlockPos(x+9, y+11, z+22), leaves);
        this.setBlockMetadataWithNotify(x+9, y+11, z+22, 4, 4);
        this.setBlockState(new BlockPos(x+5, y+11, z+23), leaves);
        this.setBlockMetadataWithNotify(x+5, y+11, z+23, 4, 4);
        this.setBlockState(new BlockPos(x+7, y+11, z+23), leaves);
        this.setBlockMetadataWithNotify(x+7, y+11, z+23, 4, 4);
        this.setBlockState(new BlockPos(x+8, y+11, z+23), leaves);
        this.setBlockMetadataWithNotify(x+8, y+11, z+23, 4, 4);
        this.setBlockState(new BlockPos(x+9, y+11, z+23), leaves);
        this.setBlockMetadataWithNotify(x+9, y+11, z+23, 4, 4);
        this.setBlockState(new BlockPos(x+11, y+11, z+24), leaves);
        this.setBlockMetadataWithNotify(x+11, y+11, z+24, 4, 4);
        this.setBlockState(new BlockPos(x+6, y+11, z+25), leaves);
        this.setBlockMetadataWithNotify(x+6, y+11, z+25, 4, 4);
        this.setBlockState(new BlockPos(x+9, y+11, z+25), leaves);
        this.setBlockMetadataWithNotify(x+9, y+11, z+25, 12, 12);
        this.setBlockState(new BlockPos(x+12, y+11, z+25), leaves);
        this.setBlockMetadataWithNotify(x+12, y+11, z+25, 4, 4);
        this.setBlockState(new BlockPos(x+7, y+11, z+26), leaves);
        this.setBlockMetadataWithNotify(x+7, y+11, z+26, 12, 12);
        this.setBlockState(new BlockPos(x+9, y+11, z+26), leaves);
        this.setBlockMetadataWithNotify(x+9, y+11, z+26, 12, 12);
        this.setBlockState(new BlockPos(x+10, y+11, z+27), leaves);
        this.setBlockMetadataWithNotify(x+10, y+11, z+27, 4, 4);
        this.setBlockState(new BlockPos(x+20, y+12, z+0), leaves);
        this.setBlockMetadataWithNotify(x+20, y+12, z+0, 4, 4);
        this.setBlockState(new BlockPos(x+20, y+12, z+1), leaves);
        this.setBlockMetadataWithNotify(x+20, y+12, z+1, 4, 4);
        this.setBlockState(new BlockPos(x+15, y+12, z+2), leaves);
        this.setBlockMetadataWithNotify(x+15, y+12, z+2, 12, 12);
        this.setBlockState(new BlockPos(x+19, y+12, z+2), leaves);
        this.setBlockMetadataWithNotify(x+19, y+12, z+2, 4, 4);
        this.setBlockState(new BlockPos(x+12, y+12, z+3), leaves);
        this.setBlockMetadataWithNotify(x+12, y+12, z+3, 4, 4);
        this.setBlockState(new BlockPos(x+15, y+12, z+3), leaves);
        this.setBlockMetadataWithNotify(x+15, y+12, z+3, 12, 12);
        this.setBlockState(new BlockPos(x+20, y+12, z+3), leaves);
        this.setBlockMetadataWithNotify(x+20, y+12, z+3, 4, 4);
        this.setBlockState(new BlockPos(x+21, y+12, z+3), leaves);
        this.setBlockMetadataWithNotify(x+21, y+12, z+3, 4, 4);
        this.setBlockState(new BlockPos(x+22, y+12, z+3), leaves);
        this.setBlockMetadataWithNotify(x+22, y+12, z+3, 4, 4);
        this.setBlockState(new BlockPos(x+10, y+12, z+4), leaves);
        this.setBlockMetadataWithNotify(x+10, y+12, z+4, 4, 4);
        this.setBlockState(new BlockPos(x+12, y+12, z+4), leaves);
        this.setBlockMetadataWithNotify(x+12, y+12, z+4, 4, 4);
        this.setBlockState(new BlockPos(x+11, y+12, z+5), leaves);
        this.setBlockMetadataWithNotify(x+11, y+12, z+5, 8, 8);
        this.setBlockState(new BlockPos(x+14, y+12, z+5), leaves);
        this.setBlockMetadataWithNotify(x+14, y+12, z+5, 12, 12);
        this.setBlockState(new BlockPos(x+17, y+12, z+5), leaves);
        this.setBlockMetadataWithNotify(x+17, y+12, z+5, 4, 4);
        this.setBlockState(new BlockPos(x+3, y+12, z+6), leaves);
        this.setBlockMetadataWithNotify(x+3, y+12, z+6, 4, 4);
        this.setBlockState(new BlockPos(x+10, y+12, z+6), leaves);
        this.setBlockState(new BlockPos(x+11, y+12, z+6), leaves);
        this.setBlockMetadataWithNotify(x+11, y+12, z+6, 8, 8);
        this.setBlockState(new BlockPos(x+12, y+12, z+6), leaves);
        this.setBlockMetadataWithNotify(x+12, y+12, z+6, 12, 12);
        this.setBlockState(new BlockPos(x+9, y+12, z+7), leaves);
        this.setBlockMetadataWithNotify(x+9, y+12, z+7, 12, 12);
        this.setBlockState(new BlockPos(x+4, y+12, z+9), leaves);
        this.setBlockMetadataWithNotify(x+4, y+12, z+9, 4, 4);
        this.setBlockState(new BlockPos(x+8, y+12, z+9), log);
        this.setBlockState(new BlockPos(x+10, y+12, z+9), leaves);
        this.setBlockMetadataWithNotify(x+10, y+12, z+9, 4, 4);
        this.setBlockState(new BlockPos(x+7, y+12, z+10), log);
        this.setBlockState(new BlockPos(x+8, y+12, z+10), log);
        this.setBlockState(new BlockPos(x+9, y+12, z+10), log);
        this.setBlockState(new BlockPos(x+10, y+12, z+10), log);
        this.setBlockState(new BlockPos(x+20, y+12, z+10), leaves);
        this.setBlockMetadataWithNotify(x+20, y+12, z+10, 4, 4);
        this.setBlockState(new BlockPos(x+23, y+12, z+10), leaves);
        this.setBlockMetadataWithNotify(x+23, y+12, z+10, 4, 4);
        this.setBlockState(new BlockPos(x+8, y+12, z+11), log);
        this.setBlockState(new BlockPos(x+22, y+12, z+11), leaves);
        this.setBlockMetadataWithNotify(x+22, y+12, z+11, 4, 4);
        this.setBlockState(new BlockPos(x+6, y+12, z+12), leaves);
        this.setBlockMetadataWithNotify(x+6, y+12, z+12, 4, 4);
        this.setBlockState(new BlockPos(x+22, y+12, z+12), leaves);
        this.setBlockMetadataWithNotify(x+22, y+12, z+12, 4, 4);
        this.setBlockState(new BlockPos(x+19, y+12, z+13), leaves);
        this.setBlockMetadataWithNotify(x+19, y+12, z+13, 4, 4);
        this.setBlockState(new BlockPos(x+20, y+12, z+13), leaves);
        this.setBlockMetadataWithNotify(x+20, y+12, z+13, 4, 4);
        this.setBlockState(new BlockPos(x+12, y+12, z+14), leaves);
        this.setBlockMetadataWithNotify(x+12, y+12, z+14, 4, 4);
        this.setBlockState(new BlockPos(x+20, y+12, z+14), leaves);
        this.setBlockMetadataWithNotify(x+20, y+12, z+14, 4, 4);
        this.setBlockState(new BlockPos(x+21, y+12, z+14), leaves);
        this.setBlockMetadataWithNotify(x+21, y+12, z+14, 4, 4);
        this.setBlockState(new BlockPos(x+11, y+12, z+15), leaves);
        this.setBlockMetadataWithNotify(x+11, y+12, z+15, 4, 4);
        this.setBlockState(new BlockPos(x+20, y+12, z+15), leaves);
        this.setBlockMetadataWithNotify(x+20, y+12, z+15, 4, 4);
        this.setBlockState(new BlockPos(x+10, y+12, z+16), leaves);
        this.setBlockMetadataWithNotify(x+10, y+12, z+16, 4, 4);
        this.setBlockState(new BlockPos(x+13, y+12, z+16), log);
        this.setBlockState(new BlockPos(x+15, y+12, z+16), leaves);
        this.setBlockMetadataWithNotify(x+15, y+12, z+16, 4, 4);
        this.setBlockState(new BlockPos(x+10, y+12, z+17), leaves);
        this.setBlockMetadataWithNotify(x+10, y+12, z+17, 4, 4);
        this.setBlockState(new BlockPos(x+16, y+12, z+17), leaves);
        this.setBlockMetadataWithNotify(x+16, y+12, z+17, 12, 12);
        this.setBlockState(new BlockPos(x+16, y+12, z+18), leaves);
        this.setBlockMetadataWithNotify(x+16, y+12, z+18, 12, 12);
        this.setBlockState(new BlockPos(x+20, y+12, z+18), leaves);
        this.setBlockMetadataWithNotify(x+20, y+12, z+18, 4, 4);
        this.setBlockState(new BlockPos(x+7, y+12, z+19), leaves);
        this.setBlockMetadataWithNotify(x+7, y+12, z+19, 4, 4);
        this.setBlockState(new BlockPos(x+13, y+12, z+19), leaves);
        this.setBlockMetadataWithNotify(x+13, y+12, z+19, 4, 4);
        this.setBlockState(new BlockPos(x+6, y+12, z+20), leaves);
        this.setBlockMetadataWithNotify(x+6, y+12, z+20, 4, 4);
        this.setBlockState(new BlockPos(x+7, y+12, z+20), leaves);
        this.setBlockMetadataWithNotify(x+7, y+12, z+20, 4, 4);
        this.setBlockState(new BlockPos(x+8, y+12, z+20), leaves);
        this.setBlockMetadataWithNotify(x+8, y+12, z+20, 4, 4);
        this.setBlockState(new BlockPos(x+14, y+12, z+20), log);
        this.setBlockState(new BlockPos(x+11, y+12, z+21), log);
        this.setBlockState(new BlockPos(x+12, y+12, z+21), log);
        this.setBlockState(new BlockPos(x+14, y+12, z+21), log);
        this.setBlockState(new BlockPos(x+7, y+12, z+22), leaves);
        this.setBlockMetadataWithNotify(x+7, y+12, z+22, 4, 4);
        this.setBlockState(new BlockPos(x+12, y+12, z+22), log);
        this.setBlockState(new BlockPos(x+6, y+12, z+23), leaves);
        this.setBlockMetadataWithNotify(x+6, y+12, z+23, 4, 4);
        this.setBlockState(new BlockPos(x+9, y+12, z+23), leaves);
        this.setBlockMetadataWithNotify(x+9, y+12, z+23, 12, 12);
        this.setBlockState(new BlockPos(x+10, y+12, z+23), leaves);
        this.setBlockMetadataWithNotify(x+10, y+12, z+23, 4, 4);
        this.setBlockState(new BlockPos(x+8, y+12, z+24), leaves);
        this.setBlockMetadataWithNotify(x+8, y+12, z+24, 12, 12);
        this.setBlockState(new BlockPos(x+10, y+12, z+24), leaves);
        this.setBlockMetadataWithNotify(x+10, y+12, z+24, 4, 4);
        this.setBlockState(new BlockPos(x+12, y+12, z+24), leaves);
        this.setBlockMetadataWithNotify(x+12, y+12, z+24, 4, 4);
        this.setBlockState(new BlockPos(x+5, y+12, z+25), leaves);
        this.setBlockMetadataWithNotify(x+5, y+12, z+25, 4, 4);
        this.setBlockState(new BlockPos(x+7, y+12, z+25), leaves);
        this.setBlockMetadataWithNotify(x+7, y+12, z+25, 12, 12);
        this.setBlockState(new BlockPos(x+8, y+12, z+25), leaves);
        this.setBlockMetadataWithNotify(x+8, y+12, z+25, 12, 12);
        this.setBlockState(new BlockPos(x+9, y+12, z+25), leaves);
        this.setBlockMetadataWithNotify(x+9, y+12, z+25, 12, 12);
        this.setBlockState(new BlockPos(x+11, y+12, z+25), leaves);
        this.setBlockMetadataWithNotify(x+11, y+12, z+25, 4, 4);
        this.setBlockState(new BlockPos(x+9, y+12, z+26), leaves);
        this.setBlockMetadataWithNotify(x+9, y+12, z+26, 12, 12);
        this.setBlockState(new BlockPos(x+14, y+12, z+26), leaves);
        this.setBlockMetadataWithNotify(x+14, y+12, z+26, 4, 4);
        this.setBlockState(new BlockPos(x+7, y+12, z+27), leaves);
        this.setBlockMetadataWithNotify(x+7, y+12, z+27, 12, 12);
        this.setBlockState(new BlockPos(x+11, y+12, z+27), leaves);
        this.setBlockMetadataWithNotify(x+11, y+12, z+27, 4, 4);
        this.setBlockState(new BlockPos(x+12, y+12, z+27), leaves);
        this.setBlockMetadataWithNotify(x+12, y+12, z+27, 4, 4);
        this.setBlockState(new BlockPos(x+13, y+12, z+27), leaves);
        this.setBlockMetadataWithNotify(x+13, y+12, z+27, 4, 4);
        this.setBlockState(new BlockPos(x+19, y+12, z+27), leaves);
        this.setBlockMetadataWithNotify(x+19, y+12, z+27, 8, 8);
        this.setBlockState(new BlockPos(x+19, y+13, z+0), leaves);
        this.setBlockMetadataWithNotify(x+19, y+13, z+0, 4, 4);
        this.setBlockState(new BlockPos(x+20, y+13, z+0), leaves);
        this.setBlockMetadataWithNotify(x+20, y+13, z+0, 4, 4);
        this.setBlockState(new BlockPos(x+8, y+13, z+1), leaves);
        this.setBlockMetadataWithNotify(x+8, y+13, z+1, 4, 4);
        this.setBlockState(new BlockPos(x+12, y+13, z+1), leaves);
        this.setBlockMetadataWithNotify(x+12, y+13, z+1, 4, 4);
        this.setBlockState(new BlockPos(x+21, y+13, z+1), leaves);
        this.setBlockMetadataWithNotify(x+21, y+13, z+1, 4, 4);
        this.setBlockState(new BlockPos(x+8, y+13, z+2), leaves);
        this.setBlockMetadataWithNotify(x+8, y+13, z+2, 4, 4);
        this.setBlockState(new BlockPos(x+21, y+13, z+2), leaves);
        this.setBlockMetadataWithNotify(x+21, y+13, z+2, 4, 4);
        this.setBlockState(new BlockPos(x+8, y+13, z+3), leaves);
        this.setBlockMetadataWithNotify(x+8, y+13, z+3, 4, 4);
        this.setBlockState(new BlockPos(x+17, y+13, z+3), leaves);
        this.setBlockMetadataWithNotify(x+17, y+13, z+3, 4, 4);
        this.setBlockState(new BlockPos(x+20, y+13, z+3), leaves);
        this.setBlockMetadataWithNotify(x+20, y+13, z+3, 4, 4);
        this.setBlockState(new BlockPos(x+18, y+13, z+4), leaves);
        this.setBlockMetadataWithNotify(x+18, y+13, z+4, 4, 4);
        this.setBlockState(new BlockPos(x+21, y+13, z+4), leaves);
        this.setBlockMetadataWithNotify(x+21, y+13, z+4, 4, 4);
        this.setBlockState(new BlockPos(x+22, y+13, z+4), leaves);
        this.setBlockMetadataWithNotify(x+22, y+13, z+4, 4, 4);
        this.setBlockState(new BlockPos(x+13, y+13, z+5), leaves);
        this.setBlockMetadataWithNotify(x+13, y+13, z+5, 12, 12);
        this.setBlockState(new BlockPos(x+15, y+13, z+5), leaves);
        this.setBlockMetadataWithNotify(x+15, y+13, z+5, 12, 12);
        this.setBlockState(new BlockPos(x+3, y+13, z+6), leaves);
        this.setBlockMetadataWithNotify(x+3, y+13, z+6, 4, 4);
        this.setBlockState(new BlockPos(x+8, y+13, z+6), leaves);
        this.setBlockMetadataWithNotify(x+8, y+13, z+6, 4, 4);
        this.setBlockState(new BlockPos(x+18, y+13, z+6), leaves);
        this.setBlockMetadataWithNotify(x+18, y+13, z+6, 4, 4);
        this.setBlockState(new BlockPos(x+19, y+13, z+6), leaves);
        this.setBlockMetadataWithNotify(x+19, y+13, z+6, 4, 4);
        this.setBlockState(new BlockPos(x+8, y+13, z+7), leaves);
        this.setBlockMetadataWithNotify(x+8, y+13, z+7, 4, 4);
        this.setBlockState(new BlockPos(x+15, y+13, z+7), leaves);
        this.setBlockMetadataWithNotify(x+15, y+13, z+7, 4, 4);
        this.setBlockState(new BlockPos(x+20, y+13, z+7), leaves);
        this.setBlockMetadataWithNotify(x+20, y+13, z+7, 4, 4);
        this.setBlockState(new BlockPos(x+1, y+13, z+8), leaves);
        this.setBlockMetadataWithNotify(x+1, y+13, z+8, 4, 4);
        this.setBlockState(new BlockPos(x+7, y+13, z+8), leaves);
        this.setBlockMetadataWithNotify(x+7, y+13, z+8, 4, 4);
        this.setBlockState(new BlockPos(x+8, y+13, z+8), leaves);
        this.setBlockMetadataWithNotify(x+8, y+13, z+8, 4, 4);
        this.setBlockState(new BlockPos(x+7, y+13, z+9), log);
        this.setBlockState(new BlockPos(x+8, y+13, z+9), log);
        this.setBlockState(new BlockPos(x+16, y+13, z+9), leaves);
        this.setBlockMetadataWithNotify(x+16, y+13, z+9, 4, 4);
        this.setBlockState(new BlockPos(x+22, y+13, z+9), leaves);
        this.setBlockMetadataWithNotify(x+22, y+13, z+9, 4, 4);
        this.setBlockState(new BlockPos(x+24, y+13, z+9), leaves);
        this.setBlockMetadataWithNotify(x+24, y+13, z+9, 4, 4);
        this.setBlockState(new BlockPos(x+3, y+13, z+10), leaves);
        this.setBlockMetadataWithNotify(x+3, y+13, z+10, 4, 4);
        this.setBlockState(new BlockPos(x+6, y+13, z+10), leaves);
        this.setBlockMetadataWithNotify(x+6, y+13, z+10, 4, 4);
        this.setBlockState(new BlockPos(x+9, y+13, z+10), log);
        this.setBlockState(new BlockPos(x+10, y+13, z+10), log);
        this.setBlockState(new BlockPos(x+5, y+13, z+11), leaves);
        this.setBlockMetadataWithNotify(x+5, y+13, z+11, 4, 4);
        this.setBlockState(new BlockPos(x+20, y+13, z+11), leaves);
        this.setBlockMetadataWithNotify(x+20, y+13, z+11, 4, 4);
        this.setBlockState(new BlockPos(x+5, y+13, z+12), leaves);
        this.setBlockMetadataWithNotify(x+5, y+13, z+12, 4, 4);
        this.setBlockState(new BlockPos(x+22, y+13, z+12), leaves);
        this.setBlockMetadataWithNotify(x+22, y+13, z+12, 4, 4);
        this.setBlockState(new BlockPos(x+14, y+13, z+13), leaves);
        this.setBlockMetadataWithNotify(x+14, y+13, z+13, 4, 4);
        this.setBlockState(new BlockPos(x+22, y+13, z+13), leaves);
        this.setBlockMetadataWithNotify(x+22, y+13, z+13, 4, 4);
        this.setBlockState(new BlockPos(x+10, y+13, z+16), leaves);
        this.setBlockMetadataWithNotify(x+10, y+13, z+16, 4, 4);
        this.setBlockState(new BlockPos(x+12, y+13, z+16), leaves);
        this.setBlockMetadataWithNotify(x+12, y+13, z+16, 4, 4);
        this.setBlockState(new BlockPos(x+14, y+13, z+16), leaves);
        this.setBlockMetadataWithNotify(x+14, y+13, z+16, 4, 4);
        this.setBlockState(new BlockPos(x+16, y+13, z+16), leaves);
        this.setBlockMetadataWithNotify(x+16, y+13, z+16, 4, 4);
        this.setBlockState(new BlockPos(x+13, y+13, z+17), leaves);
        this.setBlockMetadataWithNotify(x+13, y+13, z+17, 4, 4);
        this.setBlockState(new BlockPos(x+19, y+13, z+17), leaves);
        this.setBlockMetadataWithNotify(x+19, y+13, z+17, 4, 4);
        this.setBlockState(new BlockPos(x+13, y+13, z+18), leaves);
        this.setBlockMetadataWithNotify(x+13, y+13, z+18, 4, 4);
        this.setBlockState(new BlockPos(x+8, y+13, z+21), leaves);
        this.setBlockMetadataWithNotify(x+8, y+13, z+21, 4, 4);
        this.setBlockState(new BlockPos(x+9, y+13, z+21), leaves);
        this.setBlockMetadataWithNotify(x+9, y+13, z+21, 4, 4);
        this.setBlockState(new BlockPos(x+15, y+13, z+21), leaves);
        this.setBlockMetadataWithNotify(x+15, y+13, z+21, 4, 4);
        this.setBlockState(new BlockPos(x+6, y+13, z+22), leaves);
        this.setBlockMetadataWithNotify(x+6, y+13, z+22, 4, 4);
        this.setBlockState(new BlockPos(x+12, y+13, z+22), log);
        this.setBlockState(new BlockPos(x+15, y+13, z+22), log);
        this.setBlockState(new BlockPos(x+18, y+13, z+22), leaves);
        this.setBlockMetadataWithNotify(x+18, y+13, z+22, 4, 4);
        this.setBlockState(new BlockPos(x+6, y+13, z+23), leaves);
        this.setBlockMetadataWithNotify(x+6, y+13, z+23, 4, 4);
        this.setBlockState(new BlockPos(x+8, y+13, z+23), leaves);
        this.setBlockMetadataWithNotify(x+8, y+13, z+23, 12, 12);
        this.setBlockState(new BlockPos(x+15, y+13, z+23), log);
        this.setBlockState(new BlockPos(x+10, y+13, z+24), leaves);
        this.setBlockMetadataWithNotify(x+10, y+13, z+24, 4, 4);
        this.setBlockState(new BlockPos(x+11, y+13, z+24), leaves);
        this.setBlockMetadataWithNotify(x+11, y+13, z+24, 4, 4);
        this.setBlockState(new BlockPos(x+13, y+13, z+24), leaves);
        this.setBlockMetadataWithNotify(x+13, y+13, z+24, 4, 4);
        this.setBlockState(new BlockPos(x+15, y+13, z+24), log);
        this.setBlockState(new BlockPos(x+14, y+13, z+25), leaves);
        this.setBlockMetadataWithNotify(x+14, y+13, z+25, 4, 4);
        this.setBlockState(new BlockPos(x+11, y+13, z+26), leaves);
        this.setBlockMetadataWithNotify(x+11, y+13, z+26, 4, 4);
        this.setBlockState(new BlockPos(x+15, y+13, z+26), leaves);
        this.setBlockMetadataWithNotify(x+15, y+13, z+26, 4, 4);
        this.setBlockState(new BlockPos(x+17, y+13, z+26), leaves);
        this.setBlockMetadataWithNotify(x+17, y+13, z+26, 12, 12);
        this.setBlockState(new BlockPos(x+18, y+13, z+26), leaves);
        this.setBlockMetadataWithNotify(x+18, y+13, z+26, 12, 12);
        this.setBlockState(new BlockPos(x+13, y+13, z+27), leaves);
        this.setBlockMetadataWithNotify(x+13, y+13, z+27, 4, 4);
        this.setBlockState(new BlockPos(x+11, y+13, z+28), leaves);
        this.setBlockMetadataWithNotify(x+11, y+13, z+28, 4, 4);
        this.setBlockState(new BlockPos(x+13, y+13, z+28), leaves);
        this.setBlockMetadataWithNotify(x+13, y+13, z+28, 4, 4);
        this.setBlockState(new BlockPos(x+18, y+13, z+28), leaves);
        this.setBlockMetadataWithNotify(x+18, y+13, z+28, 12, 12);
        this.setBlockState(new BlockPos(x+9, y+14, z+0), leaves);
        this.setBlockMetadataWithNotify(x+9, y+14, z+0, 4, 4);
        this.setBlockState(new BlockPos(x+8, y+14, z+1), leaves);
        this.setBlockMetadataWithNotify(x+8, y+14, z+1, 4, 4);
        this.setBlockState(new BlockPos(x+19, y+14, z+1), leaves);
        this.setBlockMetadataWithNotify(x+19, y+14, z+1, 4, 4);
        this.setBlockState(new BlockPos(x+8, y+14, z+2), leaves);
        this.setBlockMetadataWithNotify(x+8, y+14, z+2, 4, 4);
        this.setBlockState(new BlockPos(x+20, y+14, z+2), leaves);
        this.setBlockMetadataWithNotify(x+20, y+14, z+2, 4, 4);
        this.setBlockState(new BlockPos(x+12, y+14, z+3), leaves);
        this.setBlockMetadataWithNotify(x+12, y+14, z+3, 4, 4);
        this.setBlockState(new BlockPos(x+13, y+14, z+3), leaves);
        this.setBlockMetadataWithNotify(x+13, y+14, z+3, 4, 4);
        this.setBlockState(new BlockPos(x+8, y+14, z+4), leaves);
        this.setBlockMetadataWithNotify(x+8, y+14, z+4, 4, 4);
        this.setBlockState(new BlockPos(x+19, y+14, z+4), leaves);
        this.setBlockMetadataWithNotify(x+19, y+14, z+4, 4, 4);
        this.setBlockState(new BlockPos(x+12, y+14, z+5), leaves);
        this.setBlockMetadataWithNotify(x+12, y+14, z+5, 4, 4);
        this.setBlockState(new BlockPos(x+14, y+14, z+5), leaves);
        this.setBlockMetadataWithNotify(x+14, y+14, z+5, 4, 4);
        this.setBlockState(new BlockPos(x+16, y+14, z+5), leaves);
        this.setBlockMetadataWithNotify(x+16, y+14, z+5, 4, 4);
        this.setBlockState(new BlockPos(x+3, y+14, z+6), leaves);
        this.setBlockMetadataWithNotify(x+3, y+14, z+6, 4, 4);
        this.setBlockState(new BlockPos(x+19, y+14, z+6), leaves);
        this.setBlockMetadataWithNotify(x+19, y+14, z+6, 4, 4);
        this.setBlockState(new BlockPos(x+21, y+14, z+6), leaves);
        this.setBlockMetadataWithNotify(x+21, y+14, z+6, 4, 4);
        this.setBlockState(new BlockPos(x+1, y+14, z+7), leaves);
        this.setBlockMetadataWithNotify(x+1, y+14, z+7, 4, 4);
        this.setBlockState(new BlockPos(x+3, y+14, z+7), leaves);
        this.setBlockMetadataWithNotify(x+3, y+14, z+7, 4, 4);
        this.setBlockState(new BlockPos(x+5, y+14, z+7), leaves);
        this.setBlockMetadataWithNotify(x+5, y+14, z+7, 4, 4);
        this.setBlockState(new BlockPos(x+12, y+14, z+7), leaves);
        this.setBlockMetadataWithNotify(x+12, y+14, z+7, 4, 4);
        this.setBlockState(new BlockPos(x+2, y+14, z+8), leaves);
        this.setBlockMetadataWithNotify(x+2, y+14, z+8, 4, 4);
        this.setBlockState(new BlockPos(x+3, y+14, z+8), leaves);
        this.setBlockMetadataWithNotify(x+3, y+14, z+8, 4, 4);
        this.setBlockState(new BlockPos(x+5, y+14, z+8), leaves);
        this.setBlockMetadataWithNotify(x+5, y+14, z+8, 4, 4);
        this.setBlockState(new BlockPos(x+6, y+14, z+8), log);
        this.setBlockState(new BlockPos(x+7, y+14, z+8), log);
        this.setBlockState(new BlockPos(x+9, y+14, z+8), leaves);
        this.setBlockMetadataWithNotify(x+9, y+14, z+8, 4, 4);
        this.setBlockState(new BlockPos(x+13, y+14, z+8), leaves);
        this.setBlockMetadataWithNotify(x+13, y+14, z+8, 4, 4);
        this.setBlockState(new BlockPos(x+24, y+14, z+8), leaves);
        this.setBlockMetadataWithNotify(x+24, y+14, z+8, 4, 4);
        this.setBlockState(new BlockPos(x+0, y+14, z+9), leaves);
        this.setBlockMetadataWithNotify(x+0, y+14, z+9, 4, 4);
        this.setBlockState(new BlockPos(x+3, y+14, z+9), leaves);
        this.setBlockMetadataWithNotify(x+3, y+14, z+9, 4, 4);
        this.setBlockState(new BlockPos(x+4, y+14, z+9), leaves);
        this.setBlockMetadataWithNotify(x+4, y+14, z+9, 4, 4);
        this.setBlockState(new BlockPos(x+6, y+14, z+9), log);
        this.setBlockState(new BlockPos(x+25, y+14, z+9), leaves);
        this.setBlockMetadataWithNotify(x+25, y+14, z+9, 4, 4);
        this.setBlockState(new BlockPos(x+4, y+14, z+10), leaves);
        this.setBlockMetadataWithNotify(x+4, y+14, z+10, 4, 4);
        this.setBlockState(new BlockPos(x+5, y+14, z+10), leaves);
        this.setBlockMetadataWithNotify(x+5, y+14, z+10, 4, 4);
        this.setBlockState(new BlockPos(x+7, y+14, z+10), leaves);
        this.setBlockMetadataWithNotify(x+7, y+14, z+10, 4, 4);
        this.setBlockState(new BlockPos(x+11, y+14, z+10), log);
        this.setBlockState(new BlockPos(x+21, y+14, z+10), leaves);
        this.setBlockMetadataWithNotify(x+21, y+14, z+10, 4, 4);
        this.setBlockState(new BlockPos(x+25, y+14, z+10), leaves);
        this.setBlockMetadataWithNotify(x+25, y+14, z+10, 4, 4);
        this.setBlockState(new BlockPos(x+9, y+14, z+11), leaves);
        this.setBlockMetadataWithNotify(x+9, y+14, z+11, 4, 4);
        this.setBlockState(new BlockPos(x+3, y+14, z+12), leaves);
        this.setBlockMetadataWithNotify(x+3, y+14, z+12, 4, 4);
        this.setBlockState(new BlockPos(x+8, y+14, z+12), leaves);
        this.setBlockMetadataWithNotify(x+8, y+14, z+12, 4, 4);
        this.setBlockState(new BlockPos(x+17, y+14, z+12), leaves);
        this.setBlockMetadataWithNotify(x+17, y+14, z+12, 4, 4);
        this.setBlockState(new BlockPos(x+5, y+14, z+13), leaves);
        this.setBlockMetadataWithNotify(x+5, y+14, z+13, 4, 4);
        this.setBlockState(new BlockPos(x+16, y+14, z+13), leaves);
        this.setBlockMetadataWithNotify(x+16, y+14, z+13, 4, 4);
        this.setBlockState(new BlockPos(x+12, y+14, z+15), leaves);
        this.setBlockMetadataWithNotify(x+12, y+14, z+15, 4, 4);
        this.setBlockState(new BlockPos(x+11, y+14, z+16), leaves);
        this.setBlockMetadataWithNotify(x+11, y+14, z+16, 4, 4);
        this.setBlockState(new BlockPos(x+13, y+14, z+16), leaves);
        this.setBlockMetadataWithNotify(x+13, y+14, z+16, 4, 4);
        this.setBlockState(new BlockPos(x+14, y+14, z+17), leaves);
        this.setBlockMetadataWithNotify(x+14, y+14, z+17, 4, 4);
        this.setBlockState(new BlockPos(x+18, y+14, z+17), leaves);
        this.setBlockMetadataWithNotify(x+18, y+14, z+17, 4, 4);
        this.setBlockState(new BlockPos(x+6, y+14, z+18), leaves);
        this.setBlockMetadataWithNotify(x+6, y+14, z+18, 4, 4);
        this.setBlockState(new BlockPos(x+18, y+14, z+18), leaves);
        this.setBlockMetadataWithNotify(x+18, y+14, z+18, 4, 4);
        this.setBlockState(new BlockPos(x+18, y+14, z+19), leaves);
        this.setBlockMetadataWithNotify(x+18, y+14, z+19, 4, 4);
        this.setBlockState(new BlockPos(x+7, y+14, z+20), leaves);
        this.setBlockMetadataWithNotify(x+7, y+14, z+20, 4, 4);
        this.setBlockState(new BlockPos(x+8, y+14, z+20), leaves);
        this.setBlockMetadataWithNotify(x+8, y+14, z+20, 4, 4);
        this.setBlockState(new BlockPos(x+10, y+14, z+20), leaves);
        this.setBlockMetadataWithNotify(x+10, y+14, z+20, 4, 4);
        this.setBlockState(new BlockPos(x+18, y+14, z+20), leaves);
        this.setBlockMetadataWithNotify(x+18, y+14, z+20, 4, 4);
        this.setBlockState(new BlockPos(x+9, y+14, z+21), leaves);
        this.setBlockMetadataWithNotify(x+9, y+14, z+21, 4, 4);
        this.setBlockState(new BlockPos(x+10, y+14, z+21), leaves);
        this.setBlockMetadataWithNotify(x+10, y+14, z+21, 4, 4);
        this.setBlockState(new BlockPos(x+16, y+14, z+21), leaves);
        this.setBlockMetadataWithNotify(x+16, y+14, z+21, 4, 4);
        this.setBlockState(new BlockPos(x+18, y+14, z+21), leaves);
        this.setBlockMetadataWithNotify(x+18, y+14, z+21, 4, 4);
        this.setBlockState(new BlockPos(x+12, y+14, z+22), log);
        this.setBlockState(new BlockPos(x+17, y+14, z+22), leaves);
        this.setBlockMetadataWithNotify(x+17, y+14, z+22, 4, 4);
        this.setBlockState(new BlockPos(x+19, y+14, z+22), leaves);
        this.setBlockMetadataWithNotify(x+19, y+14, z+22, 4, 4);
        this.setBlockState(new BlockPos(x+12, y+14, z+23), leaves);
        this.setBlockMetadataWithNotify(x+12, y+14, z+23, 4, 4);
        this.setBlockState(new BlockPos(x+15, y+14, z+23), leaves);
        this.setBlockMetadataWithNotify(x+15, y+14, z+23, 4, 4);
        this.setBlockState(new BlockPos(x+18, y+14, z+23), leaves);
        this.setBlockMetadataWithNotify(x+18, y+14, z+23, 4, 4);
        this.setBlockState(new BlockPos(x+8, y+14, z+24), leaves);
        this.setBlockMetadataWithNotify(x+8, y+14, z+24, 8, 8);
        this.setBlockState(new BlockPos(x+14, y+14, z+24), leaves);
        this.setBlockMetadataWithNotify(x+14, y+14, z+24, 4, 4);
        this.setBlockState(new BlockPos(x+16, y+14, z+24), log);
        this.setBlockState(new BlockPos(x+16, y+14, z+25), log);
        this.setBlockState(new BlockPos(x+7, y+14, z+26), leaves);
        this.setBlockMetadataWithNotify(x+7, y+14, z+26, 4, 4);
        this.setBlockState(new BlockPos(x+10, y+14, z+26), leaves);
        this.setBlockMetadataWithNotify(x+10, y+14, z+26, 4, 4);
        this.setBlockState(new BlockPos(x+14, y+14, z+26), leaves);
        this.setBlockMetadataWithNotify(x+14, y+14, z+26, 4, 4);
        this.setBlockState(new BlockPos(x+19, y+14, z+26), leaves);
        this.setBlockMetadataWithNotify(x+19, y+14, z+26, 4, 4);
        this.setBlockState(new BlockPos(x+11, y+14, z+27), leaves);
        this.setBlockMetadataWithNotify(x+11, y+14, z+27, 4, 4);
        this.setBlockState(new BlockPos(x+16, y+14, z+27), leaves);
        this.setBlockMetadataWithNotify(x+16, y+14, z+27, 12, 12);
        this.setBlockState(new BlockPos(x+10, y+15, z+0), leaves);
        this.setBlockMetadataWithNotify(x+10, y+15, z+0, 4, 4);
        this.setBlockState(new BlockPos(x+7, y+15, z+1), leaves);
        this.setBlockMetadataWithNotify(x+7, y+15, z+1, 4, 4);
        this.setBlockState(new BlockPos(x+8, y+15, z+2), leaves);
        this.setBlockMetadataWithNotify(x+8, y+15, z+2, 4, 4);
        this.setBlockState(new BlockPos(x+8, y+15, z+3), leaves);
        this.setBlockMetadataWithNotify(x+8, y+15, z+3, 4, 4);
        this.setBlockState(new BlockPos(x+12, y+15, z+3), leaves);
        this.setBlockMetadataWithNotify(x+12, y+15, z+3, 4, 4);
        this.setBlockState(new BlockPos(x+19, y+15, z+3), leaves);
        this.setBlockMetadataWithNotify(x+19, y+15, z+3, 4, 4);
        this.setBlockState(new BlockPos(x+7, y+15, z+4), leaves);
        this.setBlockMetadataWithNotify(x+7, y+15, z+4, 4, 4);
        this.setBlockState(new BlockPos(x+15, y+15, z+4), leaves);
        this.setBlockMetadataWithNotify(x+15, y+15, z+4, 4, 4);
        this.setBlockState(new BlockPos(x+21, y+15, z+4), leaves);
        this.setBlockMetadataWithNotify(x+21, y+15, z+4, 4, 4);
        this.setBlockState(new BlockPos(x+3, y+15, z+5), leaves);
        this.setBlockMetadataWithNotify(x+3, y+15, z+5, 4, 4);
        this.setBlockState(new BlockPos(x+7, y+15, z+5), leaves);
        this.setBlockMetadataWithNotify(x+7, y+15, z+5, 4, 4);
        this.setBlockState(new BlockPos(x+9, y+15, z+5), leaves);
        this.setBlockMetadataWithNotify(x+9, y+15, z+5, 4, 4);
        this.setBlockState(new BlockPos(x+13, y+15, z+5), leaves);
        this.setBlockMetadataWithNotify(x+13, y+15, z+5, 4, 4);
        this.setBlockState(new BlockPos(x+15, y+15, z+5), leaves);
        this.setBlockMetadataWithNotify(x+15, y+15, z+5, 4, 4);
        this.setBlockState(new BlockPos(x+21, y+15, z+5), leaves);
        this.setBlockMetadataWithNotify(x+21, y+15, z+5, 4, 4);
        this.setBlockState(new BlockPos(x+11, y+15, z+6), leaves);
        this.setBlockMetadataWithNotify(x+11, y+15, z+6, 4, 4);
        this.setBlockState(new BlockPos(x+12, y+15, z+6), leaves);
        this.setBlockMetadataWithNotify(x+12, y+15, z+6, 4, 4);
        this.setBlockState(new BlockPos(x+18, y+15, z+6), leaves);
        this.setBlockMetadataWithNotify(x+18, y+15, z+6, 12, 12);
        this.setBlockState(new BlockPos(x+23, y+15, z+6), leaves);
        this.setBlockMetadataWithNotify(x+23, y+15, z+6, 4, 4);
        this.setBlockState(new BlockPos(x+1, y+15, z+7), leaves);
        this.setBlockMetadataWithNotify(x+1, y+15, z+7, 4, 4);
        this.setBlockState(new BlockPos(x+7, y+15, z+7), log);
        this.setBlockState(new BlockPos(x+8, y+15, z+7), leaves);
        this.setBlockMetadataWithNotify(x+8, y+15, z+7, 4, 4);
        this.setBlockState(new BlockPos(x+15, y+15, z+7), leaves);
        this.setBlockMetadataWithNotify(x+15, y+15, z+7, 4, 4);
        this.setBlockState(new BlockPos(x+18, y+15, z+7), leaves);
        this.setBlockMetadataWithNotify(x+18, y+15, z+7, 12, 12);
        this.setBlockState(new BlockPos(x+22, y+15, z+7), leaves);
        this.setBlockMetadataWithNotify(x+22, y+15, z+7, 4, 4);
        this.setBlockState(new BlockPos(x+5, y+15, z+8), log);
        this.setBlockState(new BlockPos(x+6, y+15, z+8), leaves);
        this.setBlockMetadataWithNotify(x+6, y+15, z+8, 4, 4);
        this.setBlockState(new BlockPos(x+8, y+15, z+8), leaves);
        this.setBlockMetadataWithNotify(x+8, y+15, z+8, 4, 4);
        this.setBlockState(new BlockPos(x+11, y+15, z+8), leaves);
        this.setBlockMetadataWithNotify(x+11, y+15, z+8, 4, 4);
        this.setBlockState(new BlockPos(x+12, y+15, z+8), leaves);
        this.setBlockMetadataWithNotify(x+12, y+15, z+8, 4, 4);
        this.setBlockState(new BlockPos(x+18, y+15, z+8), leaves);
        this.setBlockMetadataWithNotify(x+18, y+15, z+8, 12, 12);
        this.setBlockState(new BlockPos(x+19, y+15, z+8), leaves);
        this.setBlockMetadataWithNotify(x+19, y+15, z+8, 12, 12);
        this.setBlockState(new BlockPos(x+21, y+15, z+8), leaves);
        this.setBlockMetadataWithNotify(x+21, y+15, z+8, 4, 4);
        this.setBlockState(new BlockPos(x+22, y+15, z+8), leaves);
        this.setBlockMetadataWithNotify(x+22, y+15, z+8, 4, 4);
        this.setBlockState(new BlockPos(x+0, y+15, z+9), leaves);
        this.setBlockMetadataWithNotify(x+0, y+15, z+9, 4, 4);
        this.setBlockState(new BlockPos(x+15, y+15, z+9), leaves);
        this.setBlockMetadataWithNotify(x+15, y+15, z+9, 4, 4);
        this.setBlockState(new BlockPos(x+22, y+15, z+9), leaves);
        this.setBlockMetadataWithNotify(x+22, y+15, z+9, 4, 4);
        this.setBlockState(new BlockPos(x+23, y+15, z+9), leaves);
        this.setBlockMetadataWithNotify(x+23, y+15, z+9, 4, 4);
        this.setBlockState(new BlockPos(x+24, y+15, z+9), leaves);
        this.setBlockMetadataWithNotify(x+24, y+15, z+9, 4, 4);
        this.setBlockState(new BlockPos(x+3, y+15, z+10), leaves);
        this.setBlockMetadataWithNotify(x+3, y+15, z+10, 4, 4);
        this.setBlockState(new BlockPos(x+5, y+15, z+10), leaves);
        this.setBlockMetadataWithNotify(x+5, y+15, z+10, 4, 4);
        this.setBlockState(new BlockPos(x+9, y+15, z+10), leaves);
        this.setBlockMetadataWithNotify(x+9, y+15, z+10, 4, 4);
        this.setBlockState(new BlockPos(x+12, y+15, z+10), log);
        this.setBlockState(new BlockPos(x+15, y+15, z+10), leaves);
        this.setBlockMetadataWithNotify(x+15, y+15, z+10, 4, 4);
        this.setBlockState(new BlockPos(x+16, y+15, z+10), leaves);
        this.setBlockMetadataWithNotify(x+16, y+15, z+10, 4, 4);
        this.setBlockState(new BlockPos(x+23, y+15, z+10), leaves);
        this.setBlockMetadataWithNotify(x+23, y+15, z+10, 4, 4);
        this.setBlockState(new BlockPos(x+24, y+15, z+10), leaves);
        this.setBlockMetadataWithNotify(x+24, y+15, z+10, 4, 4);
        this.setBlockState(new BlockPos(x+2, y+15, z+11), leaves);
        this.setBlockMetadataWithNotify(x+2, y+15, z+11, 4, 4);
        this.setBlockState(new BlockPos(x+3, y+15, z+11), leaves);
        this.setBlockMetadataWithNotify(x+3, y+15, z+11, 4, 4);
        this.setBlockState(new BlockPos(x+7, y+15, z+11), leaves);
        this.setBlockMetadataWithNotify(x+7, y+15, z+11, 4, 4);
        this.setBlockState(new BlockPos(x+8, y+15, z+11), leaves);
        this.setBlockMetadataWithNotify(x+8, y+15, z+11, 4, 4);
        this.setBlockState(new BlockPos(x+20, y+15, z+11), leaves);
        this.setBlockMetadataWithNotify(x+20, y+15, z+11, 4, 4);
        this.setBlockState(new BlockPos(x+21, y+15, z+11), leaves);
        this.setBlockMetadataWithNotify(x+21, y+15, z+11, 4, 4);
        this.setBlockState(new BlockPos(x+22, y+15, z+11), leaves);
        this.setBlockMetadataWithNotify(x+22, y+15, z+11, 4, 4);
        this.setBlockState(new BlockPos(x+2, y+15, z+12), leaves);
        this.setBlockMetadataWithNotify(x+2, y+15, z+12, 4, 4);
        this.setBlockState(new BlockPos(x+7, y+15, z+12), leaves);
        this.setBlockMetadataWithNotify(x+7, y+15, z+12, 4, 4);
        this.setBlockState(new BlockPos(x+17, y+15, z+13), leaves);
        this.setBlockMetadataWithNotify(x+17, y+15, z+13, 4, 4);
        this.setBlockState(new BlockPos(x+19, y+15, z+13), leaves);
        this.setBlockMetadataWithNotify(x+19, y+15, z+13, 4, 4);
        this.setBlockState(new BlockPos(x+18, y+15, z+14), leaves);
        this.setBlockMetadataWithNotify(x+18, y+15, z+14, 4, 4);
        this.setBlockState(new BlockPos(x+19, y+15, z+14), leaves);
        this.setBlockMetadataWithNotify(x+19, y+15, z+14, 4, 4);
        this.setBlockState(new BlockPos(x+13, y+15, z+15), leaves);
        this.setBlockMetadataWithNotify(x+13, y+15, z+15, 4, 4);
        this.setBlockState(new BlockPos(x+13, y+15, z+16), leaves);
        this.setBlockMetadataWithNotify(x+13, y+15, z+16, 4, 4);
        this.setBlockState(new BlockPos(x+8, y+15, z+17), leaves);
        this.setBlockMetadataWithNotify(x+8, y+15, z+17, 4, 4);
        this.setBlockState(new BlockPos(x+18, y+15, z+17), leaves);
        this.setBlockMetadataWithNotify(x+18, y+15, z+17, 4, 4);
        this.setBlockState(new BlockPos(x+7, y+15, z+19), leaves);
        this.setBlockMetadataWithNotify(x+7, y+15, z+19, 4, 4);
        this.setBlockState(new BlockPos(x+8, y+15, z+19), leaves);
        this.setBlockMetadataWithNotify(x+8, y+15, z+19, 4, 4);
        this.setBlockState(new BlockPos(x+5, y+15, z+20), leaves);
        this.setBlockMetadataWithNotify(x+5, y+15, z+20, 4, 4);
        this.setBlockState(new BlockPos(x+8, y+15, z+20), leaves);
        this.setBlockMetadataWithNotify(x+8, y+15, z+20, 4, 4);
        this.setBlockState(new BlockPos(x+18, y+15, z+20), leaves);
        this.setBlockMetadataWithNotify(x+18, y+15, z+20, 4, 4);
        this.setBlockState(new BlockPos(x+7, y+15, z+21), leaves);
        this.setBlockMetadataWithNotify(x+7, y+15, z+21, 4, 4);
        this.setBlockState(new BlockPos(x+11, y+15, z+21), leaves);
        this.setBlockMetadataWithNotify(x+11, y+15, z+21, 4, 4);
        this.setBlockState(new BlockPos(x+18, y+15, z+21), leaves);
        this.setBlockMetadataWithNotify(x+18, y+15, z+21, 4, 4);
        this.setBlockState(new BlockPos(x+5, y+15, z+22), leaves);
        this.setBlockMetadataWithNotify(x+5, y+15, z+22, 4, 4);
        this.setBlockState(new BlockPos(x+6, y+15, z+22), leaves);
        this.setBlockMetadataWithNotify(x+6, y+15, z+22, 4, 4);
        this.setBlockState(new BlockPos(x+12, y+15, z+22), log);
        this.setBlockState(new BlockPos(x+9, y+15, z+23), leaves);
        this.setBlockMetadataWithNotify(x+9, y+15, z+23, 4, 4);
        this.setBlockState(new BlockPos(x+13, y+15, z+23), log);
        this.setBlockState(new BlockPos(x+17, y+15, z+23), leaves);
        this.setBlockMetadataWithNotify(x+17, y+15, z+23, 4, 4);
        this.setBlockState(new BlockPos(x+7, y+15, z+24), leaves);
        this.setBlockMetadataWithNotify(x+7, y+15, z+24, 4, 4);
        this.setBlockState(new BlockPos(x+11, y+15, z+24), leaves);
        this.setBlockMetadataWithNotify(x+11, y+15, z+24, 4, 4);
        this.setBlockState(new BlockPos(x+16, y+15, z+24), leaves);
        this.setBlockMetadataWithNotify(x+16, y+15, z+24, 4, 4);
        this.setBlockState(new BlockPos(x+14, y+15, z+25), leaves);
        this.setBlockMetadataWithNotify(x+14, y+15, z+25, 4, 4);
        this.setBlockState(new BlockPos(x+17, y+15, z+25), leaves);
        this.setBlockMetadataWithNotify(x+17, y+15, z+25, 12, 12);
        this.setBlockState(new BlockPos(x+9, y+15, z+26), leaves);
        this.setBlockMetadataWithNotify(x+9, y+15, z+26, 4, 4);
        this.setBlockState(new BlockPos(x+13, y+15, z+26), leaves);
        this.setBlockMetadataWithNotify(x+13, y+15, z+26, 4, 4);
        this.setBlockState(new BlockPos(x+14, y+15, z+26), leaves);
        this.setBlockMetadataWithNotify(x+14, y+15, z+26, 4, 4);
        this.setBlockState(new BlockPos(x+16, y+15, z+26), log);
        this.setBlockState(new BlockPos(x+19, y+15, z+26), leaves);
        this.setBlockMetadataWithNotify(x+19, y+15, z+26, 4, 4);
        this.setBlockState(new BlockPos(x+17, y+15, z+27), leaves);
        this.setBlockMetadataWithNotify(x+17, y+15, z+27, 8, 8);
        this.setBlockState(new BlockPos(x+15, y+15, z+28), leaves);
        this.setBlockMetadataWithNotify(x+15, y+15, z+28, 4, 4);
        this.setBlockState(new BlockPos(x+16, y+15, z+28), leaves);
        this.setBlockMetadataWithNotify(x+16, y+15, z+28, 4, 4);
        this.setBlockState(new BlockPos(x+6, y+16, z+1), leaves);
        this.setBlockMetadataWithNotify(x+6, y+16, z+1, 4, 4);
        this.setBlockState(new BlockPos(x+8, y+16, z+1), leaves);
        this.setBlockMetadataWithNotify(x+8, y+16, z+1, 4, 4);
        this.setBlockState(new BlockPos(x+10, y+16, z+1), leaves);
        this.setBlockMetadataWithNotify(x+10, y+16, z+1, 4, 4);
        this.setBlockState(new BlockPos(x+11, y+16, z+1), leaves);
        this.setBlockMetadataWithNotify(x+11, y+16, z+1, 4, 4);
        this.setBlockState(new BlockPos(x+18, y+16, z+1), leaves);
        this.setBlockMetadataWithNotify(x+18, y+16, z+1, 4, 4);
        this.setBlockState(new BlockPos(x+5, y+16, z+2), leaves);
        this.setBlockMetadataWithNotify(x+5, y+16, z+2, 4, 4);
        this.setBlockState(new BlockPos(x+6, y+16, z+2), leaves);
        this.setBlockMetadataWithNotify(x+6, y+16, z+2, 4, 4);
        this.setBlockState(new BlockPos(x+8, y+16, z+2), leaves);
        this.setBlockMetadataWithNotify(x+8, y+16, z+2, 4, 4);
        this.setBlockState(new BlockPos(x+9, y+16, z+2), leaves);
        this.setBlockMetadataWithNotify(x+9, y+16, z+2, 4, 4);
        this.setBlockState(new BlockPos(x+10, y+16, z+2), leaves);
        this.setBlockMetadataWithNotify(x+10, y+16, z+2, 4, 4);
        this.setBlockState(new BlockPos(x+16, y+16, z+2), leaves);
        this.setBlockMetadataWithNotify(x+16, y+16, z+2, 4, 4);
        this.setBlockState(new BlockPos(x+17, y+16, z+2), leaves);
        this.setBlockMetadataWithNotify(x+17, y+16, z+2, 4, 4);
        this.setBlockState(new BlockPos(x+20, y+16, z+2), leaves);
        this.setBlockMetadataWithNotify(x+20, y+16, z+2, 4, 4);
        this.setBlockState(new BlockPos(x+6, y+16, z+3), leaves);
        this.setBlockMetadataWithNotify(x+6, y+16, z+3, 4, 4);
        this.setBlockState(new BlockPos(x+7, y+16, z+3), leaves);
        this.setBlockMetadataWithNotify(x+7, y+16, z+3, 4, 4);
        this.setBlockState(new BlockPos(x+11, y+16, z+3), leaves);
        this.setBlockMetadataWithNotify(x+11, y+16, z+3, 4, 4);
        this.setBlockState(new BlockPos(x+19, y+16, z+3), leaves);
        this.setBlockMetadataWithNotify(x+19, y+16, z+3, 4, 4);
        this.setBlockState(new BlockPos(x+20, y+16, z+3), leaves);
        this.setBlockMetadataWithNotify(x+20, y+16, z+3, 4, 4);
        this.setBlockState(new BlockPos(x+8, y+16, z+4), leaves);
        this.setBlockMetadataWithNotify(x+8, y+16, z+4, 4, 4);
        this.setBlockState(new BlockPos(x+20, y+16, z+5), leaves);
        this.setBlockMetadataWithNotify(x+20, y+16, z+5, 4, 4);
        this.setBlockState(new BlockPos(x+2, y+16, z+6), leaves);
        this.setBlockMetadataWithNotify(x+2, y+16, z+6, 4, 4);
        this.setBlockState(new BlockPos(x+7, y+16, z+6), leaves);
        this.setBlockMetadataWithNotify(x+7, y+16, z+6, 4, 4);
        this.setBlockState(new BlockPos(x+8, y+16, z+6), leaves);
        this.setBlockMetadataWithNotify(x+8, y+16, z+6, 4, 4);
        this.setBlockState(new BlockPos(x+22, y+16, z+6), leaves);
        this.setBlockMetadataWithNotify(x+22, y+16, z+6, 4, 4);
        this.setBlockState(new BlockPos(x+23, y+16, z+6), leaves);
        this.setBlockMetadataWithNotify(x+23, y+16, z+6, 4, 4);
        this.setBlockState(new BlockPos(x+1, y+16, z+7), leaves);
        this.setBlockMetadataWithNotify(x+1, y+16, z+7, 4, 4);
        this.setBlockState(new BlockPos(x+2, y+16, z+7), leaves);
        this.setBlockMetadataWithNotify(x+2, y+16, z+7, 4, 4);
        this.setBlockState(new BlockPos(x+3, y+16, z+7), leaves);
        this.setBlockMetadataWithNotify(x+3, y+16, z+7, 4, 4);
        this.setBlockState(new BlockPos(x+7, y+16, z+7), log);
        this.setBlockState(new BlockPos(x+9, y+16, z+7), leaves);
        this.setBlockMetadataWithNotify(x+9, y+16, z+7, 4, 4);
        this.setBlockState(new BlockPos(x+12, y+16, z+7), leaves);
        this.setBlockMetadataWithNotify(x+12, y+16, z+7, 4, 4);
        this.setBlockState(new BlockPos(x+14, y+16, z+7), leaves);
        this.setBlockMetadataWithNotify(x+14, y+16, z+7, 4, 4);
        this.setBlockState(new BlockPos(x+17, y+16, z+7), leaves);
        this.setBlockMetadataWithNotify(x+17, y+16, z+7, 12, 12);
        this.setBlockState(new BlockPos(x+2, y+16, z+8), leaves);
        this.setBlockMetadataWithNotify(x+2, y+16, z+8, 4, 4);
        this.setBlockState(new BlockPos(x+3, y+16, z+8), leaves);
        this.setBlockMetadataWithNotify(x+3, y+16, z+8, 4, 4);
        this.setBlockState(new BlockPos(x+4, y+16, z+8), leaves);
        this.setBlockMetadataWithNotify(x+4, y+16, z+8, 4, 4);
        this.setBlockState(new BlockPos(x+5, y+16, z+8), log);
        this.setBlockState(new BlockPos(x+8, y+16, z+8), leaves);
        this.setBlockMetadataWithNotify(x+8, y+16, z+8, 4, 4);
        this.setBlockState(new BlockPos(x+9, y+16, z+8), leaves);
        this.setBlockMetadataWithNotify(x+9, y+16, z+8, 4, 4);
        this.setBlockState(new BlockPos(x+10, y+16, z+8), leaves);
        this.setBlockMetadataWithNotify(x+10, y+16, z+8, 4, 4);
        this.setBlockState(new BlockPos(x+21, y+16, z+8), leaves);
        this.setBlockMetadataWithNotify(x+21, y+16, z+8, 4, 4);
        this.setBlockState(new BlockPos(x+5, y+16, z+9), leaves);
        this.setBlockMetadataWithNotify(x+5, y+16, z+9, 4, 4);
        this.setBlockState(new BlockPos(x+19, y+16, z+9), leaves);
        this.setBlockMetadataWithNotify(x+19, y+16, z+9, 4, 4);
        this.setBlockState(new BlockPos(x+20, y+16, z+9), leaves);
        this.setBlockMetadataWithNotify(x+20, y+16, z+9, 4, 4);
        this.setBlockState(new BlockPos(x+21, y+16, z+9), leaves);
        this.setBlockMetadataWithNotify(x+21, y+16, z+9, 4, 4);
        this.setBlockState(new BlockPos(x+24, y+16, z+9), leaves);
        this.setBlockMetadataWithNotify(x+24, y+16, z+9, 4, 4);
        this.setBlockState(new BlockPos(x+25, y+16, z+9), leaves);
        this.setBlockMetadataWithNotify(x+25, y+16, z+9, 4, 4);
        this.setBlockState(new BlockPos(x+4, y+16, z+10), leaves);
        this.setBlockMetadataWithNotify(x+4, y+16, z+10, 4, 4);
        this.setBlockState(new BlockPos(x+13, y+16, z+10), log);
        this.setBlockState(new BlockPos(x+14, y+16, z+10), log);
        this.setBlockState(new BlockPos(x+15, y+16, z+10), log);
        this.setBlockState(new BlockPos(x+17, y+16, z+10), leaves);
        this.setBlockMetadataWithNotify(x+17, y+16, z+10, 4, 4);
        this.setBlockState(new BlockPos(x+18, y+16, z+10), leaves);
        this.setBlockMetadataWithNotify(x+18, y+16, z+10, 4, 4);
        this.setBlockState(new BlockPos(x+16, y+16, z+11), leaves);
        this.setBlockMetadataWithNotify(x+16, y+16, z+11, 4, 4);
        this.setBlockState(new BlockPos(x+17, y+16, z+11), leaves);
        this.setBlockMetadataWithNotify(x+17, y+16, z+11, 4, 4);
        this.setBlockState(new BlockPos(x+21, y+16, z+11), leaves);
        this.setBlockMetadataWithNotify(x+21, y+16, z+11, 4, 4);
        this.setBlockState(new BlockPos(x+17, y+16, z+12), leaves);
        this.setBlockMetadataWithNotify(x+17, y+16, z+12, 4, 4);
        this.setBlockState(new BlockPos(x+16, y+16, z+13), leaves);
        this.setBlockMetadataWithNotify(x+16, y+16, z+13, 4, 4);
        this.setBlockState(new BlockPos(x+20, y+16, z+13), leaves);
        this.setBlockMetadataWithNotify(x+20, y+16, z+13, 4, 4);
        this.setBlockState(new BlockPos(x+4, y+16, z+14), leaves);
        this.setBlockMetadataWithNotify(x+4, y+16, z+14, 4, 4);
        this.setBlockState(new BlockPos(x+7, y+16, z+15), leaves);
        this.setBlockMetadataWithNotify(x+7, y+16, z+15, 4, 4);
        this.setBlockState(new BlockPos(x+16, y+16, z+15), leaves);
        this.setBlockMetadataWithNotify(x+16, y+16, z+15, 4, 4);
        this.setBlockState(new BlockPos(x+7, y+16, z+17), leaves);
        this.setBlockMetadataWithNotify(x+7, y+16, z+17, 4, 4);
        this.setBlockState(new BlockPos(x+8, y+16, z+17), leaves);
        this.setBlockMetadataWithNotify(x+8, y+16, z+17, 4, 4);
        this.setBlockState(new BlockPos(x+9, y+16, z+17), leaves);
        this.setBlockMetadataWithNotify(x+9, y+16, z+17, 4, 4);
        this.setBlockState(new BlockPos(x+10, y+16, z+17), leaves);
        this.setBlockMetadataWithNotify(x+10, y+16, z+17, 4, 4);
        this.setBlockState(new BlockPos(x+8, y+16, z+18), leaves);
        this.setBlockMetadataWithNotify(x+8, y+16, z+18, 4, 4);
        this.setBlockState(new BlockPos(x+9, y+16, z+18), leaves);
        this.setBlockMetadataWithNotify(x+9, y+16, z+18, 4, 4);
        this.setBlockState(new BlockPos(x+19, y+16, z+18), leaves);
        this.setBlockMetadataWithNotify(x+19, y+16, z+18, 4, 4);
        this.setBlockState(new BlockPos(x+6, y+16, z+19), leaves);
        this.setBlockMetadataWithNotify(x+6, y+16, z+19, 4, 4);
        this.setBlockState(new BlockPos(x+10, y+16, z+19), leaves);
        this.setBlockMetadataWithNotify(x+10, y+16, z+19, 4, 4);
        this.setBlockState(new BlockPos(x+15, y+16, z+19), leaves);
        this.setBlockMetadataWithNotify(x+15, y+16, z+19, 4, 4);
        this.setBlockState(new BlockPos(x+5, y+16, z+20), leaves);
        this.setBlockMetadataWithNotify(x+5, y+16, z+20, 4, 4);
        this.setBlockState(new BlockPos(x+9, y+16, z+20), leaves);
        this.setBlockMetadataWithNotify(x+9, y+16, z+20, 4, 4);
        this.setBlockState(new BlockPos(x+12, y+16, z+20), leaves);
        this.setBlockMetadataWithNotify(x+12, y+16, z+20, 4, 4);
        this.setBlockState(new BlockPos(x+16, y+16, z+20), leaves);
        this.setBlockMetadataWithNotify(x+16, y+16, z+20, 4, 4);
        this.setBlockState(new BlockPos(x+18, y+16, z+20), leaves);
        this.setBlockMetadataWithNotify(x+18, y+16, z+20, 4, 4);
        this.setBlockState(new BlockPos(x+19, y+16, z+20), leaves);
        this.setBlockMetadataWithNotify(x+19, y+16, z+20, 4, 4);
        this.setBlockState(new BlockPos(x+11, y+16, z+21), leaves);
        this.setBlockMetadataWithNotify(x+11, y+16, z+21, 4, 4);
        this.setBlockState(new BlockPos(x+14, y+16, z+21), leaves);
        this.setBlockMetadataWithNotify(x+14, y+16, z+21, 4, 4);
        this.setBlockState(new BlockPos(x+17, y+16, z+21), leaves);
        this.setBlockMetadataWithNotify(x+17, y+16, z+21, 4, 4);
        this.setBlockState(new BlockPos(x+7, y+16, z+22), leaves);
        this.setBlockMetadataWithNotify(x+7, y+16, z+22, 4, 4);
        this.setBlockState(new BlockPos(x+8, y+16, z+22), leaves);
        this.setBlockMetadataWithNotify(x+8, y+16, z+22, 4, 4);
        this.setBlockState(new BlockPos(x+11, y+16, z+22), log);
        this.setBlockState(new BlockPos(x+14, y+16, z+22), leaves);
        this.setBlockMetadataWithNotify(x+14, y+16, z+22, 4, 4);
        this.setBlockState(new BlockPos(x+16, y+16, z+22), leaves);
        this.setBlockMetadataWithNotify(x+16, y+16, z+22, 4, 4);
        this.setBlockState(new BlockPos(x+18, y+16, z+22), leaves);
        this.setBlockMetadataWithNotify(x+18, y+16, z+22, 4, 4);
        this.setBlockState(new BlockPos(x+13, y+16, z+23), log);
        this.setBlockState(new BlockPos(x+15, y+16, z+23), leaves);
        this.setBlockMetadataWithNotify(x+15, y+16, z+23, 4, 4);
        this.setBlockState(new BlockPos(x+16, y+16, z+23), leaves);
        this.setBlockMetadataWithNotify(x+16, y+16, z+23, 4, 4);
        this.setBlockState(new BlockPos(x+11, y+16, z+24), leaves);
        this.setBlockMetadataWithNotify(x+11, y+16, z+24, 4, 4);
        this.setBlockState(new BlockPos(x+12, y+16, z+24), leaves);
        this.setBlockMetadataWithNotify(x+12, y+16, z+24, 4, 4);
        this.setBlockState(new BlockPos(x+16, y+16, z+24), leaves);
        this.setBlockMetadataWithNotify(x+16, y+16, z+24, 4, 4);
        this.setBlockState(new BlockPos(x+11, y+16, z+25), leaves);
        this.setBlockMetadataWithNotify(x+11, y+16, z+25, 4, 4);
        this.setBlockState(new BlockPos(x+14, y+16, z+25), leaves);
        this.setBlockMetadataWithNotify(x+14, y+16, z+25, 4, 4);
        this.setBlockState(new BlockPos(x+16, y+16, z+25), leaves);
        this.setBlockMetadataWithNotify(x+16, y+16, z+25, 12, 12);
        this.setBlockState(new BlockPos(x+11, y+16, z+26), leaves);
        this.setBlockMetadataWithNotify(x+11, y+16, z+26, 4, 4);
        this.setBlockState(new BlockPos(x+14, y+16, z+26), leaves);
        this.setBlockMetadataWithNotify(x+14, y+16, z+26, 4, 4);
        this.setBlockState(new BlockPos(x+16, y+16, z+26), leaves);
        this.setBlockMetadataWithNotify(x+16, y+16, z+26, 12, 12);
        this.setBlockState(new BlockPos(x+17, y+16, z+26), leaves);
        this.setBlockMetadataWithNotify(x+17, y+16, z+26, 12, 12);
        this.setBlockState(new BlockPos(x+13, y+16, z+27), leaves);
        this.setBlockMetadataWithNotify(x+13, y+16, z+27, 4, 4);
        this.setBlockState(new BlockPos(x+15, y+16, z+27), leaves);
        this.setBlockMetadataWithNotify(x+15, y+16, z+27, 4, 4);
        this.setBlockState(new BlockPos(x+16, y+16, z+28), leaves);
        this.setBlockMetadataWithNotify(x+16, y+16, z+28, 4, 4);
        this.setBlockState(new BlockPos(x+18, y+16, z+28), leaves);
        this.setBlockMetadataWithNotify(x+18, y+16, z+28, 4, 4);
        this.setBlockState(new BlockPos(x+19, y+17, z+1), leaves);
        this.setBlockMetadataWithNotify(x+19, y+17, z+1, 4, 4);
        this.setBlockState(new BlockPos(x+8, y+17, z+2), leaves);
        this.setBlockMetadataWithNotify(x+8, y+17, z+2, 12, 12);
        this.setBlockState(new BlockPos(x+5, y+17, z+3), leaves);
        this.setBlockMetadataWithNotify(x+5, y+17, z+3, 4, 4);
        this.setBlockState(new BlockPos(x+17, y+17, z+3), leaves);
        this.setBlockMetadataWithNotify(x+17, y+17, z+3, 4, 4);
        this.setBlockState(new BlockPos(x+18, y+17, z+3), leaves);
        this.setBlockMetadataWithNotify(x+18, y+17, z+3, 4, 4);
        this.setBlockState(new BlockPos(x+19, y+17, z+3), leaves);
        this.setBlockMetadataWithNotify(x+19, y+17, z+3, 4, 4);
        this.setBlockState(new BlockPos(x+5, y+17, z+4), leaves);
        this.setBlockMetadataWithNotify(x+5, y+17, z+4, 4, 4);
        this.setBlockState(new BlockPos(x+12, y+17, z+5), leaves);
        this.setBlockMetadataWithNotify(x+12, y+17, z+5, 4, 4);
        this.setBlockState(new BlockPos(x+13, y+17, z+5), leaves);
        this.setBlockMetadataWithNotify(x+13, y+17, z+5, 4, 4);
        this.setBlockState(new BlockPos(x+16, y+17, z+5), leaves);
        this.setBlockMetadataWithNotify(x+16, y+17, z+5, 4, 4);
        this.setBlockState(new BlockPos(x+20, y+17, z+5), leaves);
        this.setBlockMetadataWithNotify(x+20, y+17, z+5, 4, 4);
        this.setBlockState(new BlockPos(x+7, y+17, z+6), leaves);
        this.setBlockMetadataWithNotify(x+7, y+17, z+6, 4, 4);
        this.setBlockState(new BlockPos(x+8, y+17, z+6), log);
        this.setBlockState(new BlockPos(x+14, y+17, z+6), leaves);
        this.setBlockMetadataWithNotify(x+14, y+17, z+6, 4, 4);
        this.setBlockState(new BlockPos(x+15, y+17, z+6), leaves);
        this.setBlockMetadataWithNotify(x+15, y+17, z+6, 4, 4);
        this.setBlockState(new BlockPos(x+1, y+17, z+7), leaves);
        this.setBlockMetadataWithNotify(x+1, y+17, z+7, 4, 4);
        this.setBlockState(new BlockPos(x+4, y+17, z+7), log);
        this.setBlockState(new BlockPos(x+6, y+17, z+7), leaves);
        this.setBlockMetadataWithNotify(x+6, y+17, z+7, 4, 4);
        this.setBlockState(new BlockPos(x+14, y+17, z+7), leaves);
        this.setBlockMetadataWithNotify(x+14, y+17, z+7, 4, 4);
        this.setBlockState(new BlockPos(x+18, y+17, z+7), leaves);
        this.setBlockMetadataWithNotify(x+18, y+17, z+7, 8, 8);
        this.setBlockState(new BlockPos(x+2, y+17, z+8), leaves);
        this.setBlockMetadataWithNotify(x+2, y+17, z+8, 4, 4);
        this.setBlockState(new BlockPos(x+4, y+17, z+8), log);
        this.setBlockState(new BlockPos(x+7, y+17, z+8), leaves);
        this.setBlockMetadataWithNotify(x+7, y+17, z+8, 4, 4);
        this.setBlockState(new BlockPos(x+8, y+17, z+8), leaves);
        this.setBlockMetadataWithNotify(x+8, y+17, z+8, 4, 4);
        this.setBlockState(new BlockPos(x+9, y+17, z+8), leaves);
        this.setBlockMetadataWithNotify(x+9, y+17, z+8, 4, 4);
        this.setBlockState(new BlockPos(x+2, y+17, z+9), leaves);
        this.setBlockMetadataWithNotify(x+2, y+17, z+9, 4, 4);
        this.setBlockState(new BlockPos(x+13, y+17, z+9), leaves);
        this.setBlockMetadataWithNotify(x+13, y+17, z+9, 4, 4);
        this.setBlockState(new BlockPos(x+21, y+17, z+9), leaves);
        this.setBlockState(new BlockPos(x+4, y+17, z+10), leaves);
        this.setBlockMetadataWithNotify(x+4, y+17, z+10, 4, 4);
        this.setBlockState(new BlockPos(x+16, y+17, z+10), log);
        this.setBlockState(new BlockPos(x+17, y+17, z+10), log);
        this.setBlockState(new BlockPos(x+18, y+17, z+10), log);
        this.setBlockState(new BlockPos(x+20, y+17, z+10), leaves);
        this.setBlockMetadataWithNotify(x+20, y+17, z+10, 4, 4);
        this.setBlockState(new BlockPos(x+3, y+17, z+11), leaves);
        this.setBlockMetadataWithNotify(x+3, y+17, z+11, 4, 4);
        this.setBlockState(new BlockPos(x+13, y+17, z+11), leaves);
        this.setBlockMetadataWithNotify(x+13, y+17, z+11, 4, 4);
        this.setBlockState(new BlockPos(x+3, y+17, z+12), leaves);
        this.setBlockMetadataWithNotify(x+3, y+17, z+12, 4, 4);
        this.setBlockState(new BlockPos(x+4, y+17, z+12), leaves);
        this.setBlockMetadataWithNotify(x+4, y+17, z+12, 4, 4);
        this.setBlockState(new BlockPos(x+5, y+17, z+12), leaves);
        this.setBlockMetadataWithNotify(x+5, y+17, z+12, 4, 4);
        this.setBlockState(new BlockPos(x+14, y+17, z+12), leaves);
        this.setBlockMetadataWithNotify(x+14, y+17, z+12, 4, 4);
        this.setBlockState(new BlockPos(x+16, y+17, z+12), leaves);
        this.setBlockMetadataWithNotify(x+16, y+17, z+12, 4, 4);
        this.setBlockState(new BlockPos(x+17, y+17, z+12), leaves);
        this.setBlockMetadataWithNotify(x+17, y+17, z+12, 4, 4);
        this.setBlockState(new BlockPos(x+20, y+17, z+12), leaves);
        this.setBlockMetadataWithNotify(x+20, y+17, z+12, 4, 4);
        this.setBlockState(new BlockPos(x+5, y+17, z+13), leaves);
        this.setBlockMetadataWithNotify(x+5, y+17, z+13, 4, 4);
        this.setBlockState(new BlockPos(x+14, y+17, z+13), leaves);
        this.setBlockMetadataWithNotify(x+14, y+17, z+13, 4, 4);
        this.setBlockState(new BlockPos(x+17, y+17, z+13), leaves);
        this.setBlockMetadataWithNotify(x+17, y+17, z+13, 4, 4);
        this.setBlockState(new BlockPos(x+3, y+17, z+14), leaves);
        this.setBlockMetadataWithNotify(x+3, y+17, z+14, 4, 4);
        this.setBlockState(new BlockPos(x+6, y+17, z+14), leaves);
        this.setBlockMetadataWithNotify(x+6, y+17, z+14, 4, 4);
        this.setBlockState(new BlockPos(x+7, y+17, z+14), leaves);
        this.setBlockMetadataWithNotify(x+7, y+17, z+14, 4, 4);
        this.setBlockState(new BlockPos(x+8, y+17, z+14), leaves);
        this.setBlockMetadataWithNotify(x+8, y+17, z+14, 4, 4);
        this.setBlockState(new BlockPos(x+10, y+17, z+15), leaves);
        this.setBlockMetadataWithNotify(x+10, y+17, z+15, 4, 4);
        this.setBlockState(new BlockPos(x+16, y+17, z+16), leaves);
        this.setBlockMetadataWithNotify(x+16, y+17, z+16, 4, 4);
        this.setBlockState(new BlockPos(x+8, y+17, z+17), leaves);
        this.setBlockMetadataWithNotify(x+8, y+17, z+17, 4, 4);
        this.setBlockState(new BlockPos(x+16, y+17, z+17), leaves);
        this.setBlockMetadataWithNotify(x+16, y+17, z+17, 4, 4);
        this.setBlockState(new BlockPos(x+7, y+17, z+18), leaves);
        this.setBlockMetadataWithNotify(x+7, y+17, z+18, 4, 4);
        this.setBlockState(new BlockPos(x+11, y+17, z+19), leaves);
        this.setBlockMetadataWithNotify(x+11, y+17, z+19, 4, 4);
        this.setBlockState(new BlockPos(x+12, y+17, z+19), leaves);
        this.setBlockMetadataWithNotify(x+12, y+17, z+19, 4, 4);
        this.setBlockState(new BlockPos(x+5, y+17, z+20), leaves);
        this.setBlockMetadataWithNotify(x+5, y+17, z+20, 4, 4);
        this.setBlockState(new BlockPos(x+6, y+17, z+20), leaves);
        this.setBlockMetadataWithNotify(x+6, y+17, z+20, 4, 4);
        this.setBlockState(new BlockPos(x+9, y+17, z+20), leaves);
        this.setBlockMetadataWithNotify(x+9, y+17, z+20, 4, 4);
        this.setBlockState(new BlockPos(x+6, y+17, z+21), leaves);
        this.setBlockMetadataWithNotify(x+6, y+17, z+21, 4, 4);
        this.setBlockState(new BlockPos(x+7, y+17, z+21), leaves);
        this.setBlockMetadataWithNotify(x+7, y+17, z+21, 4, 4);
        this.setBlockState(new BlockPos(x+8, y+17, z+21), leaves);
        this.setBlockMetadataWithNotify(x+8, y+17, z+21, 4, 4);
        this.setBlockState(new BlockPos(x+9, y+17, z+21), leaves);
        this.setBlockMetadataWithNotify(x+9, y+17, z+21, 4, 4);
        this.setBlockState(new BlockPos(x+10, y+17, z+21), leaves);
        this.setBlockMetadataWithNotify(x+10, y+17, z+21, 4, 4);
        this.setBlockState(new BlockPos(x+11, y+17, z+21), leaves);
        this.setBlockMetadataWithNotify(x+11, y+17, z+21, 4, 4);
        this.setBlockState(new BlockPos(x+13, y+17, z+21), leaves);
        this.setBlockMetadataWithNotify(x+13, y+17, z+21, 4, 4);
        this.setBlockState(new BlockPos(x+14, y+17, z+21), leaves);
        this.setBlockMetadataWithNotify(x+14, y+17, z+21, 4, 4);
        this.setBlockState(new BlockPos(x+8, y+17, z+22), leaves);
        this.setBlockMetadataWithNotify(x+8, y+17, z+22, 4, 4);
        this.setBlockState(new BlockPos(x+11, y+17, z+22), log);
        this.setBlockState(new BlockPos(x+12, y+17, z+22), leaves);
        this.setBlockMetadataWithNotify(x+12, y+17, z+22, 4, 4);
        this.setBlockState(new BlockPos(x+13, y+17, z+22), leaves);
        this.setBlockMetadataWithNotify(x+13, y+17, z+22, 4, 4);
        this.setBlockState(new BlockPos(x+8, y+17, z+23), leaves);
        this.setBlockMetadataWithNotify(x+8, y+17, z+23, 4, 4);
        this.setBlockState(new BlockPos(x+10, y+17, z+23), leaves);
        this.setBlockMetadataWithNotify(x+10, y+17, z+23, 4, 4);
        this.setBlockState(new BlockPos(x+11, y+17, z+23), leaves);
        this.setBlockMetadataWithNotify(x+11, y+17, z+23, 4, 4);
        this.setBlockState(new BlockPos(x+12, y+17, z+23), leaves);
        this.setBlockMetadataWithNotify(x+12, y+17, z+23, 4, 4);
        this.setBlockState(new BlockPos(x+9, y+17, z+24), leaves);
        this.setBlockMetadataWithNotify(x+9, y+17, z+24, 4, 4);
        this.setBlockState(new BlockPos(x+14, y+17, z+24), log);
        this.setBlockState(new BlockPos(x+15, y+17, z+24), leaves);
        this.setBlockMetadataWithNotify(x+15, y+17, z+24, 4, 4);
        this.setBlockState(new BlockPos(x+16, y+17, z+24), leaves);
        this.setBlockMetadataWithNotify(x+16, y+17, z+24, 4, 4);
        this.setBlockState(new BlockPos(x+12, y+17, z+25), leaves);
        this.setBlockMetadataWithNotify(x+12, y+17, z+25, 4, 4);
        this.setBlockState(new BlockPos(x+17, y+17, z+25), leaves);
        this.setBlockMetadataWithNotify(x+17, y+17, z+25, 4, 4);
        this.setBlockState(new BlockPos(x+12, y+17, z+26), leaves);
        this.setBlockMetadataWithNotify(x+12, y+17, z+26, 4, 4);
        this.setBlockState(new BlockPos(x+15, y+17, z+26), leaves);
        this.setBlockMetadataWithNotify(x+15, y+17, z+26, 4, 4);
        this.setBlockState(new BlockPos(x+16, y+17, z+26), leaves);
        this.setBlockMetadataWithNotify(x+16, y+17, z+26, 4, 4);
        this.setBlockState(new BlockPos(x+18, y+17, z+28), leaves);
        this.setBlockMetadataWithNotify(x+18, y+17, z+28, 4, 4);
        this.setBlockState(new BlockPos(x+8, y+18, z+0), leaves);
        this.setBlockMetadataWithNotify(x+8, y+18, z+0, 4, 4);
        this.setBlockState(new BlockPos(x+17, y+18, z+0), leaves);
        this.setBlockMetadataWithNotify(x+17, y+18, z+0, 4, 4);
        this.setBlockState(new BlockPos(x+18, y+18, z+0), leaves);
        this.setBlockMetadataWithNotify(x+18, y+18, z+0, 4, 4);
        this.setBlockState(new BlockPos(x+9, y+18, z+1), leaves);
        this.setBlockMetadataWithNotify(x+9, y+18, z+1, 8, 8);
        this.setBlockState(new BlockPos(x+19, y+18, z+1), leaves);
        this.setBlockMetadataWithNotify(x+19, y+18, z+1, 4, 4);
        this.setBlockState(new BlockPos(x+10, y+18, z+2), leaves);
        this.setBlockMetadataWithNotify(x+10, y+18, z+2, 12, 12);
        this.setBlockState(new BlockPos(x+15, y+18, z+2), leaves);
        this.setBlockMetadataWithNotify(x+15, y+18, z+2, 4, 4);
        this.setBlockState(new BlockPos(x+16, y+18, z+2), leaves);
        this.setBlockMetadataWithNotify(x+16, y+18, z+2, 4, 4);
        this.setBlockState(new BlockPos(x+20, y+18, z+2), leaves);
        this.setBlockMetadataWithNotify(x+20, y+18, z+2, 4, 4);
        this.setBlockState(new BlockPos(x+21, y+18, z+2), leaves);
        this.setBlockMetadataWithNotify(x+21, y+18, z+2, 4, 4);
        this.setBlockState(new BlockPos(x+8, y+18, z+3), leaves);
        this.setBlockMetadataWithNotify(x+8, y+18, z+3, 12, 12);
        this.setBlockState(new BlockPos(x+10, y+18, z+3), leaves);
        this.setBlockMetadataWithNotify(x+10, y+18, z+3, 8, 8);
        this.setBlockState(new BlockPos(x+15, y+18, z+3), leaves);
        this.setBlockMetadataWithNotify(x+15, y+18, z+3, 4, 4);
        this.setBlockState(new BlockPos(x+19, y+18, z+3), leaves);
        this.setBlockMetadataWithNotify(x+19, y+18, z+3, 4, 4);
        this.setBlockState(new BlockPos(x+5, y+18, z+4), leaves);
        this.setBlockMetadataWithNotify(x+5, y+18, z+4, 4, 4);
        this.setBlockState(new BlockPos(x+11, y+18, z+4), leaves);
        this.setBlockMetadataWithNotify(x+11, y+18, z+4, 12, 12);
        this.setBlockState(new BlockPos(x+12, y+18, z+4), leaves);
        this.setBlockMetadataWithNotify(x+12, y+18, z+4, 4, 4);
        this.setBlockState(new BlockPos(x+15, y+18, z+4), leaves);
        this.setBlockMetadataWithNotify(x+15, y+18, z+4, 4, 4);
        this.setBlockState(new BlockPos(x+4, y+18, z+5), leaves);
        this.setBlockMetadataWithNotify(x+4, y+18, z+5, 4, 4);
        this.setBlockState(new BlockPos(x+6, y+18, z+5), leaves);
        this.setBlockMetadataWithNotify(x+6, y+18, z+5, 4, 4);
        this.setBlockState(new BlockPos(x+17, y+18, z+5), leaves);
        this.setBlockMetadataWithNotify(x+17, y+18, z+5, 4, 4);
        this.setBlockState(new BlockPos(x+18, y+18, z+5), leaves);
        this.setBlockMetadataWithNotify(x+18, y+18, z+5, 4, 4);
        this.setBlockState(new BlockPos(x+7, y+18, z+6), leaves);
        this.setBlockMetadataWithNotify(x+7, y+18, z+6, 4, 4);
        this.setBlockState(new BlockPos(x+8, y+18, z+6), log);
        this.setBlockState(new BlockPos(x+1, y+18, z+7), leaves);
        this.setBlockMetadataWithNotify(x+1, y+18, z+7, 4, 4);
        this.setBlockState(new BlockPos(x+4, y+18, z+7), log);
        this.setBlockState(new BlockPos(x+6, y+18, z+7), leaves);
        this.setBlockMetadataWithNotify(x+6, y+18, z+7, 4, 4);
        this.setBlockState(new BlockPos(x+15, y+18, z+7), leaves);
        this.setBlockMetadataWithNotify(x+15, y+18, z+7, 4, 4);
        this.setBlockState(new BlockPos(x+19, y+18, z+7), leaves);
        this.setBlockMetadataWithNotify(x+19, y+18, z+7, 4, 4);
        this.setBlockState(new BlockPos(x+2, y+18, z+8), leaves);
        this.setBlockMetadataWithNotify(x+2, y+18, z+8, 4, 4);
        this.setBlockState(new BlockPos(x+16, y+18, z+8), leaves);
        this.setBlockMetadataWithNotify(x+16, y+18, z+8, 4, 4);
        this.setBlockState(new BlockPos(x+9, y+18, z+9), leaves);
        this.setBlockMetadataWithNotify(x+9, y+18, z+9, 4, 4);
        this.setBlockState(new BlockPos(x+19, y+18, z+9), log);
        this.setBlockState(new BlockPos(x+22, y+18, z+9), leaves);
        this.setBlockMetadataWithNotify(x+22, y+18, z+9, 4, 4);
        this.setBlockState(new BlockPos(x+23, y+18, z+9), leaves);
        this.setBlockMetadataWithNotify(x+23, y+18, z+9, 4, 4);
        this.setBlockState(new BlockPos(x+13, y+18, z+10), leaves);
        this.setBlockMetadataWithNotify(x+13, y+18, z+10, 4, 4);
        this.setBlockState(new BlockPos(x+6, y+18, z+11), leaves);
        this.setBlockMetadataWithNotify(x+6, y+18, z+11, 4, 4);
        this.setBlockState(new BlockPos(x+8, y+18, z+11), leaves);
        this.setBlockMetadataWithNotify(x+8, y+18, z+11, 4, 4);
        this.setBlockState(new BlockPos(x+13, y+18, z+11), leaves);
        this.setBlockMetadataWithNotify(x+13, y+18, z+11, 4, 4);
        this.setBlockState(new BlockPos(x+7, y+18, z+12), leaves);
        this.setBlockMetadataWithNotify(x+7, y+18, z+12, 4, 4);
