package appalachia.rtg.world.gen.feature.tree.rtg;

import java.util.ArrayList;
import java.util.Arrays;
import java.util.Random;

import net.minecraft.block.state.IBlockState;
import net.minecraft.init.Blocks;
import net.minecraft.util.math.BlockPos;
import net.minecraft.world.World;

import appalachia.api.AppalachiaBlocks;

/**
 * Tilia Americana (American Basswood)
 * <p>
 * This tree was designed by Lentebriesje and released as part of the 'Custom Tree Repository' project
 * on Planet Minecraft (http://www.planetminecraft.com/project/native-trees-of-europe-template-repository-1779952/).
 * It was converted into Java from its original schematic using the 'Schematic To Java Converter [For Modders]' program
 * by ThisIsMika (http://www.minecraftforum.net/forums/mapping-and-modding/minecraft-tools/2193206-schematic-to-java-converter-for-modders).
 * It has been modified slightly by WhichOnesPink to allow for random variation when generating in the world.
 */
public class TreeAmericanBasswood extends AppalachiaTree {

    public TreeAmericanBasswood() {

        super();
        this.setLogBlock(AppalachiaBlocks.log_american_basswood_01.getDefaultState());
        this.setLeavesBlock(AppalachiaBlocks.leaves_american_basswood_01.getDefaultState());
        this.setFallenLeavesBlock(AppalachiaBlocks.leaves_american_basswood_01_fallen.getDefaultState());
        this.setSaplingBlock(AppalachiaBlocks.sapling_american_basswood_01.getDefaultState());

        this.trunkSize = 2;
        this.validGroundBlocks = new ArrayList<IBlockState>(Arrays.asList(Blocks.GRASS.getDefaultState(), Blocks.DIRT.getDefaultState()));

        this.firstBlockOffsetX = 8;
        this.firstBlockOffsetZ = 7;
    }

    @Override
    public boolean generate(World world, Random rand, BlockPos pos) {
        this.init(world, rand, pos);

        int x = pos.getX();
        int y = pos.getY();
        int z = pos.getZ();

        ArrayList<BlockPos> groundPos = new ArrayList<BlockPos>(){};
        groundPos.add(new BlockPos(x + 8, y, z + 7));
        groundPos.add(new BlockPos(x + 7, y, z + 8));
        groundPos.add(new BlockPos(x + 9, y, z + 8));

        for (int i = 0; i < groundPos.size(); i++) {
            if (!isValidGroundBlock(world, rand, groundPos.get(i), 1)) {
                return false;
            }
        }

        this.spawn(world, x, y - this.rootDepth(), z, this.logBlock, this.leavesBlock);

        return true;
    }

    @Override
    public int rootDepth() {
        return 1;
    }

    @Override
    public int opaqueLeavesChance() {
        return 2;
    }

    protected void spawn(World world, int x, int y, int z, IBlockState log, IBlockState leaves) {

        int currentY = y;

        this.setBlockState(new BlockPos(x + 8, y + 0, z + 7), log);
        this.setBlockState(new BlockPos(x + 8, y + 1, z + 7), log);
        this.setBlockState(new BlockPos(x + 7, y + 1, z + 8), log);
        this.setBlockState(new BlockPos(x + 9, y + 1, z + 8), log);
        this.setBlockState(new BlockPos(x + 8, y + 2, z + 6), log);
        this.setBlockState(new BlockPos(x + 7, y + 2, z + 7), log);
        this.setBlockState(new BlockPos(x + 8, y + 2, z + 7), log);
        this.setBlockState(new BlockPos(x + 7, y + 2, z + 8), log);
        this.setBlockState(new BlockPos(x + 9, y + 2, z + 8), log);
        this.setBlockState(new BlockPos(x + 8, y + 3, z + 6), log);
        this.setBlockState(new BlockPos(x + 7, y + 3, z + 7), log);
        this.setBlockState(new BlockPos(x + 8, y + 3, z + 7), log);
        this.setBlockState(new BlockPos(x + 7, y + 3, z + 8), log);
        this.setBlockState(new BlockPos(x + 9, y + 3, z + 8), log);
        this.setBlockState(new BlockPos(x + 7, y + 4, z + 7), log);
        this.setBlockState(new BlockPos(x + 8, y + 4, z + 7), log);
        this.setBlockState(new BlockPos(x + 7, y + 5, z + 7), log);
        this.setBlockState(new BlockPos(x + 8, y + 5, z + 7), log);
        this.setBlockState(new BlockPos(x + 8, y + 5, z + 9), leaves);
        this.setBlockState(new BlockPos(x + 9, y + 5, z + 9), leaves);
        this.setBlockState(new BlockPos(x + 4, y + 5, z + 10), leaves);
        this.setBlockState(new BlockPos(x + 5, y + 5, z + 10), leaves);
        this.setBlockState(new BlockPos(x + 6, y + 5, z + 10), leaves);
        this.setBlockState(new BlockPos(x + 7, y + 5, z + 10), leaves);
        this.setBlockState(new BlockPos(x + 8, y + 5, z + 10), leaves);
        this.setBlockState(new BlockPos(x + 9, y + 5, z + 10), leaves);
        this.setBlockState(new BlockPos(x + 6, y + 5, z + 11), leaves);
        this.setBlockState(new BlockPos(x + 7, y + 6, z + 7), log);
        this.setBlockState(new BlockPos(x + 8, y + 6, z + 7), log);
        this.setBlockState(new BlockPos(x + 5, y + 6, z + 8), leaves);
        this.setBlockState(new BlockPos(x + 6, y + 6, z + 8), leaves);
        this.setBlockState(new BlockPos(x + 7, y + 6, z + 8), log);
        this.setBlockState(new BlockPos(x + 10, y + 6, z + 8), leaves);
        this.setBlockState(new BlockPos(x + 7, y + 6, z + 9), leaves);
        this.setBlockState(new BlockPos(x + 10, y + 6, z + 9), leaves);
        this.setBlockState(new BlockPos(x + 5, y + 6, z + 10), leaves);
        this.setBlockState(new BlockPos(x + 6, y + 6, z + 10), leaves);
        this.setBlockState(new BlockPos(x + 8, y + 6, z + 10), leaves);
        this.setBlockState(new BlockPos(x + 10, y + 6, z + 10), leaves);
        this.setBlockState(new BlockPos(x + 5, y + 6, z + 11), leaves);
        this.setBlockState(new BlockPos(x + 8, y + 6, z + 11), leaves);
        this.setBlockState(new BlockPos(x + 10, y + 6, z + 11), leaves);
        this.setBlockState(new BlockPos(x + 9, y + 6, z + 12), leaves);
        this.setBlockState(new BlockPos(x + 10, y + 6, z + 12), leaves);
        this.setBlockState(new BlockPos(x + 10, y + 7, z + 4), leaves);
        this.setBlockState(new BlockPos(x + 10, y + 7, z + 6), leaves);
        this.setBlockState(new BlockPos(x + 4, y + 7, z + 7), leaves);
        this.setBlockState(new BlockPos(x + 7, y + 7, z + 7), log);
        this.setBlockState(new BlockPos(x + 8, y + 7, z + 7), leaves);
        this.setBlockState(new BlockPos(x + 6, y + 7, z + 9), log);
        this.setBlockState(new BlockPos(x + 7, y + 7, z + 9), log);
        this.setBlockState(new BlockPos(x + 8, y + 7, z + 9), leaves);
        this.setBlockState(new BlockPos(x + 2, y + 7, z + 10), leaves);
        this.setBlockState(new BlockPos(x + 4, y + 7, z + 10), leaves);
        this.setBlockState(new BlockPos(x + 5, y + 7, z + 10), leaves);
        this.setBlockState(new BlockPos(x + 6, y + 7, z + 10), leaves);
        this.setBlockState(new BlockPos(x + 7, y + 7, z + 10), leaves);
        this.setBlockState(new BlockPos(x + 8, y + 7, z + 10), leaves);
        this.setBlockState(new BlockPos(x + 9, y + 7, z + 10), leaves);
        this.setBlockState(new BlockPos(x + 10, y + 7, z + 10), leaves);
        this.setBlockState(new BlockPos(x + 11, y + 7, z + 10), leaves);
        this.setBlockState(new BlockPos(x + 2, y + 7, z + 11), leaves);
        this.setBlockState(new BlockPos(x + 4, y + 7, z + 11), leaves);
        this.setBlockState(new BlockPos(x + 6, y + 7, z + 11), leaves);
        this.setBlockState(new BlockPos(x + 7, y + 7, z + 11), leaves);
        this.setBlockState(new BlockPos(x + 8, y + 7, z + 11), leaves);
        this.setBlockState(new BlockPos(x + 10, y + 7, z + 11), leaves);
        this.setBlockState(new BlockPos(x + 5, y + 7, z + 12), leaves);
        this.setBlockState(new BlockPos(x + 7, y + 7, z + 12), leaves);
        this.setBlockState(new BlockPos(x + 9, y + 7, z + 12), leaves);
        this.setBlockState(new BlockPos(x + 7, y + 7, z + 13), leaves);
        this.setBlockState(new BlockPos(x + 9, y + 7, z + 13), leaves);
        this.setBlockState(new BlockPos(x + 12, y + 8, z + 3), leaves);
        this.setBlockState(new BlockPos(x + 9, y + 8, z + 4), leaves);
        this.setBlockState(new BlockPos(x + 11, y + 8, z + 4), leaves);
        this.setBlockState(new BlockPos(x + 12, y + 8, z + 4), leaves);
        this.setBlockState(new BlockPos(x + 8, y + 8, z + 5), leaves);
        this.setBlockState(new BlockPos(x + 9, y + 8, z + 5), leaves);
        this.setBlockState(new BlockPos(x + 10, y + 8, z + 5), leaves);
        this.setBlockState(new BlockPos(x + 11, y + 8, z + 5), leaves);
        this.setBlockState(new BlockPos(x + 8, y + 8, z + 6), log);
        this.setBlockState(new BlockPos(x + 4, y + 8, z + 7), leaves);
        this.setBlockState(new BlockPos(x + 5, y + 8, z + 7), leaves);
        this.setBlockState(new BlockPos(x + 7, y + 8, z + 7), log);
        this.setBlockState(new BlockPos(x + 8, y + 8, z + 7), leaves);
        this.setBlockState(new BlockPos(x + 9, y + 8, z + 7), leaves);
        this.setBlockState(new BlockPos(x + 10, y + 8, z + 7), leaves);
        this.setBlockState(new BlockPos(x + 12, y + 8, z + 7), leaves);
        this.setBlockState(new BlockPos(x + 3, y + 8, z + 8), leaves);
        this.setBlockState(new BlockPos(x + 4, y + 8, z + 8), leaves);
        this.setBlockState(new BlockPos(x + 6, y + 8, z + 8), leaves);
        this.setBlockState(new BlockPos(x + 7, y + 8, z + 8), leaves);
        this.setBlockState(new BlockPos(x + 3, y + 8, z + 9), leaves);
        this.setBlockState(new BlockPos(x + 4, y + 8, z + 9), leaves);
        this.setBlockState(new BlockPos(x + 6, y + 8, z + 9), leaves);
        this.setBlockState(new BlockPos(x + 7, y + 8, z + 9), leaves);
        this.setBlockState(new BlockPos(x + 8, y + 8, z + 9), leaves);
        this.setBlockState(new BlockPos(x + 11, y + 8, z + 9), leaves);
        this.setBlockState(new BlockPos(x + 2, y + 8, z + 10), leaves);
        this.setBlockState(new BlockPos(x + 3, y + 8, z + 10), leaves);
        this.setBlockState(new BlockPos(x + 4, y + 8, z + 10), leaves);
        this.setBlockState(new BlockPos(x + 5, y + 8, z + 10), log);
        this.setBlockState(new BlockPos(x + 6, y + 8, z + 10), leaves);
        this.setBlockState(new BlockPos(x + 7, y + 8, z + 10), leaves);
        this.setBlockState(new BlockPos(x + 8, y + 8, z + 10), log);
        this.setBlockState(new BlockPos(x + 9, y + 8, z + 10), leaves);
        this.setBlockState(new BlockPos(x + 3, y + 8, z + 11), leaves);
        this.setBlockState(new BlockPos(x + 5, y + 8, z + 11), leaves);
        this.setBlockState(new BlockPos(x + 6, y + 8, z + 11), log);
        this.setBlockState(new BlockPos(x + 7, y + 8, z + 11), leaves);
        this.setBlockState(new BlockPos(x + 10, y + 8, z + 11), leaves);
        this.setBlockState(new BlockPos(x + 11, y + 8, z + 11), leaves);
        this.setBlockState(new BlockPos(x + 3, y + 8, z + 12), leaves);
        this.setBlockState(new BlockPos(x + 4, y + 8, z + 12), leaves);
        this.setBlockState(new BlockPos(x + 6, y + 8, z + 12), leaves);
        this.setBlockState(new BlockPos(x + 8, y + 8, z + 12), leaves);
        this.setBlockState(new BlockPos(x + 9, y + 8, z + 12), leaves);
        this.setBlockState(new BlockPos(x + 4, y + 8, z + 13), leaves);
        this.setBlockState(new BlockPos(x + 8, y + 8, z + 13), leaves);
        this.setBlockState(new BlockPos(x + 9, y + 8, z + 13), leaves);
        this.setBlockState(new BlockPos(x + 9, y + 9, z + 2), leaves);
        this.setBlockState(new BlockPos(x + 9, y + 9, z + 3), leaves);
        this.setBlockState(new BlockPos(x + 7, y + 9, z + 4), leaves);
        this.setBlockState(new BlockPos(x + 10, y + 9, z + 4), leaves);
        this.setBlockState(new BlockPos(x + 4, y + 9, z + 5), leaves);
        this.setBlockState(new BlockPos(x + 5, y + 9, z + 5), leaves);
        this.setBlockState(new BlockPos(x + 9, y + 9, z + 5), log);
        this.setBlockState(new BlockPos(x + 3, y + 9, z + 6), leaves);
        this.setBlockState(new BlockPos(x + 6, y + 9, z + 6), leaves);
        this.setBlockState(new BlockPos(x + 7, y + 9, z + 6), leaves);
        this.setBlockState(new BlockPos(x + 11, y + 9, z + 6), leaves);
        this.setBlockState(new BlockPos(x + 4, y + 9, z + 7), leaves);
        this.setBlockState(new BlockPos(x + 5, y + 9, z + 7), leaves);
        this.setBlockState(new BlockPos(x + 6, y + 9, z + 7), log);
        this.setBlockState(new BlockPos(x + 7, y + 9, z + 7), log);
        this.setBlockState(new BlockPos(x + 8, y + 9, z + 7), leaves);
        this.setBlockState(new BlockPos(x + 10, y + 9, z + 7), leaves);
        this.setBlockState(new BlockPos(x + 11, y + 9, z + 7), log);
        this.setBlockState(new BlockPos(x + 12, y + 9, z + 7), leaves);
        this.setBlockState(new BlockPos(x + 3, y + 9, z + 8), leaves);
        this.setBlockState(new BlockPos(x + 4, y + 9, z + 8), leaves);
        this.setBlockState(new BlockPos(x + 5, y + 9, z + 8), leaves);
        this.setBlockState(new BlockPos(x + 6, y + 9, z + 8), leaves);
        this.setBlockState(new BlockPos(x + 7, y + 9, z + 8), leaves);
        this.setBlockState(new BlockPos(x + 10, y + 9, z + 8), leaves);
        this.setBlockState(new BlockPos(x + 11, y + 9, z + 8), leaves);
        this.setBlockState(new BlockPos(x + 4, y + 9, z + 9), leaves);
        this.setBlockState(new BlockPos(x + 5, y + 9, z + 9), leaves);
        this.setBlockState(new BlockPos(x + 6, y + 9, z + 9), leaves);
        this.setBlockState(new BlockPos(x + 7, y + 9, z + 9), leaves);
        this.setBlockState(new BlockPos(x + 8, y + 9, z + 9), leaves);
        this.setBlockState(new BlockPos(x + 9, y + 9, z + 9), leaves);
        this.setBlockState(new BlockPos(x + 2, y + 9, z + 10), leaves);
        this.setBlockState(new BlockPos(x + 7, y + 9, z + 10), leaves);
        this.setBlockState(new BlockPos(x + 8, y + 9, z + 10), leaves);
        this.setBlockState(new BlockPos(x + 9, y + 9, z + 10), leaves);
        this.setBlockState(new BlockPos(x + 2, y + 9, z + 11), leaves);
        this.setBlockState(new BlockPos(x + 3, y + 9, z + 12), leaves);
        this.setBlockState(new BlockPos(x + 5, y + 9, z + 12), leaves);
        this.setBlockState(new BlockPos(x + 6, y + 9, z + 12), leaves);
        this.setBlockState(new BlockPos(x + 7, y + 9, z + 12), leaves);
        this.setBlockState(new BlockPos(x + 8, y + 9, z + 12), leaves);
        this.setBlockState(new BlockPos(x + 7, y + 9, z + 13), leaves);
        this.setBlockState(new BlockPos(x + 9, y + 10, z + 2), leaves);
        this.setBlockState(new BlockPos(x + 8, y + 10, z + 3), leaves);
        this.setBlockState(new BlockPos(x + 10, y + 10, z + 3), leaves);
        this.setBlockState(new BlockPos(x + 4, y + 10, z + 4), leaves);
        this.setBlockState(new BlockPos(x + 7, y + 10, z + 4), leaves);
        this.setBlockState(new BlockPos(x + 9, y + 10, z + 4), leaves);
        this.setBlockState(new BlockPos(x + 10, y + 10, z + 4), leaves);
        this.setBlockState(new BlockPos(x + 3, y + 10, z + 5), leaves);
        this.setBlockState(new BlockPos(x + 7, y + 10, z + 5), log);
        this.setBlockState(new BlockPos(x + 9, y + 10, z + 5), leaves);
        this.setBlockState(new BlockPos(x + 10, y + 10, z + 5), log);
        this.setBlockState(new BlockPos(x + 13, y + 10, z + 5), leaves);
        this.setBlockState(new BlockPos(x + 3, y + 10, z + 6), leaves);
        this.setBlockState(new BlockPos(x + 7, y + 10, z + 6), leaves);
        this.setBlockState(new BlockPos(x + 8, y + 10, z + 6), leaves);
        this.setBlockState(new BlockPos(x + 9, y + 10, z + 6), leaves);
        this.setBlockState(new BlockPos(x + 11, y + 10, z + 6), leaves);
        this.setBlockState(new BlockPos(x + 12, y + 10, z + 6), leaves);
        this.setBlockState(new BlockPos(x + 13, y + 10, z + 6), leaves);
        this.setBlockState(new BlockPos(x + 2, y + 10, z + 7), leaves);
        this.setBlockState(new BlockPos(x + 3, y + 10, z + 7), leaves);
        this.setBlockState(new BlockPos(x + 4, y + 10, z + 7), leaves);
        this.setBlockState(new BlockPos(x + 5, y + 10, z + 7), log);
        this.setBlockState(new BlockPos(x + 6, y + 10, z + 7), leaves);
        this.setBlockState(new BlockPos(x + 7, y + 10, z + 7), log);
        this.setBlockState(new BlockPos(x + 8, y + 10, z + 7), leaves);
        this.setBlockState(new BlockPos(x + 9, y + 10, z + 7), leaves);
        this.setBlockState(new BlockPos(x + 10, y + 10, z + 7), leaves);
        this.setBlockState(new BlockPos(x + 12, y + 10, z + 7), leaves);
        this.setBlockState(new BlockPos(x + 4, y + 10, z + 8), leaves);
        this.setBlockState(new BlockPos(x + 5, y + 10, z + 8), leaves);
        this.setBlockState(new BlockPos(x + 6, y + 10, z + 8), leaves);
        this.setBlockState(new BlockPos(x + 7, y + 10, z + 8), leaves);
        this.setBlockState(new BlockPos(x + 9, y + 10, z + 8), leaves);
        this.setBlockState(new BlockPos(x + 10, y + 10, z + 8), leaves);
        this.setBlockState(new BlockPos(x + 4, y + 10, z + 9), leaves);
        this.setBlockState(new BlockPos(x + 10, y + 10, z + 9), leaves);
        this.setBlockState(new BlockPos(x + 11, y + 10, z + 9), leaves);
        this.setBlockState(new BlockPos(x + 4, y + 10, z + 10), leaves);
        this.setBlockState(new BlockPos(x + 5, y + 10, z + 10), leaves);
        this.setBlockState(new BlockPos(x + 7, y + 10, z + 10), leaves);
        this.setBlockState(new BlockPos(x + 8, y + 10, z + 10), leaves);
        this.setBlockState(new BlockPos(x + 10, y + 10, z + 10), leaves);
        this.setBlockState(new BlockPos(x + 7, y + 10, z + 11), leaves);
        this.setBlockState(new BlockPos(x + 8, y + 10, z + 11), leaves);
        this.setBlockState(new BlockPos(x + 5, y + 10, z + 12), leaves);
        this.setBlockState(new BlockPos(x + 7, y + 10, z + 12), leaves);
        this.setBlockState(new BlockPos(x + 8, y + 10, z + 12), leaves);
        this.setBlockState(new BlockPos(x + 10, y + 11, z + 2), leaves);
        this.setBlockState(new BlockPos(x + 9, y + 11, z + 3), leaves);
        this.setBlockState(new BlockPos(x + 12, y + 11, z + 3), leaves);
        this.setBlockState(new BlockPos(x + 3, y + 11, z + 4), leaves);
        this.setBlockState(new BlockPos(x + 4, y + 11, z + 4), leaves);
        this.setBlockState(new BlockPos(x + 5, y + 11, z + 4), leaves);
        this.setBlockState(new BlockPos(x + 7, y + 11, z + 4), leaves);
        this.setBlockState(new BlockPos(x + 9, y + 11, z + 4), leaves);
        this.setBlockState(new BlockPos(x + 10, y + 11, z + 4), leaves);
        this.setBlockState(new BlockPos(x + 12, y + 11, z + 4), leaves);
        this.setBlockState(new BlockPos(x + 4, y + 11, z + 5), leaves);
        this.setBlockState(new BlockPos(x + 5, y + 11, z + 5), leaves);
        this.setBlockState(new BlockPos(x + 8, y + 11, z + 5), leaves);
        this.setBlockState(new BlockPos(x + 10, y + 11, z + 5), leaves);
        this.setBlockState(new BlockPos(x + 12, y + 11, z + 5), leaves);
        this.setBlockState(new BlockPos(x + 1, y + 11, z + 6), leaves);
        this.setBlockState(new BlockPos(x + 3, y + 11, z + 6), leaves);
        this.setBlockState(new BlockPos(x + 4, y + 11, z + 6), leaves);
        this.setBlockState(new BlockPos(x + 5, y + 11, z + 6), leaves);
        this.setBlockState(new BlockPos(x + 10, y + 11, z + 6), leaves);
        this.setBlockState(new BlockPos(x + 1, y + 11, z + 7), leaves);
        this.setBlockState(new BlockPos(x + 3, y + 11, z + 7), leaves);
        this.setBlockState(new BlockPos(x + 4, y + 11, z + 7), log);
        this.setBlockState(new BlockPos(x + 5, y + 11, z + 7), leaves);
        this.setBlockState(new BlockPos(x + 7, y + 11, z + 7), log);
        this.setBlockState(new BlockPos(x + 8, y + 11, z + 7), log);
        this.setBlockState(new BlockPos(x + 9, y + 11, z + 7), log);
        this.setBlockState(new BlockPos(x + 12, y + 11, z + 7), leaves);
        this.setBlockState(new BlockPos(x + 2, y + 11, z + 8), leaves);
        this.setBlockState(new BlockPos(x + 3, y + 11, z + 8), leaves);
        this.setBlockState(new BlockPos(x + 7, y + 11, z + 8), leaves);
        this.setBlockState(new BlockPos(x + 8, y + 11, z + 8), leaves);
        this.setBlockState(new BlockPos(x + 10, y + 11, z + 8), leaves);
        this.setBlockState(new BlockPos(x + 11, y + 11, z + 8), leaves);
        this.setBlockState(new BlockPos(x + 2, y + 11, z + 9), leaves);
        this.setBlockState(new BlockPos(x + 3, y + 11, z + 9), leaves);
        this.setBlockState(new BlockPos(x + 5, y + 11, z + 9), leaves);
        this.setBlockState(new BlockPos(x + 6, y + 11, z + 9), leaves);
        this.setBlockState(new BlockPos(x + 7, y + 11, z + 9), leaves);
        this.setBlockState(new BlockPos(x + 8, y + 11, z + 9), leaves);
        this.setBlockState(new BlockPos(x + 9, y + 11, z + 9), leaves);
        this.setBlockState(new BlockPos(x + 10, y + 11, z + 9), leaves);
        this.setBlockState(new BlockPos(x + 12, y + 11, z + 9), leaves);
        this.setBlockState(new BlockPos(x + 5, y + 11, z + 10), leaves);
        this.setBlockState(new BlockPos(x + 6, y + 11, z + 10), leaves);
        this.setBlockState(new BlockPos(x + 8, y + 11, z + 10), leaves);
        this.setBlockState(new BlockPos(x + 9, y + 11, z + 10), leaves);
        this.setBlockState(new BlockPos(x + 10, y + 11, z + 10), leaves);
        this.setBlockState(new BlockPos(x + 5, y + 11, z + 11), leaves);
        this.setBlockState(new BlockPos(x + 8, y + 11, z + 11), leaves);
        this.setBlockState(new BlockPos(x + 2, y + 12, z + 2), leaves);
        this.setBlockState(new BlockPos(x + 10, y + 12, z + 3), leaves);
        this.setBlockState(new BlockPos(x + 4, y + 12, z + 4), leaves);
        this.setBlockState(new BlockPos(x + 5, y + 12, z + 4), leaves);
        this.setBlockState(new BlockPos(x + 6, y + 12, z + 4), leaves);
        this.setBlockState(new BlockPos(x + 10, y + 12, z + 4), leaves);
        this.setBlockState(new BlockPos(x + 11, y + 12, z + 4), leaves);
        this.setBlockState(new BlockPos(x + 4, y + 12, z + 5), leaves);
        this.setBlockState(new BlockPos(x + 6, y + 12, z + 5), leaves);
        this.setBlockState(new BlockPos(x + 10, y + 12, z + 5), leaves);
        this.setBlockState(new BlockPos(x + 11, y + 12, z + 5), leaves);
        this.setBlockState(new BlockPos(x + 12, y + 12, z + 5), leaves);
        this.setBlockState(new BlockPos(x + 4, y + 12, z + 6), leaves);
        this.setBlockState(new BlockPos(x + 8, y + 12, z + 6), leaves);
        this.setBlockState(new BlockPos(x + 12, y + 12, z + 6), leaves);
        this.setBlockState(new BlockPos(x + 3, y + 12, z + 7), leaves);
        this.setBlockState(new BlockPos(x + 4, y + 12, z + 7), leaves);
        this.setBlockState(new BlockPos(x + 5, y + 12, z + 7), leaves);
        this.setBlockState(new BlockPos(x + 6, y + 12, z + 7), leaves);
        this.setBlockState(new BlockPos(x + 7, y + 12, z + 7), log);
        this.setBlockState(new BlockPos(x + 8, y + 12, z + 7), leaves);
        this.setBlockState(new BlockPos(x + 9, y + 12, z + 7), leaves);
        this.setBlockState(new BlockPos(x + 10, y + 12, z + 7), leaves);
        this.setBlockState(new BlockPos(x + 11, y + 12, z + 7), leaves);
        this.setBlockState(new BlockPos(x + 1, y + 12, z + 8), leaves);
        this.setBlockState(new BlockPos(x + 7, y + 12, z + 8), log);
        this.setBlockState(new BlockPos(x + 9, y + 12, z + 8), leaves);
        this.setBlockState(new BlockPos(x + 10, y + 12, z + 8), log);
        this.setBlockState(new BlockPos(x + 11, y + 12, z + 8), leaves);
        this.setBlockState(new BlockPos(x + 13, y + 12, z + 8), leaves);
        this.setBlockState(new BlockPos(x + 2, y + 12, z + 9), leaves);
        this.setBlockState(new BlockPos(x + 6, y + 12, z + 9), leaves);
        this.setBlockState(new BlockPos(x + 7, y + 12, z + 9), leaves);
        this.setBlockState(new BlockPos(x + 10, y + 12, z + 9), leaves);
        this.setBlockState(new BlockPos(x + 11, y + 12, z + 9), leaves);
        this.setBlockState(new BlockPos(x + 12, y + 12, z + 9), leaves);
        this.setBlockState(new BlockPos(x + 3, y + 12, z + 10), leaves);
        this.setBlockState(new BlockPos(x + 4, y + 12, z + 10), leaves);
        this.setBlockState(new BlockPos(x + 5, y + 12, z + 10), leaves);
        this.setBlockState(new BlockPos(x + 6, y + 12, z + 10), leaves);
        this.setBlockState(new BlockPos(x + 7, y + 12, z + 10), leaves);
        this.setBlockState(new BlockPos(x + 12, y + 12, z + 10), leaves);
        this.setBlockState(new BlockPos(x + 4, y + 12, z + 11), leaves);
        this.setBlockState(new BlockPos(x + 6, y + 12, z + 11), leaves);
        this.setBlockState(new BlockPos(x + 7, y + 12, z + 11), leaves);
        this.setBlockState(new BlockPos(x + 9, y + 12, z + 11), leaves);
        this.setBlockState(new BlockPos(x + 11, y + 12, z + 11), leaves);
        this.setBlockState(new BlockPos(x + 7, y + 12, z + 12), leaves);
        this.setBlockState(new BlockPos(x + 3, y + 13, z + 1), leaves);
        this.setBlockState(new BlockPos(x + 5, y + 13, z + 2), leaves);
        this.setBlockState(new BlockPos(x + 2, y + 13, z + 3), leaves);
        this.setBlockState(new BlockPos(x + 5, y + 13, z + 3), leaves);
        this.setBlockState(new BlockPos(x + 6, y + 13, z + 3), leaves);
        this.setBlockState(new BlockPos(x + 7, y + 13, z + 3), leaves);
        this.setBlockState(new BlockPos(x + 3, y + 13, z + 4), leaves);
        this.setBlockState(new BlockPos(x + 4, y + 13, z + 4), leaves);
        this.setBlockState(new BlockPos(x + 5, y + 13, z + 4), log);
        this.setBlockState(new BlockPos(x + 7, y + 13, z + 4), leaves);
        this.setBlockState(new BlockPos(x + 8, y + 13, z + 4), leaves);
        this.setBlockState(new BlockPos(x + 9, y + 13, z + 4), leaves);
        this.setBlockState(new BlockPos(x + 1, y + 13, z + 5), leaves);
        this.setBlockState(new BlockPos(x + 4, y + 13, z + 5), leaves);
        this.setBlockState(new BlockPos(x + 5, y + 13, z + 5), log);
        this.setBlockState(new BlockPos(x + 6, y + 13, z + 5), leaves);
        this.setBlockState(new BlockPos(x + 7, y + 13, z + 5), leaves);
        this.setBlockState(new BlockPos(x + 10, y + 13, z + 5), leaves);
        this.setBlockState(new BlockPos(x + 2, y + 13, z + 6), leaves);
        this.setBlockState(new BlockPos(x + 4, y + 13, z + 6), leaves);
        this.setBlockState(new BlockPos(x + 6, y + 13, z + 6), log);
        this.setBlockState(new BlockPos(x + 9, y + 13, z + 6), leaves);
        this.setBlockState(new BlockPos(x + 10, y + 13, z + 6), leaves);
        this.setBlockState(new BlockPos(x + 11, y + 13, z + 6), leaves);
        this.setBlockState(new BlockPos(x + 12, y + 13, z + 6), leaves);
        this.setBlockState(new BlockPos(x + 2, y + 13, z + 7), leaves);
        this.setBlockState(new BlockPos(x + 3, y + 13, z + 7), leaves);
        this.setBlockState(new BlockPos(x + 4, y + 13, z + 7), leaves);
        this.setBlockState(new BlockPos(x + 7, y + 13, z + 7), log);
        this.setBlockState(new BlockPos(x + 5, y + 13, z + 8), leaves);
        this.setBlockState(new BlockPos(x + 6, y + 13, z + 8), leaves);
        this.setBlockState(new BlockPos(x + 7, y + 13, z + 8), leaves);
        this.setBlockState(new BlockPos(x + 8, y + 13, z + 8), leaves);
        this.setBlockState(new BlockPos(x + 9, y + 13, z + 8), leaves);
        this.setBlockState(new BlockPos(x + 10, y + 13, z + 8), leaves);
        this.setBlockState(new BlockPos(x + 12, y + 13, z + 8), leaves);
        this.setBlockState(new BlockPos(x + 13, y + 13, z + 8), leaves);
        this.setBlockState(new BlockPos(x + 6, y + 13, z + 9), leaves);
        this.setBlockState(new BlockPos(x + 7, y + 13, z + 9), log);
        this.setBlockState(new BlockPos(x + 9, y + 13, z + 9), leaves);
        this.setBlockState(new BlockPos(x + 10, y + 13, z + 9), leaves);
        this.setBlockState(new BlockPos(x + 12, y + 13, z + 9), leaves);
        this.setBlockState(new BlockPos(x + 3, y + 13, z + 10), leaves);
        this.setBlockState(new BlockPos(x + 4, y + 13, z + 10), leaves);
        this.setBlockState(new BlockPos(x + 5, y + 13, z + 10), leaves);
        this.setBlockState(new BlockPos(x + 6, y + 13, z + 10), leaves);
        this.setBlockState(new BlockPos(x + 7, y + 13, z + 10), leaves);
        this.setBlockState(new BlockPos(x + 12, y + 13, z + 10), leaves);
        this.setBlockState(new BlockPos(x + 9, y + 13, z + 11), leaves);
        this.setBlockState(new BlockPos(x + 10, y + 13, z + 11), leaves);
        this.setBlockState(new BlockPos(x + 6, y + 13, z + 12), leaves);
        this.setBlockState(new BlockPos(x + 8, y + 13, z + 12), leaves);
        this.setBlockState(new BlockPos(x + 6, y + 13, z + 13), leaves);
        this.setBlockState(new BlockPos(x + 7, y + 13, z + 13), leaves);
        this.setBlockState(new BlockPos(x + 4, y + 14, z + 1), leaves);
        this.setBlockState(new BlockPos(x + 5, y + 14, z + 1), leaves);
        this.setBlockState(new BlockPos(x + 3, y + 14, z + 2), leaves);
        this.setBlockState(new BlockPos(x + 4, y + 14, z + 2), leaves);
        this.setBlockState(new BlockPos(x + 5, y + 14, z + 2), leaves);
        this.setBlockState(new BlockPos(x + 6, y + 14, z + 2), leaves);
        this.setBlockState(new BlockPos(x + 2, y + 14, z + 3), leaves);
        this.setBlockState(new BlockPos(x + 3, y + 14, z + 3), leaves);
        this.setBlockState(new BlockPos(x + 4, y + 14, z + 3), leaves);
        this.setBlockState(new BlockPos(x + 5, y + 14, z + 3), leaves);
        this.setBlockState(new BlockPos(x + 6, y + 14, z + 3), leaves);
        this.setBlockState(new BlockPos(x + 7, y + 14, z + 3), leaves);
        this.setBlockState(new BlockPos(x + 8, y + 14, z + 3), leaves);
        this.setBlockState(new BlockPos(x + 9, y + 14, z + 3), leaves);
        this.setBlockState(new BlockPos(x + 1, y + 14, z + 4), leaves);
        this.setBlockState(new BlockPos(x + 2, y + 14, z + 4), leaves);
        this.setBlockState(new BlockPos(x + 3, y + 14, z + 4), leaves);
        this.setBlockState(new BlockPos(x + 4, y + 14, z + 4), log);
        this.setBlockState(new BlockPos(x + 5, y + 14, z + 4), leaves);
        this.setBlockState(new BlockPos(x + 6, y + 14, z + 4), leaves);
        this.setBlockState(new BlockPos(x + 7, y + 14, z + 4), leaves);
        this.setBlockState(new BlockPos(x + 9, y + 14, z + 4), leaves);
        this.setBlockState(new BlockPos(x + 2, y + 14, z + 5), leaves);
        this.setBlockState(new BlockPos(x + 4, y + 14, z + 5), leaves);
        this.setBlockState(new BlockPos(x + 5, y + 14, z + 5), leaves);
        this.setBlockState(new BlockPos(x + 6, y + 14, z + 5), leaves);
        this.setBlockState(new BlockPos(x + 7, y + 14, z + 5), leaves);
        this.setBlockState(new BlockPos(x + 3, y + 14, z + 6), leaves);
        this.setBlockState(new BlockPos(x + 4, y + 14, z + 6), leaves);
        this.setBlockState(new BlockPos(x + 5, y + 14, z + 6), leaves);
        this.setBlockState(new BlockPos(x + 6, y + 14, z + 6), leaves);
        this.setBlockState(new BlockPos(x + 8, y + 14, z + 6), leaves);
        this.setBlockState(new BlockPos(x + 9, y + 14, z + 6), leaves);
        this.setBlockState(new BlockPos(x + 10, y + 14, z + 6), leaves);
        this.setBlockState(new BlockPos(x + 12, y + 14, z + 6), leaves);
        this.setBlockState(new BlockPos(x + 3, y + 14, z + 7), leaves);
        this.setBlockState(new BlockPos(x + 4, y + 14, z + 7), leaves);
        this.setBlockState(new BlockPos(x + 5, y + 14, z + 7), leaves);
        this.setBlockState(new BlockPos(x + 6, y + 14, z + 7), leaves);
        this.setBlockState(new BlockPos(x + 7, y + 14, z + 7), log);
        this.setBlockState(new BlockPos(x + 3, y + 14, z + 8), leaves);
        this.setBlockState(new BlockPos(x + 5, y + 14, z + 8), leaves);
        this.setBlockState(new BlockPos(x + 6, y + 14, z + 8), leaves);
        this.setBlockState(new BlockPos(x + 7, y + 14, z + 8), leaves);
        this.setBlockState(new BlockPos(x + 8, y + 14, z + 8), leaves);
        this.setBlockState(new BlockPos(x + 10, y + 14, z + 8), leaves);
        this.setBlockState(new BlockPos(x + 11, y + 14, z + 8), leaves);
        this.setBlockState(new BlockPos(x + 4, y + 14, z + 9), leaves);
        this.setBlockState(new BlockPos(x + 5, y + 14, z + 9), leaves);
        this.setBlockState(new BlockPos(x + 6, y + 14, z + 9), leaves);
        this.setBlockState(new BlockPos(x + 7, y + 14, z + 9), leaves);
        this.setBlockState(new BlockPos(x + 9, y + 14, z + 9), leaves);
        this.setBlockState(new BlockPos(x + 4, y + 14, z + 10), leaves);
        this.setBlockState(new BlockPos(x + 5, y + 14, z + 10), leaves);
        this.setBlockState(new BlockPos(x + 6, y + 14, z + 10), log);
        this.setBlockState(new BlockPos(x + 7, y + 14, z + 10), leaves);
        this.setBlockState(new BlockPos(x + 8, y + 14, z + 10), leaves);
        this.setBlockState(new BlockPos(x + 9, y + 14, z + 10), leaves);
        this.setBlockState(new BlockPos(x + 12, y + 14, z + 10), leaves);
        this.setBlockState(new BlockPos(x + 4, y + 14, z + 11), leaves);
        this.setBlockState(new BlockPos(x + 5, y + 14, z + 11), leaves);
        this.setBlockState(new BlockPos(x + 7, y + 14, z + 11), leaves);
        this.setBlockState(new BlockPos(x + 8, y + 14, z + 11), leaves);
        this.setBlockState(new BlockPos(x + 6, y + 14, z + 12), leaves);
        this.setBlockState(new BlockPos(x + 7, y + 14, z + 12), leaves);
        this.setBlockState(new BlockPos(x + 8, y + 14, z + 12), leaves);
        this.setBlockState(new BlockPos(x + 5, y + 14, z + 13), leaves);
        this.setBlockState(new BlockPos(x + 6, y + 14, z + 13), leaves);
        this.setBlockState(new BlockPos(x + 6, y + 15, z + 1), leaves);
        this.setBlockState(new BlockPos(x + 6, y + 15, z + 2), leaves);
        this.setBlockState(new BlockPos(x + 7, y + 15, z + 2), leaves);
        this.setBlockState(new BlockPos(x + 8, y + 15, z + 2), leaves);
        this.setBlockState(new BlockPos(x + 2, y + 15, z + 3), leaves);
        this.setBlockState(new BlockPos(x + 10, y + 15, z + 3), leaves);
        this.setBlockState(new BlockPos(x + 4, y + 15, z + 4), leaves);
        this.setBlockState(new BlockPos(x + 5, y + 15, z + 4), leaves);
        this.setBlockState(new BlockPos(x + 6, y + 15, z + 4), leaves);
        this.setBlockState(new BlockPos(x + 7, y + 15, z + 4), leaves);
        this.setBlockState(new BlockPos(x + 1, y + 15, z + 5), leaves);
        this.setBlockState(new BlockPos(x + 3, y + 15, z + 5), leaves);
        this.setBlockState(new BlockPos(x + 4, y + 15, z + 5), leaves);
        this.setBlockState(new BlockPos(x + 5, y + 15, z + 5), leaves);
        this.setBlockState(new BlockPos(x + 7, y + 15, z + 5), log);
        this.setBlockState(new BlockPos(x + 6, y + 15, z + 6), leaves);
        this.setBlockState(new BlockPos(x + 7, y + 15, z + 6), log);
        this.setBlockState(new BlockPos(x + 8, y + 15, z + 6), leaves);
        this.setBlockState(new BlockPos(x + 10, y + 15, z + 6), leaves);
        this.setBlockState(new BlockPos(x + 3, y + 15, z + 7), leaves);
        this.setBlockState(new BlockPos(x + 4, y + 15, z + 7), leaves);
        this.setBlockState(new BlockPos(x + 5, y + 15, z + 7), leaves);
        this.setBlockState(new BlockPos(x + 7, y + 15, z + 7), log);
        this.setBlockState(new BlockPos(x + 10, y + 15, z + 7), leaves);
        this.setBlockState(new BlockPos(x + 11, y + 15, z + 7), leaves);
        this.setBlockState(new BlockPos(x + 2, y + 15, z + 8), leaves);
        this.setBlockState(new BlockPos(x + 5, y + 15, z + 8), leaves);
        this.setBlockState(new BlockPos(x + 6, y + 15, z + 8), leaves);
        this.setBlockState(new BlockPos(x + 7, y + 15, z + 8), leaves);
        this.setBlockState(new BlockPos(x + 9, y + 15, z + 8), leaves);
        this.setBlockState(new BlockPos(x + 10, y + 15, z + 8), leaves);
        this.setBlockState(new BlockPos(x + 11, y + 15, z + 8), leaves);
        this.setBlockState(new BlockPos(x + 4, y + 15, z + 9), leaves);
        this.setBlockState(new BlockPos(x + 6, y + 15, z + 9), leaves);
        this.setBlockState(new BlockPos(x + 2, y + 15, z + 10), leaves);
        this.setBlockState(new BlockPos(x + 3, y + 15, z + 10), leaves);
        this.setBlockState(new BlockPos(x + 4, y + 15, z + 10), leaves);
        this.setBlockState(new BlockPos(x + 5, y + 15, z + 10), leaves);
        this.setBlockState(new BlockPos(x + 6, y + 15, z + 10), leaves);
        this.setBlockState(new BlockPos(x + 9, y + 15, z + 10), leaves);
        this.setBlockState(new BlockPos(x + 4, y + 15, z + 11), leaves);
        this.setBlockState(new BlockPos(x + 2, y + 15, z + 12), leaves);
        this.setBlockState(new BlockPos(x + 4, y + 15, z + 12), leaves);
        this.setBlockState(new BlockPos(x + 5, y + 15, z + 12), leaves);
        this.setBlockState(new BlockPos(x + 6, y + 15, z + 12), leaves);
        this.setBlockState(new BlockPos(x + 7, y + 15, z + 12), leaves);
        this.setBlockState(new BlockPos(x + 6, y + 16, z + 1), leaves);
        this.setBlockState(new BlockPos(x + 2, y + 16, z + 2), leaves);
        this.setBlockState(new BlockPos(x + 3, y + 16, z + 2), leaves);
        this.setBlockState(new BlockPos(x + 6, y + 16, z + 2), leaves);
        this.setBlockState(new BlockPos(x + 7, y + 16, z + 2), leaves);
        this.setBlockState(new BlockPos(x + 2, y + 16, z + 3), leaves);
        this.setBlockState(new BlockPos(x + 4, y + 16, z + 3), leaves);
        this.setBlockState(new BlockPos(x + 5, y + 16, z + 3), leaves);
        this.setBlockState(new BlockPos(x + 6, y + 16, z + 3), leaves);
        this.setBlockState(new BlockPos(x + 7, y + 16, z + 3), leaves);
        this.setBlockState(new BlockPos(x + 2, y + 16, z + 4), leaves);
        this.setBlockState(new BlockPos(x + 3, y + 16, z + 4), leaves);
        this.setBlockState(new BlockPos(x + 4, y + 16, z + 4), log);
        this.setBlockState(new BlockPos(x + 5, y + 16, z + 4), leaves);
        this.setBlockState(new BlockPos(x + 6, y + 16, z + 4), leaves);
        this.setBlockState(new BlockPos(x + 7, y + 16, z + 4), log);
        this.setBlockState(new BlockPos(x + 8, y + 16, z + 4), leaves);
        this.setBlockState(new BlockPos(x + 9, y + 16, z + 4), leaves);
        this.setBlockState(new BlockPos(x + 2, y + 16, z + 5), leaves);
        this.setBlockState(new BlockPos(x + 4, y + 16, z + 5), leaves);
        this.setBlockState(new BlockPos(x + 5, y + 16, z + 5), leaves);
        this.setBlockState(new BlockPos(x + 7, y + 16, z + 5), leaves);
        this.setBlockState(new BlockPos(x + 9, y + 16, z + 5), leaves);
        this.setBlockState(new BlockPos(x + 10, y + 16, z + 5), leaves);
        this.setBlockState(new BlockPos(x + 11, y + 16, z + 5), leaves);
        this.setBlockState(new BlockPos(x + 4, y + 16, z + 6), leaves);
        this.setBlockState(new BlockPos(x + 5, y + 16, z + 6), leaves);
        this.setBlockState(new BlockPos(x + 7, y + 16, z + 6), leaves);
        this.setBlockState(new BlockPos(x + 8, y + 16, z + 6), leaves);
        this.setBlockState(new BlockPos(x + 10, y + 16, z + 6), leaves);
        this.setBlockState(new BlockPos(x + 12, y + 16, z + 6), leaves);
        this.setBlockState(new BlockPos(x + 6, y + 16, z + 7), leaves);
        this.setBlockState(new BlockPos(x + 7, y + 16, z + 7), log);
        this.setBlockState(new BlockPos(x + 8, y + 16, z + 7), leaves);
        this.setBlockState(new BlockPos(x + 4, y + 16, z + 8), leaves);
        this.setBlockState(new BlockPos(x + 6, y + 16, z + 8), log);
        this.setBlockState(new BlockPos(x + 8, y + 16, z + 8), leaves);
        this.setBlockState(new BlockPos(x + 12, y + 16, z + 8), leaves);
        this.setBlockState(new BlockPos(x + 1, y + 16, z + 9), leaves);
        this.setBlockState(new BlockPos(x + 4, y + 16, z + 9), log);
        this.setBlockState(new BlockPos(x + 5, y + 16, z + 9), log);
        this.setBlockState(new BlockPos(x + 6, y + 16, z + 9), leaves);
        this.setBlockState(new BlockPos(x + 7, y + 16, z + 9), leaves);
        this.setBlockState(new BlockPos(x + 8, y + 16, z + 9), leaves);
        this.setBlockState(new BlockPos(x + 11, y + 16, z + 9), leaves);
        this.setBlockState(new BlockPos(x + 1, y + 16, z + 10), leaves);
        this.setBlockState(new BlockPos(x + 3, y + 16, z + 10), leaves);
        this.setBlockState(new BlockPos(x + 4, y + 16, z + 10), leaves);
        this.setBlockState(new BlockPos(x + 5, y + 16, z + 10), leaves);
        this.setBlockState(new BlockPos(x + 6, y + 16, z + 10), leaves);
        this.setBlockState(new BlockPos(x + 7, y + 16, z + 10), leaves);
        this.setBlockState(new BlockPos(x + 1, y + 16, z + 11), leaves);
        this.setBlockState(new BlockPos(x + 2, y + 16, z + 11), leaves);
        this.setBlockState(new BlockPos(x + 5, y + 16, z + 11), leaves);
        this.setBlockState(new BlockPos(x + 6, y + 16, z + 11), leaves);
        this.setBlockState(new BlockPos(x + 4, y + 16, z + 12), leaves);
        this.setBlockState(new BlockPos(x + 6, y + 16, z + 12), leaves);
        this.setBlockState(new BlockPos(x + 8, y + 16, z + 12), leaves);
        this.setBlockState(new BlockPos(x + 4, y + 16, z + 13), leaves);
        this.setBlockState(new BlockPos(x + 6, y + 17, z + 1), leaves);
        this.setBlockState(new BlockPos(x + 6, y + 17, z + 2), leaves);
        this.setBlockState(new BlockPos(x + 7, y + 17, z + 2), leaves);
        this.setBlockState(new BlockPos(x + 3, y + 17, z + 3), leaves);
        this.setBlockState(new BlockPos(x + 5, y + 17, z + 3), leaves);
        this.setBlockState(new BlockPos(x + 6, y + 17, z + 3), log);
        this.setBlockState(new BlockPos(x + 7, y + 17, z + 3), leaves);
        this.setBlockState(new BlockPos(x + 10, y + 17, z + 3), leaves);
        this.setBlockState(new BlockPos(x + 3, y + 17, z + 4), leaves);
        this.setBlockState(new BlockPos(x + 4, y + 17, z + 4), leaves);
        this.setBlockState(new BlockPos(x + 5, y + 17, z + 4), leaves);
        this.setBlockState(new BlockPos(x + 10, y + 17, z + 4), leaves);
        this.setBlockState(new BlockPos(x + 3, y + 17, z + 5), leaves);
        this.setBlockState(new BlockPos(x + 4, y + 17, z + 5), leaves);
        this.setBlockState(new BlockPos(x + 10, y + 17, z + 5), leaves);
        this.setBlockState(new BlockPos(x + 7, y + 17, z + 6), leaves);
        this.setBlockState(new BlockPos(x + 9, y + 17, z + 6), leaves);
        this.setBlockState(new BlockPos(x + 11, y + 17, z + 6), leaves);
        this.setBlockState(new BlockPos(x + 3, y + 17, z + 7), leaves);
        this.setBlockState(new BlockPos(x + 7, y + 17, z + 7), log);
        this.setBlockState(new BlockPos(x + 8, y + 17, z + 7), log);
        this.setBlockState(new BlockPos(x + 9, y + 17, z + 7), log);
        this.setBlockState(new BlockPos(x + 10, y + 17, z + 7), leaves);
        this.setBlockState(new BlockPos(x + 12, y + 17, z + 7), leaves);
        this.setBlockState(new BlockPos(x + 5, y + 17, z + 8), leaves);
        this.setBlockState(new BlockPos(x + 10, y + 17, z + 8), leaves);
        this.setBlockState(new BlockPos(x + 1, y + 17, z + 9), leaves);
        this.setBlockState(new BlockPos(x + 2, y + 17, z + 9), leaves);
        this.setBlockState(new BlockPos(x + 3, y + 17, z + 9), leaves);
        this.setBlockState(new BlockPos(x + 4, y + 17, z + 9), leaves);
        this.setBlockState(new BlockPos(x + 5, y + 17, z + 9), leaves);
        this.setBlockState(new BlockPos(x + 6, y + 17, z + 9), leaves);
        this.setBlockState(new BlockPos(x + 7, y + 17, z + 9), leaves);
        this.setBlockState(new BlockPos(x + 8, y + 17, z + 9), leaves);
        this.setBlockState(new BlockPos(x + 1, y + 17, z + 10), leaves);
        this.setBlockState(new BlockPos(x + 2, y + 17, z + 10), leaves);
        this.setBlockState(new BlockPos(x + 3, y + 17, z + 10), log);
        this.setBlockState(new BlockPos(x + 4, y + 17, z + 10), log);
        this.setBlockState(new BlockPos(x + 5, y + 17, z + 10), leaves);
        this.setBlockState(new BlockPos(x + 6, y + 17, z + 10), leaves);
        this.setBlockState(new BlockPos(x + 7, y + 17, z + 10), leaves);
        this.setBlockState(new BlockPos(x + 2, y + 17, z + 11), leaves);
        this.setBlockState(new BlockPos(x + 3, y + 17, z + 11), leaves);
        this.setBlockState(new BlockPos(x + 4, y + 17, z + 11), leaves);
        this.setBlockState(new BlockPos(x + 5, y + 17, z + 11), leaves);
        this.setBlockState(new BlockPos(x + 7, y + 17, z + 11), leaves);
        this.setBlockState(new BlockPos(x + 2, y + 17, z + 12), leaves);
        this.setBlockState(new BlockPos(x + 4, y + 17, z + 12), leaves);
        this.setBlockState(new BlockPos(x + 6, y + 17, z + 12), leaves);
        this.setBlockState(new BlockPos(x + 4, y + 17, z + 13), leaves);
        this.setBlockState(new BlockPos(x + 6, y + 18, z + 2), leaves);
        this.setBlockState(new BlockPos(x + 7, y + 18, z + 2), leaves);
        this.setBlockState(new BlockPos(x + 7, y + 18, z + 3), leaves);
        this.setBlockState(new BlockPos(x + 8, y + 18, z + 3), leaves);
        this.setBlockState(new BlockPos(x + 6, y + 18, z + 4), leaves);
        this.setBlockState(new BlockPos(x + 7, y + 18, z + 4), leaves);
        this.setBlockState(new BlockPos(x + 9, y + 18, z + 4), leaves);
        this.setBlockState(new BlockPos(x + 7, y + 18, z + 5), leaves);
        this.setBlockState(new BlockPos(x + 8, y + 18, z + 5), leaves);
        this.setBlockState(new BlockPos(x + 9, y + 18, z + 5), leaves);
        this.setBlockState(new BlockPos(x + 10, y + 18, z + 5), leaves);
        this.setBlockState(new BlockPos(x + 7, y + 18, z + 6), leaves);
        this.setBlockState(new BlockPos(x + 8, y + 18, z + 6), leaves);
        this.setBlockState(new BlockPos(x + 10, y + 18, z + 6), leaves);
        this.setBlockState(new BlockPos(x + 12, y + 18, z + 6), leaves);
        this.setBlockState(new BlockPos(x + 13, y + 18, z + 6), leaves);
        this.setBlockState(new BlockPos(x + 4, y + 18, z + 7), leaves);
        this.setBlockState(new BlockPos(x + 7, y + 18, z + 7), log);
        this.setBlockState(new BlockPos(x + 8, y + 18, z + 7), leaves);
        this.setBlockState(new BlockPos(x + 10, y + 18, z + 7), log);
        this.setBlockState(new BlockPos(x + 11, y + 18, z + 7), leaves);
        this.setBlockState(new BlockPos(x + 12, y + 18, z + 7), leaves);
        this.setBlockState(new BlockPos(x + 13, y + 18, z + 7), leaves);
        this.setBlockState(new BlockPos(x + 2, y + 18, z + 8), leaves);
        this.setBlockState(new BlockPos(x + 5, y + 18, z + 8), leaves);
        this.setBlockState(new BlockPos(x + 6, y + 18, z + 8), leaves);
        this.setBlockState(new BlockPos(x + 7, y + 18, z + 8), leaves);
        this.setBlockState(new BlockPos(x + 8, y + 18, z + 8), leaves);
        this.setBlockState(new BlockPos(x + 9, y + 18, z + 8), leaves);
        this.setBlockState(new BlockPos(x + 12, y + 18, z + 8), leaves);
        this.setBlockState(new BlockPos(x + 1, y + 18, z + 9), leaves);
        this.setBlockState(new BlockPos(x + 3, y + 18, z + 9), leaves);
        this.setBlockState(new BlockPos(x + 7, y + 18, z + 9), leaves);
        this.setBlockState(new BlockPos(x + 10, y + 18, z + 9), leaves);
        this.setBlockState(new BlockPos(x + 12, y + 18, z + 9), leaves);
        this.setBlockState(new BlockPos(x + 2, y + 18, z + 10), leaves);
        this.setBlockState(new BlockPos(x + 3, y + 18, z + 10), leaves);
        this.setBlockState(new BlockPos(x + 4, y + 18, z + 10), leaves);
        this.setBlockState(new BlockPos(x + 5, y + 18, z + 10), leaves);
        this.setBlockState(new BlockPos(x + 6, y + 18, z + 10), leaves);
        this.setBlockState(new BlockPos(x + 7, y + 18, z + 10), leaves);
        this.setBlockState(new BlockPos(x + 9, y + 18, z + 10), leaves);
        this.setBlockState(new BlockPos(x + 11, y + 18, z + 10), leaves);
        this.setBlockState(new BlockPos(x + 1, y + 18, z + 11), leaves);
        this.setBlockState(new BlockPos(x + 2, y + 18, z + 11), leaves);
        this.setBlockState(new BlockPos(x + 6, y + 18, z + 11), leaves);
        this.setBlockState(new BlockPos(x + 7, y + 18, z + 11), leaves);
        this.setBlockState(new BlockPos(x + 9, y + 18, z + 11), leaves);
        this.setBlockState(new BlockPos(x + 5, y + 18, z + 12), leaves);
        this.setBlockState(new BlockPos(x + 6, y + 18, z + 12), leaves);
        this.setBlockState(new BlockPos(x + 7, y + 18, z + 12), leaves);
        this.setBlockState(new BlockPos(x + 5, y + 19, z + 3), leaves);
        this.setBlockState(new BlockPos(x + 7, y + 19, z + 3), leaves);
        this.setBlockState(new BlockPos(x + 6, y + 19, z + 4), leaves);
        this.setBlockState(new BlockPos(x + 7, y + 19, z + 4), leaves);
        this.setBlockState(new BlockPos(x + 9, y + 19, z + 4), leaves);
        this.setBlockState(new BlockPos(x + 7, y + 19, z + 5), leaves);
        this.setBlockState(new BlockPos(x + 8, y + 19, z + 5), leaves);
        this.setBlockState(new BlockPos(x + 9, y + 19, z + 5), leaves);
        this.setBlockState(new BlockPos(x + 12, y + 19, z + 5), leaves);
        this.setBlockState(new BlockPos(x + 9, y + 19, z + 6), leaves);
        this.setBlockState(new BlockPos(x + 10, y + 19, z + 6), leaves);
        this.setBlockState(new BlockPos(x + 7, y + 19, z + 7), log);
        this.setBlockState(new BlockPos(x + 9, y + 19, z + 7), leaves);
        this.setBlockState(new BlockPos(x + 10, y + 19, z + 7), leaves);
        this.setBlockState(new BlockPos(x + 11, y + 19, z + 7), leaves);
        this.setBlockState(new BlockPos(x + 4, y + 19, z + 8), leaves);
        this.setBlockState(new BlockPos(x + 5, y + 19, z + 8), leaves);
        this.setBlockState(new BlockPos(x + 6, y + 19, z + 8), leaves);
        this.setBlockState(new BlockPos(x + 7, y + 19, z + 8), log);
        this.setBlockState(new BlockPos(x + 9, y + 19, z + 8), leaves);
        this.setBlockState(new BlockPos(x + 10, y + 19, z + 8), leaves);
        this.setBlockState(new BlockPos(x + 4, y + 19, z + 9), leaves);
        this.setBlockState(new BlockPos(x + 5, y + 19, z + 9), leaves);
        this.setBlockState(new BlockPos(x + 6, y + 19, z + 9), leaves);
        this.setBlockState(new BlockPos(x + 7, y + 19, z + 9), log);
        this.setBlockState(new BlockPos(x + 9, y + 19, z + 9), leaves);
        this.setBlockState(new BlockPos(x + 10, y + 19, z + 9), leaves);
        this.setBlockState(new BlockPos(x + 12, y + 19, z + 9), leaves);
        this.setBlockState(new BlockPos(x + 4, y + 19, z + 10), leaves);
        this.setBlockState(new BlockPos(x + 5, y + 19, z + 10), leaves);
        this.setBlockState(new BlockPos(x + 8, y + 19, z + 10), leaves);
        this.setBlockState(new BlockPos(x + 10, y + 19, z + 10), leaves);
        this.setBlockState(new BlockPos(x + 11, y + 19, z + 10), leaves);
        this.setBlockState(new BlockPos(x + 2, y + 19, z + 11), leaves);
        this.setBlockState(new BlockPos(x + 7, y + 19, z + 11), leaves);
        this.setBlockState(new BlockPos(x + 2, y + 19, z + 12), leaves);
        this.setBlockState(new BlockPos(x + 5, y + 19, z + 12), leaves);
        this.setBlockState(new BlockPos(x + 6, y + 20, z + 1), leaves);
        this.setBlockState(new BlockPos(x + 5, y + 20, z + 3), leaves);
        this.setBlockState(new BlockPos(x + 7, y + 20, z + 3), leaves);
        this.setBlockState(new BlockPos(x + 10, y + 20, z + 3), leaves);
        this.setBlockState(new BlockPos(x + 7, y + 20, z + 4), leaves);
        this.setBlockState(new BlockPos(x + 9, y + 20, z + 4), leaves);
        this.setBlockState(new BlockPos(x + 10, y + 20, z + 4), leaves);
        this.setBlockState(new BlockPos(x + 4, y + 20, z + 5), leaves);
        this.setBlockState(new BlockPos(x + 7, y + 20, z + 5), log);
        this.setBlockState(new BlockPos(x + 8, y + 20, z + 5), leaves);
        this.setBlockState(new BlockPos(x + 9, y + 20, z + 5), leaves);
        this.setBlockState(new BlockPos(x + 10, y + 20, z + 5), leaves);
        this.setBlockState(new BlockPos(x + 4, y + 20, z + 6), leaves);
        this.setBlockState(new BlockPos(x + 5, y + 20, z + 6), leaves);
        this.setBlockState(new BlockPos(x + 7, y + 20, z + 6), log);
        this.setBlockState(new BlockPos(x + 8, y + 20, z + 6), leaves);
        this.setBlockState(new BlockPos(x + 9, y + 20, z + 6), leaves);
        this.setBlockState(new BlockPos(x + 10, y + 20, z + 6), leaves);
        this.setBlockState(new BlockPos(x + 11, y + 20, z + 6), leaves);
        this.setBlockState(new BlockPos(x + 12, y + 20, z + 6), leaves);
        this.setBlockState(new BlockPos(x + 3, y + 20, z + 7), leaves);
        this.setBlockState(new BlockPos(x + 4, y + 20, z + 7), leaves);
        this.setBlockState(new BlockPos(x + 5, y + 20, z + 7), leaves);
        this.setBlockState(new BlockPos(x + 7, y + 20, z + 7), log);
        this.setBlockState(new BlockPos(x + 8, y + 20, z + 7), leaves);
        this.setBlockState(new BlockPos(x + 9, y + 20, z + 7), leaves);
        this.setBlockState(new BlockPos(x + 10, y + 20, z + 7), leaves);
        this.setBlockState(new BlockPos(x + 11, y + 20, z + 7), leaves);
        this.setBlockState(new BlockPos(x + 12, y + 20, z + 7), leaves);
        this.setBlockState(new BlockPos(x + 4, y + 20, z + 8), leaves);
        this.setBlockState(new BlockPos(x + 5, y + 20, z + 8), leaves);
        this.setBlockState(new BlockPos(x + 7, y + 20, z + 8), leaves);
        this.setBlockState(new BlockPos(x + 8, y + 20, z + 8), leaves);
        this.setBlockState(new BlockPos(x + 9, y + 20, z + 8), leaves);
        this.setBlockState(new BlockPos(x + 10, y + 20, z + 8), leaves);
        this.setBlockState(new BlockPos(x + 4, y + 20, z + 9), leaves);
        this.setBlockState(new BlockPos(x + 5, y + 20, z + 9), leaves);
        this.setBlockState(new BlockPos(x + 7, y + 20, z + 9), leaves);
        this.setBlockState(new BlockPos(x + 8, y + 20, z + 9), leaves);
        this.setBlockState(new BlockPos(x + 10, y + 20, z + 9), leaves);
        this.setBlockState(new BlockPos(x + 4, y + 20, z + 10), leaves);
        this.setBlockState(new BlockPos(x + 5, y + 20, z + 10), leaves);
        this.setBlockState(new BlockPos(x + 6, y + 20, z + 10), leaves);
        this.setBlockState(new BlockPos(x + 7, y + 20, z + 10), log);
        this.setBlockState(new BlockPos(x + 8, y + 20, z + 10), leaves);
        this.setBlockState(new BlockPos(x + 9, y + 20, z + 10), leaves);
        this.setBlockState(new BlockPos(x + 3, y + 20, z + 11), leaves);
        this.setBlockState(new BlockPos(x + 4, y + 20, z + 11), leaves);
        this.setBlockState(new BlockPos(x + 7, y + 20, z + 11), leaves);
        this.setBlockState(new BlockPos(x + 5, y + 20, z + 12), leaves);
        this.setBlockState(new BlockPos(x + 7, y + 20, z + 12), leaves);
        this.setBlockState(new BlockPos(x + 9, y + 20, z + 12), leaves);
        this.setBlockState(new BlockPos(x + 7, y + 20, z + 13), leaves);
        this.setBlockState(new BlockPos(x + 7, y + 21, z + 1), leaves);
        this.setBlockState(new BlockPos(x + 5, y + 21, z + 2), leaves);
        this.setBlockState(new BlockPos(x + 7, y + 21, z + 2), leaves);
        this.setBlockState(new BlockPos(x + 6, y + 21, z + 3), leaves);
        this.setBlockState(new BlockPos(x + 8, y + 21, z + 3), leaves);
        this.setBlockState(new BlockPos(x + 9, y + 21, z + 3), leaves);
        this.setBlockState(new BlockPos(x + 4, y + 21, z + 4), leaves);
        this.setBlockState(new BlockPos(x + 5, y + 21, z + 4), leaves);
        this.setBlockState(new BlockPos(x + 7, y + 21, z + 4), log);
        this.setBlockState(new BlockPos(x + 8, y + 21, z + 4), leaves);
        this.setBlockState(new BlockPos(x + 9, y + 21, z + 4), leaves);
        this.setBlockState(new BlockPos(x + 2, y + 21, z + 5), leaves);
        this.setBlockState(new BlockPos(x + 3, y + 21, z + 5), leaves);
        this.setBlockState(new BlockPos(x + 4, y + 21, z + 5), leaves);
        this.setBlockState(new BlockPos(x + 5, y + 21, z + 5), leaves);
        this.setBlockState(new BlockPos(x + 8, y + 21, z + 5), leaves);
        this.setBlockState(new BlockPos(x + 10, y + 21, z + 5), leaves);
        this.setBlockState(new BlockPos(x + 11, y + 21, z + 5), leaves);
        this.setBlockState(new BlockPos(x + 3, y + 21, z + 6), leaves);
        this.setBlockState(new BlockPos(x + 4, y + 21, z + 6), leaves);
        this.setBlockState(new BlockPos(x + 7, y + 21, z + 6), leaves);
        this.setBlockState(new BlockPos(x + 9, y + 21, z + 6), leaves);
        this.setBlockState(new BlockPos(x + 10, y + 21, z + 6), leaves);
        this.setBlockState(new BlockPos(x + 13, y + 21, z + 6), leaves);
        this.setBlockState(new BlockPos(x + 3, y + 21, z + 7), leaves);
        this.setBlockState(new BlockPos(x + 4, y + 21, z + 7), leaves);
        this.setBlockState(new BlockPos(x + 5, y + 21, z + 7), leaves);
        this.setBlockState(new BlockPos(x + 7, y + 21, z + 7), log);
        this.setBlockState(new BlockPos(x + 8, y + 21, z + 7), log);
        this.setBlockState(new BlockPos(x + 9, y + 21, z + 7), log);
        this.setBlockState(new BlockPos(x + 10, y + 21, z + 7), leaves);
        this.setBlockState(new BlockPos(x + 11, y + 21, z + 7), leaves);
        this.setBlockState(new BlockPos(x + 12, y + 21, z + 7), leaves);
        this.setBlockState(new BlockPos(x + 3, y + 21, z + 8), leaves);
        this.setBlockState(new BlockPos(x + 7, y + 21, z + 8), leaves);
        this.setBlockState(new BlockPos(x + 9, y + 21, z + 8), leaves);
        this.setBlockState(new BlockPos(x + 10, y + 21, z + 8), leaves);
        this.setBlockState(new BlockPos(x + 12, y + 21, z + 8), leaves);
        this.setBlockState(new BlockPos(x + 2, y + 21, z + 9), leaves);
        this.setBlockState(new BlockPos(x + 3, y + 21, z + 9), leaves);
        this.setBlockState(new BlockPos(x + 8, y + 21, z + 9), leaves);
        this.setBlockState(new BlockPos(x + 9, y + 21, z + 9), leaves);
        this.setBlockState(new BlockPos(x + 12, y + 21, z + 9), leaves);
        this.setBlockState(new BlockPos(x + 6, y + 21, z + 10), leaves);
        this.setBlockState(new BlockPos(x + 7, y + 21, z + 11), leaves);
        this.setBlockState(new BlockPos(x + 7, y + 21, z + 12), leaves);
        this.setBlockState(new BlockPos(x + 7, y + 22, z + 1), leaves);
        this.setBlockState(new BlockPos(x + 8, y + 22, z + 1), leaves);
        this.setBlockState(new BlockPos(x + 6, y + 22, z + 3), leaves);
        this.setBlockState(new BlockPos(x + 7, y + 22, z + 3), leaves);
        this.setBlockState(new BlockPos(x + 3, y + 22, z + 4), leaves);
        this.setBlockState(new BlockPos(x + 4, y + 22, z + 4), leaves);
        this.setBlockState(new BlockPos(x + 5, y + 22, z + 4), leaves);
        this.setBlockState(new BlockPos(x + 6, y + 22, z + 4), leaves);
        this.setBlockState(new BlockPos(x + 7, y + 22, z + 4), leaves);
        this.setBlockState(new BlockPos(x + 9, y + 22, z + 4), leaves);
        this.setBlockState(new BlockPos(x + 10, y + 22, z + 4), leaves);
        this.setBlockState(new BlockPos(x + 11, y + 22, z + 4), leaves);
        this.setBlockState(new BlockPos(x + 2, y + 22, z + 5), leaves);
        this.setBlockState(new BlockPos(x + 4, y + 22, z + 5), leaves);
        this.setBlockState(new BlockPos(x + 7, y + 22, z + 5), leaves);
        this.setBlockState(new BlockPos(x + 9, y + 22, z + 5), leaves);
        this.setBlockState(new BlockPos(x + 3, y + 22, z + 6), leaves);
        this.setBlockState(new BlockPos(x + 6, y + 22, z + 6), leaves);
        this.setBlockState(new BlockPos(x + 7, y + 22, z + 6), leaves);
        this.setBlockState(new BlockPos(x + 9, y + 22, z + 6), leaves);
        this.setBlockState(new BlockPos(x + 10, y + 22, z + 6), leaves);
        this.setBlockState(new BlockPos(x + 12, y + 22, z + 6), leaves);
        this.setBlockState(new BlockPos(x + 13, y + 22, z + 6), leaves);
        this.setBlockState(new BlockPos(x + 2, y + 22, z + 7), leaves);
        this.setBlockState(new BlockPos(x + 4, y + 22, z + 7), leaves);
        this.setBlockState(new BlockPos(x + 5, y + 22, z + 7), log);
        this.setBlockState(new BlockPos(x + 6, y + 22, z + 7), log);
        this.setBlockState(new BlockPos(x + 7, y + 22, z + 7), log);
        this.setBlockState(new BlockPos(x + 8, y + 22, z + 7), leaves);
        this.setBlockState(new BlockPos(x + 9, y + 22, z + 7), leaves);
        this.setBlockState(new BlockPos(x + 10, y + 22, z + 7), log);
        this.setBlockState(new BlockPos(x + 11, y + 22, z + 7), leaves);
        this.setBlockState(new BlockPos(x + 4, y + 22, z + 8), leaves);
        this.setBlockState(new BlockPos(x + 5, y + 22, z + 8), leaves);
        this.setBlockState(new BlockPos(x + 6, y + 22, z + 8), leaves);
        this.setBlockState(new BlockPos(x + 8, y + 22, z + 8), leaves);
        this.setBlockState(new BlockPos(x + 9, y + 22, z + 8), leaves);
        this.setBlockState(new BlockPos(x + 10, y + 22, z + 8), leaves);
        this.setBlockState(new BlockPos(x + 11, y + 22, z + 8), leaves);
        this.setBlockState(new BlockPos(x + 12, y + 22, z + 8), leaves);
        this.setBlockState(new BlockPos(x + 13, y + 22, z + 8), leaves);
        this.setBlockState(new BlockPos(x + 2, y + 22, z + 9), leaves);
        this.setBlockState(new BlockPos(x + 4, y + 22, z + 9), leaves);
        this.setBlockState(new BlockPos(x + 6, y + 22, z + 9), leaves);
        this.setBlockState(new BlockPos(x + 7, y + 22, z + 9), leaves);
        this.setBlockState(new BlockPos(x + 8, y + 22, z + 9), leaves);
        this.setBlockState(new BlockPos(x + 9, y + 22, z + 9), leaves);
        this.setBlockState(new BlockPos(x + 10, y + 22, z + 9), leaves);
        this.setBlockState(new BlockPos(x + 11, y + 22, z + 9), leaves);
        this.setBlockState(new BlockPos(x + 3, y + 22, z + 10), leaves);
        this.setBlockState(new BlockPos(x + 4, y + 22, z + 10), leaves);
        this.setBlockState(new BlockPos(x + 5, y + 22, z + 10), leaves);
        this.setBlockState(new BlockPos(x + 7, y + 22, z + 10), leaves);
        this.setBlockState(new BlockPos(x + 8, y + 22, z + 10), leaves);
        this.setBlockState(new BlockPos(x + 9, y + 22, z + 10), leaves);
        this.setBlockState(new BlockPos(x + 11, y + 22, z + 10), leaves);
        this.setBlockState(new BlockPos(x + 7, y + 22, z + 11), leaves);
        this.setBlockState(new BlockPos(x + 9, y + 22, z + 11), leaves);
        this.setBlockState(new BlockPos(x + 9, y + 22, z + 12), leaves);
        this.setBlockState(new BlockPos(x + 5, y + 23, z + 2), leaves);
        this.setBlockState(new BlockPos(x + 6, y + 23, z + 2), leaves);
        this.setBlockState(new BlockPos(x + 7, y + 23, z + 2), leaves);
        this.setBlockState(new BlockPos(x + 8, y + 23, z + 2), leaves);
        this.setBlockState(new BlockPos(x + 9, y + 23, z + 2), leaves);
        this.setBlockState(new BlockPos(x + 8, y + 23, z + 3), leaves);
        this.setBlockState(new BlockPos(x + 3, y + 23, z + 4), leaves);
        this.setBlockState(new BlockPos(x + 4, y + 23, z + 4), leaves);
        this.setBlockState(new BlockPos(x + 5, y + 23, z + 4), leaves);
        this.setBlockState(new BlockPos(x + 7, y + 23, z + 4), leaves);
        this.setBlockState(new BlockPos(x + 8, y + 23, z + 4), leaves);
        this.setBlockState(new BlockPos(x + 9, y + 23, z + 4), leaves);
        this.setBlockState(new BlockPos(x + 10, y + 23, z + 4), leaves);
        this.setBlockState(new BlockPos(x + 11, y + 23, z + 4), leaves);
        this.setBlockState(new BlockPos(x + 2, y + 23, z + 5), leaves);
        this.setBlockState(new BlockPos(x + 5, y + 23, z + 5), leaves);
        this.setBlockState(new BlockPos(x + 7, y + 23, z + 5), leaves);
        this.setBlockState(new BlockPos(x + 8, y + 23, z + 5), log);
        this.setBlockState(new BlockPos(x + 10, y + 23, z + 5), leaves);
        this.setBlockState(new BlockPos(x + 12, y + 23, z + 5), leaves);
        this.setBlockState(new BlockPos(x + 4, y + 23, z + 6), leaves);
        this.setBlockState(new BlockPos(x + 5, y + 23, z + 6), leaves);
        this.setBlockState(new BlockPos(x + 6, y + 23, z + 6), leaves);
        this.setBlockState(new BlockPos(x + 7, y + 23, z + 6), leaves);
        this.setBlockState(new BlockPos(x + 8, y + 23, z + 6), leaves);
        this.setBlockState(new BlockPos(x + 12, y + 23, z + 6), leaves);
        this.setBlockState(new BlockPos(x + 13, y + 23, z + 6), leaves);
        this.setBlockState(new BlockPos(x + 1, y + 23, z + 7), leaves);
        this.setBlockState(new BlockPos(x + 4, y + 23, z + 7), log);
        this.setBlockState(new BlockPos(x + 6, y + 23, z + 7), leaves);
        this.setBlockState(new BlockPos(x + 7, y + 23, z + 7), log);
        this.setBlockState(new BlockPos(x + 9, y + 23, z + 7), leaves);
        this.setBlockState(new BlockPos(x + 1, y + 23, z + 8), leaves);
        this.setBlockState(new BlockPos(x + 3, y + 23, z + 8), leaves);
        this.setBlockState(new BlockPos(x + 4, y + 23, z + 8), leaves);
        this.setBlockState(new BlockPos(x + 5, y + 23, z + 8), leaves);
        this.setBlockState(new BlockPos(x + 6, y + 23, z + 8), leaves);
        this.setBlockState(new BlockPos(x + 7, y + 23, z + 8), leaves);
        this.setBlockState(new BlockPos(x + 13, y + 23, z + 8), leaves);
        this.setBlockState(new BlockPos(x + 3, y + 23, z + 9), leaves);
        this.setBlockState(new BlockPos(x + 4, y + 23, z + 9), leaves);
        this.setBlockState(new BlockPos(x + 6, y + 23, z + 9), leaves);
        this.setBlockState(new BlockPos(x + 7, y + 23, z + 9), leaves);
        this.setBlockState(new BlockPos(x + 8, y + 23, z + 9), leaves);
        this.setBlockState(new BlockPos(x + 9, y + 23, z + 9), leaves);
        this.setBlockState(new BlockPos(x + 10, y + 23, z + 9), leaves);
        this.setBlockState(new BlockPos(x + 12, y + 23, z + 9), leaves);
        this.setBlockState(new BlockPos(x + 3, y + 23, z + 10), leaves);
        this.setBlockState(new BlockPos(x + 4, y + 23, z + 10), leaves);
        this.setBlockState(new BlockPos(x + 5, y + 23, z + 10), leaves);
        this.setBlockState(new BlockPos(x + 6, y + 23, z + 10), leaves);
        this.setBlockState(new BlockPos(x + 7, y + 23, z + 10), leaves);
        this.setBlockState(new BlockPos(x + 8, y + 23, z + 10), leaves);
        this.setBlockState(new BlockPos(x + 10, y + 23, z + 10), leaves);
        this.setBlockState(new BlockPos(x + 11, y + 23, z + 10), leaves);
        this.setBlockState(new BlockPos(x + 10, y + 23, z + 11), leaves);
        this.setBlockState(new BlockPos(x + 11, y + 23, z + 11), leaves);
        this.setBlockState(new BlockPos(x + 7, y + 24, z + 1), leaves);
        this.setBlockState(new BlockPos(x + 9, y + 24, z + 1), leaves);
        this.setBlockState(new BlockPos(x + 7, y + 24, z + 2), leaves);
        this.setBlockState(new BlockPos(x + 6, y + 24, z + 3), leaves);
        this.setBlockState(new BlockPos(x + 7, y + 24, z + 3), leaves);
        this.setBlockState(new BlockPos(x + 11, y + 24, z + 3), leaves);
        this.setBlockState(new BlockPos(x + 5, y + 24, z + 4), leaves);
        this.setBlockState(new BlockPos(x + 6, y + 24, z + 4), leaves);
        this.setBlockState(new BlockPos(x + 7, y + 24, z + 4), leaves);
        this.setBlockState(new BlockPos(x + 11, y + 24, z + 4), leaves);
        this.setBlockState(new BlockPos(x + 4, y + 24, z + 5), leaves);
        this.setBlockState(new BlockPos(x + 6, y + 24, z + 5), leaves);
        this.setBlockState(new BlockPos(x + 7, y + 24, z + 5), log);
        this.setBlockState(new BlockPos(x + 9, y + 24, z + 5), leaves);
        this.setBlockState(new BlockPos(x + 10, y + 24, z + 5), leaves);
        this.setBlockState(new BlockPos(x + 11, y + 24, z + 5), leaves);
        this.setBlockState(new BlockPos(x + 12, y + 24, z + 5), leaves);
        this.setBlockState(new BlockPos(x + 3, y + 24, z + 6), leaves);
        this.setBlockState(new BlockPos(x + 7, y + 24, z + 6), log);
        this.setBlockState(new BlockPos(x + 8, y + 24, z + 6), leaves);
        this.setBlockState(new BlockPos(x + 3, y + 24, z + 7), leaves);
        this.setBlockState(new BlockPos(x + 4, y + 24, z + 7), leaves);
        this.setBlockState(new BlockPos(x + 5, y + 24, z + 7), leaves);
        this.setBlockState(new BlockPos(x + 7, y + 24, z + 7), log);
        this.setBlockState(new BlockPos(x + 8, y + 24, z + 7), leaves);
        this.setBlockState(new BlockPos(x + 9, y + 24, z + 7), leaves);
        this.setBlockState(new BlockPos(x + 10, y + 24, z + 7), leaves);
        this.setBlockState(new BlockPos(x + 11, y + 24, z + 7), leaves);
        this.setBlockState(new BlockPos(x + 12, y + 24, z + 7), leaves);
        this.setBlockState(new BlockPos(x + 2, y + 24, z + 8), leaves);
        this.setBlockState(new BlockPos(x + 5, y + 24, z + 8), leaves);
        this.setBlockState(new BlockPos(x + 6, y + 24, z + 8), leaves);
        this.setBlockState(new BlockPos(x + 7, y + 24, z + 8), leaves);
        this.setBlockState(new BlockPos(x + 8, y + 24, z + 8), log);
        this.setBlockState(new BlockPos(x + 9, y + 24, z + 8), leaves);
        this.setBlockState(new BlockPos(x + 10, y + 24, z + 8), leaves);
        this.setBlockState(new BlockPos(x + 5, y + 24, z + 9), leaves);
        this.setBlockState(new BlockPos(x + 7, y + 24, z + 9), leaves);
        this.setBlockState(new BlockPos(x + 9, y + 24, z + 9), leaves);
        this.setBlockState(new BlockPos(x + 11, y + 24, z + 9), leaves);
        this.setBlockState(new BlockPos(x + 12, y + 24, z + 9), leaves);
        this.setBlockState(new BlockPos(x + 5, y + 24, z + 10), leaves);
        this.setBlockState(new BlockPos(x + 9, y + 24, z + 10), leaves);
        this.setBlockState(new BlockPos(x + 11, y + 24, z + 10), leaves);
        this.setBlockState(new BlockPos(x + 10, y + 24, z + 11), leaves);
        this.setBlockState(new BlockPos(x + 8, y + 24, z + 12), leaves);
        this.setBlockState(new BlockPos(x + 9, y + 24, z + 12), leaves);
        this.setBlockState(new BlockPos(x + 10, y + 24, z + 12), leaves);
        this.setBlockState(new BlockPos(x + 9, y + 25, z + 1), leaves);
        this.setBlockState(new BlockPos(x + 6, y + 25, z + 2), leaves);
        this.setBlockState(new BlockPos(x + 8, y + 25, z + 2), leaves);
        this.setBlockState(new BlockPos(x + 9, y + 25, z + 2), leaves);
        this.setBlockState(new BlockPos(x + 8, y + 25, z + 3), leaves);
        this.setBlockState(new BlockPos(x + 9, y + 25, z + 3), leaves);
        this.setBlockState(new BlockPos(x + 10, y + 25, z + 3), leaves);
        this.setBlockState(new BlockPos(x + 5, y + 25, z + 4), leaves);
        this.setBlockState(new BlockPos(x + 6, y + 25, z + 4), leaves);
        this.setBlockState(new BlockPos(x + 7, y + 25, z + 4), leaves);
        this.setBlockState(new BlockPos(x + 8, y + 25, z + 4), log);
        this.setBlockState(new BlockPos(x + 9, y + 25, z + 4), leaves);
        this.setBlockState(new BlockPos(x + 5, y + 25, z + 5), leaves);
        this.setBlockState(new BlockPos(x + 6, y + 25, z + 5), leaves);
        this.setBlockState(new BlockPos(x + 7, y + 25, z + 5), leaves);
        this.setBlockState(new BlockPos(x + 8, y + 25, z + 5), leaves);
        this.setBlockState(new BlockPos(x + 10, y + 25, z + 5), leaves);
        this.setBlockState(new BlockPos(x + 3, y + 25, z + 6), leaves);
        this.setBlockState(new BlockPos(x + 6, y + 25, z + 6), leaves);
        this.setBlockState(new BlockPos(x + 7, y + 25, z + 6), leaves);
        this.setBlockState(new BlockPos(x + 8, y + 25, z + 6), leaves);
        this.setBlockState(new BlockPos(x + 9, y + 25, z + 6), leaves);
        this.setBlockState(new BlockPos(x + 10, y + 25, z + 6), leaves);
        this.setBlockState(new BlockPos(x + 2, y + 25, z + 7), leaves);
        this.setBlockState(new BlockPos(x + 3, y + 25, z + 7), leaves);
        this.setBlockState(new BlockPos(x + 4, y + 25, z + 7), leaves);
        this.setBlockState(new BlockPos(x + 5, y + 25, z + 7), leaves);
        this.setBlockState(new BlockPos(x + 6, y + 25, z + 7), leaves);
        this.setBlockState(new BlockPos(x + 7, y + 25, z + 7), log);
        this.setBlockState(new BlockPos(x + 8, y + 25, z + 7), leaves);
        this.setBlockState(new BlockPos(x + 9, y + 25, z + 7), leaves);
        this.setBlockState(new BlockPos(x + 11, y + 25, z + 7), leaves);
        this.setBlockState(new BlockPos(x + 4, y + 25, z + 8), leaves);
        this.setBlockState(new BlockPos(x + 6, y + 25, z + 8), leaves);
        this.setBlockState(new BlockPos(x + 7, y + 25, z + 8), leaves);
        this.setBlockState(new BlockPos(x + 8, y + 25, z + 8), leaves);
        this.setBlockState(new BlockPos(x + 5, y + 25, z + 9), leaves);
        this.setBlockState(new BlockPos(x + 6, y + 25, z + 9), leaves);
        this.setBlockState(new BlockPos(x + 7, y + 25, z + 9), leaves);
        this.setBlockState(new BlockPos(x + 8, y + 25, z + 9), leaves);
        this.setBlockState(new BlockPos(x + 9, y + 25, z + 9), log);
        this.setBlockState(new BlockPos(x + 10, y + 25, z + 9), leaves);
        this.setBlockState(new BlockPos(x + 11, y + 25, z + 9), leaves);
        this.setBlockState(new BlockPos(x + 12, y + 25, z + 9), leaves);
        this.setBlockState(new BlockPos(x + 10, y + 25, z + 10), leaves);
        this.setBlockState(new BlockPos(x + 11, y + 25, z + 10), leaves);
        this.setBlockState(new BlockPos(x + 9, y + 25, z + 11), leaves);
        this.setBlockState(new BlockPos(x + 10, y + 25, z + 11), leaves);
        this.setBlockState(new BlockPos(x + 11, y + 25, z + 11), leaves);
        this.setBlockState(new BlockPos(x + 9, y + 25, z + 12), leaves);
        this.setBlockState(new BlockPos(x + 6, y + 26, z + 2), leaves);
        this.setBlockState(new BlockPos(x + 9, y + 26, z + 2), leaves);
        this.setBlockState(new BlockPos(x + 8, y + 26, z + 3), leaves);
        this.setBlockState(new BlockPos(x + 6, y + 26, z + 4), leaves);
        this.setBlockState(new BlockPos(x + 7, y + 26, z + 4), leaves);
        this.setBlockState(new BlockPos(x + 8, y + 26, z + 4), leaves);
        this.setBlockState(new BlockPos(x + 5, y + 26, z + 5), leaves);
        this.setBlockState(new BlockPos(x + 8, y + 26, z + 5), leaves);
        this.setBlockState(new BlockPos(x + 9, y + 26, z + 5), leaves);
        this.setBlockState(new BlockPos(x + 11, y + 26, z + 5), leaves);
        this.setBlockState(new BlockPos(x + 4, y + 26, z + 6), leaves);
        this.setBlockState(new BlockPos(x + 7, y + 26, z + 6), log);
        this.setBlockState(new BlockPos(x + 3, y + 26, z + 7), leaves);
        this.setBlockState(new BlockPos(x + 5, y + 26, z + 7), leaves);
        this.setBlockState(new BlockPos(x + 7, y + 26, z + 7), log);
        this.setBlockState(new BlockPos(x + 8, y + 26, z + 7), log);
        this.setBlockState(new BlockPos(x + 9, y + 26, z + 7), leaves);
        this.setBlockState(new BlockPos(x + 10, y + 26, z + 7), leaves);
        this.setBlockState(new BlockPos(x + 3, y + 26, z + 8), leaves);
        this.setBlockState(new BlockPos(x + 4, y + 26, z + 8), leaves);
        this.setBlockState(new BlockPos(x + 8, y + 26, z + 8), leaves);
        this.setBlockState(new BlockPos(x + 9, y + 26, z + 8), leaves);
        this.setBlockState(new BlockPos(x + 10, y + 26, z + 8), leaves);
        this.setBlockState(new BlockPos(x + 11, y + 26, z + 8), leaves);
        this.setBlockState(new BlockPos(x + 5, y + 26, z + 9), leaves);
        this.setBlockState(new BlockPos(x + 6, y + 26, z + 9), leaves);
        this.setBlockState(new BlockPos(x + 8, y + 26, z + 9), leaves);
        this.setBlockState(new BlockPos(x + 9, y + 26, z + 9), leaves);
        this.setBlockState(new BlockPos(x + 10, y + 26, z + 9), leaves);
        this.setBlockState(new BlockPos(x + 11, y + 26, z + 9), leaves);
        this.setBlockState(new BlockPos(x + 7, y + 26, z + 10), leaves);
        this.setBlockState(new BlockPos(x + 11, y + 26, z + 10), leaves);
        this.setBlockState(new BlockPos(x + 10, y + 26, z + 11), leaves);
        this.setBlockState(new BlockPos(x + 11, y + 26, z + 11), leaves);
        this.setBlockState(new BlockPos(x + 6, y + 27, z + 3), leaves);
        this.setBlockState(new BlockPos(x + 6, y + 27, z + 4), leaves);
        this.setBlockState(new BlockPos(x + 7, y + 27, z + 4), leaves);
        this.setBlockState(new BlockPos(x + 8, y + 27, z + 4), leaves);
        this.setBlockState(new BlockPos(x + 6, y + 27, z + 5), leaves);
        this.setBlockState(new BlockPos(x + 8, y + 27, z + 5), leaves);
        this.setBlockState(new BlockPos(x + 9, y + 27, z + 5), leaves);
        this.setBlockState(new BlockPos(x + 4, y + 27, z + 6), leaves);
        this.setBlockState(new BlockPos(x + 5, y + 27, z + 6), leaves);
        this.setBlockState(new BlockPos(x + 7, y + 27, z + 6), leaves);
        this.setBlockState(new BlockPos(x + 10, y + 27, z + 6), leaves);
        this.setBlockState(new BlockPos(x + 4, y + 27, z + 7), leaves);
        this.setBlockState(new BlockPos(x + 5, y + 27, z + 7), leaves);
        this.setBlockState(new BlockPos(x + 6, y + 27, z + 7), leaves);
        this.setBlockState(new BlockPos(x + 7, y + 27, z + 7), log);
        this.setBlockState(new BlockPos(x + 9, y + 27, z + 7), leaves);
        this.setBlockState(new BlockPos(x + 10, y + 27, z + 7), leaves);
        this.setBlockState(new BlockPos(x + 4, y + 27, z + 8), leaves);
        this.setBlockState(new BlockPos(x + 5, y + 27, z + 8), leaves);
        this.setBlockState(new BlockPos(x + 7, y + 27, z + 8), leaves);
        this.setBlockState(new BlockPos(x + 8, y + 27, z + 8), leaves);
        this.setBlockState(new BlockPos(x + 9, y + 27, z + 8), leaves);
        this.setBlockState(new BlockPos(x + 5, y + 27, z + 9), leaves);
        this.setBlockState(new BlockPos(x + 7, y + 27, z + 9), leaves);
        this.setBlockState(new BlockPos(x + 8, y + 27, z + 9), leaves);
        this.setBlockState(new BlockPos(x + 9, y + 27, z + 9), leaves);
        this.setBlockState(new BlockPos(x + 11, y + 27, z + 9), leaves);
        this.setBlockState(new BlockPos(x + 6, y + 27, z + 10), leaves);
        this.setBlockState(new BlockPos(x + 9, y + 27, z + 10), leaves);
        this.setBlockState(new BlockPos(x + 10, y + 27, z + 11), leaves);
        this.setBlockState(new BlockPos(x + 6, y + 28, z + 4), leaves);
        this.setBlockState(new BlockPos(x + 7, y + 28, z + 4), leaves);
        this.setBlockState(new BlockPos(x + 8, y + 28, z + 4), leaves);
        this.setBlockState(new BlockPos(x + 8, y + 28, z + 5), leaves);
        this.setBlockState(new BlockPos(x + 7, y + 28, z + 6), leaves);
        this.setBlockState(new BlockPos(x + 8, y + 28, z + 6), leaves);
        this.setBlockState(new BlockPos(x + 7, y + 28, z + 7), log);
        this.setBlockState(new BlockPos(x + 8, y + 28, z + 7), leaves);
        this.setBlockState(new BlockPos(x + 5, y + 28, z + 8), leaves);
        this.setBlockState(new BlockPos(x + 6, y + 28, z + 8), leaves);
        this.setBlockState(new BlockPos(x + 7, y + 28, z + 8), leaves);
        this.setBlockState(new BlockPos(x + 8, y + 28, z + 8), leaves);
        this.setBlockState(new BlockPos(x + 10, y + 28, z + 8), leaves);
        this.setBlockState(new BlockPos(x + 7, y + 28, z + 9), leaves);
        this.setBlockState(new BlockPos(x + 8, y + 28, z + 9), leaves);
        this.setBlockState(new BlockPos(x + 7, y + 28, z + 10), leaves);
        this.setBlockState(new BlockPos(x + 8, y + 28, z + 10), leaves);
        this.setBlockState(new BlockPos(x + 7, y + 29, z + 5), leaves);
        this.setBlockState(new BlockPos(x + 5, y + 29, z + 6), leaves);
        this.setBlockState(new BlockPos(x + 6, y + 29, z + 6), leaves);
        this.setBlockState(new BlockPos(x + 7, y + 29, z + 7), leaves);
        this.setBlockState(new BlockPos(x + 8, y + 29, z + 9), leaves);
        this.setBlockState(new BlockPos(x + 6, y + 30, z + 6), leaves);
        this.setBlockState(new BlockPos(x + 7, y + 30, z + 7), leaves);
        this.setBlockState(new BlockPos(x + 6, y + 30, z + 8), leaves);
    }
}
