package appalachia.world.gen.feature.tree;

import java.util.ArrayList;
import java.util.Arrays;
import java.util.Random;

import net.minecraft.block.BlockLeaves;
import net.minecraft.block.state.IBlockState;
import net.minecraft.init.Blocks;
import net.minecraft.util.math.BlockPos;
import net.minecraft.world.World;

/**
 * Acer Rubrum (Red Maple)
 */
public class TreeAcerRubrum extends AppalachiaTree {

    public TreeAcerRubrum() {

        super();

        this.validGroundBlocks = new ArrayList<IBlockState>(Arrays.asList(Blocks.GRASS.getDefaultState(), Blocks.DIRT.getDefaultState()));
    }

    @Override
    public boolean generate(World world, Random rand, BlockPos pos) {

        int x = pos.getX();
        int y = pos.getY();
        int z = pos.getZ();

        if (!isValidGroundBlock(world, rand, new BlockPos(x+5,  y+0,  z+5))) {
            return false;
        }

        IBlockState leaves = this.leavesBlock.withProperty(BlockLeaves.CHECK_DECAY, false);

        world.setBlockState(new BlockPos(x+5,  y+0,  z+5),  this.logBlock);
        this.setBlockMetadataWithNotify(x+5, y+0, z+5, 12, 12);
        world.setBlockState(new BlockPos(x+5,  y+1,  z+5),  this.logBlock);
        this.setBlockMetadataWithNotify(x+5, y+1, z+5, 12, 12);
        world.setBlockState(new BlockPos(x+5,  y+2,  z+5),  this.logBlock);
        this.setBlockMetadataWithNotify(x+5, y+2, z+5, 12, 12);
        world.setBlockState(new BlockPos(x+5,  y+3,  z+2),  leaves);
        this.setBlockMetadataWithNotify(x+5, y+3, z+2, 12, 12);
        world.setBlockState(new BlockPos(x+4,  y+3,  z+5),  this.logBlock);
        this.setBlockMetadataWithNotify(x+4, y+3, z+5, 12, 12);
        world.setBlockState(new BlockPos(x+5,  y+3,  z+5),  this.logBlock);
        this.setBlockMetadataWithNotify(x+5, y+3, z+5, 12, 12);
        world.setBlockState(new BlockPos(x+5,  y+3,  z+7),  leaves);
        this.setBlockMetadataWithNotify(x+5, y+3, z+7, 4, 4);
        world.setBlockState(new BlockPos(x+5,  y+3,  z+8),  leaves);
        this.setBlockMetadataWithNotify(x+5, y+3, z+8, 4, 4);
        world.setBlockState(new BlockPos(x+6,  y+3,  z+9),  leaves);
        this.setBlockMetadataWithNotify(x+6, y+3, z+9, 4, 4);
        world.setBlockState(new BlockPos(x+5,  y+4,  z+1),  leaves);
        this.setBlockMetadataWithNotify(x+5, y+4, z+1, 12, 12);
        world.setBlockState(new BlockPos(x+3,  y+4,  z+2),  leaves);
        this.setBlockMetadataWithNotify(x+3, y+4, z+2, 12, 12);
        world.setBlockState(new BlockPos(x+4,  y+4,  z+2),  leaves);
        this.setBlockMetadataWithNotify(x+4, y+4, z+2, 12, 12);
        world.setBlockState(new BlockPos(x+5,  y+4,  z+2),  leaves);
        this.setBlockMetadataWithNotify(x+5, y+4, z+2, 12, 12);
        world.setBlockState(new BlockPos(x+6,  y+4,  z+2),  leaves);
        this.setBlockMetadataWithNotify(x+6, y+4, z+2, 12, 12);
        world.setBlockState(new BlockPos(x+7,  y+4,  z+2),  leaves);
        this.setBlockMetadataWithNotify(x+7, y+4, z+2, 12, 12);
        world.setBlockState(new BlockPos(x+4,  y+4,  z+3),  leaves);
        this.setBlockMetadataWithNotify(x+4, y+4, z+3, 12, 12);
        world.setBlockState(new BlockPos(x+5,  y+4,  z+3),  leaves);
        this.setBlockMetadataWithNotify(x+5, y+4, z+3, 12, 12);
        world.setBlockState(new BlockPos(x+6,  y+4,  z+3),  leaves);
        this.setBlockMetadataWithNotify(x+6, y+4, z+3, 12, 12);
        world.setBlockState(new BlockPos(x+7,  y+4,  z+3),  leaves);
        this.setBlockMetadataWithNotify(x+7, y+4, z+3, 12, 12);
        world.setBlockState(new BlockPos(x+8,  y+4,  z+3),  leaves);
        this.setBlockMetadataWithNotify(x+8, y+4, z+3, 12, 12);
        world.setBlockState(new BlockPos(x+1,  y+4,  z+4),  leaves);
        this.setBlockMetadataWithNotify(x+1, y+4, z+4, 12, 12);
        world.setBlockState(new BlockPos(x+2,  y+4,  z+4),  leaves);
        this.setBlockMetadataWithNotify(x+2, y+4, z+4, 12, 12);
        world.setBlockState(new BlockPos(x+5,  y+4,  z+4),  leaves);
        this.setBlockMetadataWithNotify(x+5, y+4, z+4, 12, 12);
        world.setBlockState(new BlockPos(x+6,  y+4,  z+4),  this.logBlock);
        this.setBlockMetadataWithNotify(x+6, y+4, z+4, 12, 12);
        world.setBlockState(new BlockPos(x+8,  y+4,  z+4),  leaves);
        this.setBlockMetadataWithNotify(x+8, y+4, z+4, 12, 12);
        world.setBlockState(new BlockPos(x+3,  y+4,  z+5),  this.logBlock);
        this.setBlockMetadataWithNotify(x+3, y+4, z+5, 12, 12);
        world.setBlockState(new BlockPos(x+5,  y+4,  z+5),  this.logBlock);
        this.setBlockMetadataWithNotify(x+5, y+4, z+5, 12, 12);
        world.setBlockState(new BlockPos(x+3,  y+4,  z+6),  leaves);
        this.setBlockMetadataWithNotify(x+3, y+4, z+6, 12, 12);
        world.setBlockState(new BlockPos(x+5,  y+4,  z+6),  this.logBlock);
        this.setBlockMetadataWithNotify(x+5, y+4, z+6, 12, 12);
        world.setBlockState(new BlockPos(x+6,  y+4,  z+6),  leaves);
        this.setBlockMetadataWithNotify(x+6, y+4, z+6, 12, 12);
        world.setBlockState(new BlockPos(x+5,  y+4,  z+7),  this.logBlock);
        this.setBlockMetadataWithNotify(x+5, y+4, z+7, 12, 12);
        world.setBlockState(new BlockPos(x+7,  y+4,  z+7),  leaves);
        this.setBlockMetadataWithNotify(x+7, y+4, z+7, 4, 4);
        world.setBlockState(new BlockPos(x+4,  y+4,  z+8),  leaves);
        this.setBlockMetadataWithNotify(x+4, y+4, z+8, 4, 4);
        world.setBlockState(new BlockPos(x+5,  y+4,  z+8),  leaves);
        this.setBlockMetadataWithNotify(x+5, y+4, z+8, 4, 4);
        world.setBlockState(new BlockPos(x+6,  y+4,  z+8),  leaves);
        this.setBlockMetadataWithNotify(x+6, y+4, z+8, 4, 4);
        world.setBlockState(new BlockPos(x+7,  y+4,  z+8),  leaves);
        this.setBlockMetadataWithNotify(x+7, y+4, z+8, 4, 4);
        world.setBlockState(new BlockPos(x+3,  y+4,  z+9),  leaves);
        this.setBlockMetadataWithNotify(x+3, y+4, z+9, 4, 4);
        world.setBlockState(new BlockPos(x+5,  y+4,  z+9),  leaves);
        this.setBlockMetadataWithNotify(x+5, y+4, z+9, 4, 4);
        world.setBlockState(new BlockPos(x+6,  y+4,  z+9),  leaves);
        this.setBlockMetadataWithNotify(x+6, y+4, z+9, 4, 4);
        world.setBlockState(new BlockPos(x+7,  y+4,  z+9),  leaves);
        this.setBlockMetadataWithNotify(x+7, y+4, z+9, 4, 4);
        world.setBlockState(new BlockPos(x+4,  y+5,  z+0),  leaves);
        this.setBlockMetadataWithNotify(x+4, y+5, z+0, 12, 12);
        world.setBlockState(new BlockPos(x+6,  y+5,  z+0),  leaves);
        this.setBlockMetadataWithNotify(x+6, y+5, z+0, 12, 12);
        world.setBlockState(new BlockPos(x+3,  y+5,  z+1),  leaves);
        this.setBlockMetadataWithNotify(x+3, y+5, z+1, 12, 12);
        world.setBlockState(new BlockPos(x+4,  y+5,  z+1),  leaves);
        this.setBlockMetadataWithNotify(x+4, y+5, z+1, 12, 12);
        world.setBlockState(new BlockPos(x+6,  y+5,  z+1),  leaves);
        this.setBlockMetadataWithNotify(x+6, y+5, z+1, 12, 12);
        world.setBlockState(new BlockPos(x+3,  y+5,  z+2),  leaves);
        this.setBlockMetadataWithNotify(x+3, y+5, z+2, 12, 12);
        world.setBlockState(new BlockPos(x+6,  y+5,  z+2),  leaves);
        this.setBlockMetadataWithNotify(x+6, y+5, z+2, 12, 12);
        world.setBlockState(new BlockPos(x+7,  y+5,  z+2),  leaves);
        this.setBlockMetadataWithNotify(x+7, y+5, z+2, 12, 12);
        world.setBlockState(new BlockPos(x+9,  y+5,  z+2),  leaves);
        this.setBlockMetadataWithNotify(x+9, y+5, z+2, 12, 12);
        world.setBlockState(new BlockPos(x+10,  y+5,  z+2),  leaves);
        this.setBlockMetadataWithNotify(x+10, y+5, z+2, 12, 12);
        world.setBlockState(new BlockPos(x+2,  y+5,  z+3),  leaves);
        this.setBlockMetadataWithNotify(x+2, y+5, z+3, 12, 12);
        world.setBlockState(new BlockPos(x+3,  y+5,  z+3),  leaves);
        this.setBlockMetadataWithNotify(x+3, y+5, z+3, 12, 12);
        world.setBlockState(new BlockPos(x+4,  y+5,  z+3),  leaves);
        this.setBlockMetadataWithNotify(x+4, y+5, z+3, 12, 12);
        world.setBlockState(new BlockPos(x+5,  y+5,  z+3),  leaves);
        this.setBlockMetadataWithNotify(x+5, y+5, z+3, 12, 12);
        world.setBlockState(new BlockPos(x+6,  y+5,  z+3),  leaves);
        this.setBlockMetadataWithNotify(x+6, y+5, z+3, 12, 12);
        world.setBlockState(new BlockPos(x+7,  y+5,  z+3),  this.logBlock);
        this.setBlockMetadataWithNotify(x+7, y+5, z+3, 12, 12);
        world.setBlockState(new BlockPos(x+8,  y+5,  z+3),  leaves);
        this.setBlockMetadataWithNotify(x+8, y+5, z+3, 12, 12);
        world.setBlockState(new BlockPos(x+0,  y+5,  z+4),  leaves);
        this.setBlockMetadataWithNotify(x+0, y+5, z+4, 12, 12);
        world.setBlockState(new BlockPos(x+2,  y+5,  z+4),  leaves);
        this.setBlockMetadataWithNotify(x+2, y+5, z+4, 12, 12);
        world.setBlockState(new BlockPos(x+5,  y+5,  z+4),  this.logBlock);
        this.setBlockMetadataWithNotify(x+5, y+5, z+4, 12, 12);
        world.setBlockState(new BlockPos(x+6,  y+5,  z+4),  leaves);
        this.setBlockMetadataWithNotify(x+6, y+5, z+4, 12, 12);
        world.setBlockState(new BlockPos(x+10,  y+5,  z+4),  leaves);
        this.setBlockMetadataWithNotify(x+10, y+5, z+4, 12, 12);
        world.setBlockState(new BlockPos(x+0,  y+5,  z+5),  leaves);
        this.setBlockMetadataWithNotify(x+0, y+5, z+5, 12, 12);
        world.setBlockState(new BlockPos(x+1,  y+5,  z+5),  leaves);
        this.setBlockMetadataWithNotify(x+1, y+5, z+5, 12, 12);
        world.setBlockState(new BlockPos(x+2,  y+5,  z+5),  leaves);
        this.setBlockMetadataWithNotify(x+2, y+5, z+5, 12, 12);
        world.setBlockState(new BlockPos(x+3,  y+5,  z+5),  this.logBlock);
        this.setBlockMetadataWithNotify(x+3, y+5, z+5, 12, 12);
        world.setBlockState(new BlockPos(x+4,  y+5,  z+5),  leaves);
        this.setBlockMetadataWithNotify(x+4, y+5, z+5, 12, 12);
        world.setBlockState(new BlockPos(x+5,  y+5,  z+5),  this.logBlock);
        this.setBlockMetadataWithNotify(x+5, y+5, z+5, 12, 12);
        world.setBlockState(new BlockPos(x+7,  y+5,  z+5),  leaves);
        this.setBlockMetadataWithNotify(x+7, y+5, z+5, 12, 12);
        world.setBlockState(new BlockPos(x+8,  y+5,  z+5),  leaves);
        this.setBlockMetadataWithNotify(x+8, y+5, z+5, 12, 12);
        world.setBlockState(new BlockPos(x+2,  y+5,  z+6),  leaves);
        this.setBlockMetadataWithNotify(x+2, y+5, z+6, 12, 12);
        world.setBlockState(new BlockPos(x+4,  y+5,  z+6),  leaves);
        this.setBlockMetadataWithNotify(x+4, y+5, z+6, 12, 12);
        world.setBlockState(new BlockPos(x+4,  y+5,  z+7),  leaves);
        this.setBlockMetadataWithNotify(x+4, y+5, z+7, 4, 4);
        world.setBlockState(new BlockPos(x+5,  y+5,  z+7),  leaves);
        this.setBlockMetadataWithNotify(x+5, y+5, z+7, 4, 4);
        world.setBlockState(new BlockPos(x+3,  y+5,  z+8),  leaves);
        this.setBlockMetadataWithNotify(x+3, y+5, z+8, 4, 4);
        world.setBlockState(new BlockPos(x+4,  y+5,  z+8),  leaves);
        this.setBlockMetadataWithNotify(x+4, y+5, z+8, 4, 4);
        world.setBlockState(new BlockPos(x+5,  y+5,  z+8),  this.logBlock);
        this.setBlockMetadataWithNotify(x+5, y+5, z+8, 12, 12);
        world.setBlockState(new BlockPos(x+6,  y+5,  z+8),  leaves);
        this.setBlockMetadataWithNotify(x+6, y+5, z+8, 4, 4);
        world.setBlockState(new BlockPos(x+4,  y+5,  z+9),  leaves);
        this.setBlockMetadataWithNotify(x+4, y+5, z+9, 4, 4);
        world.setBlockState(new BlockPos(x+5,  y+5,  z+9),  leaves);
        this.setBlockMetadataWithNotify(x+5, y+5, z+9, 4, 4);
        world.setBlockState(new BlockPos(x+5,  y+5,  z+10),  leaves);
        this.setBlockMetadataWithNotify(x+5, y+5, z+10, 4, 4);
        world.setBlockState(new BlockPos(x+6,  y+5,  z+10),  leaves);
        this.setBlockMetadataWithNotify(x+6, y+5, z+10, 4, 4);
        world.setBlockState(new BlockPos(x+3,  y+6,  z+1),  leaves);
        this.setBlockMetadataWithNotify(x+3, y+6, z+1, 12, 12);
        world.setBlockState(new BlockPos(x+4,  y+6,  z+1),  leaves);
        this.setBlockMetadataWithNotify(x+4, y+6, z+1, 12, 12);
        world.setBlockState(new BlockPos(x+6,  y+6,  z+1),  leaves);
        this.setBlockMetadataWithNotify(x+6, y+6, z+1, 12, 12);
        world.setBlockState(new BlockPos(x+8,  y+6,  z+1),  leaves);
        this.setBlockMetadataWithNotify(x+8, y+6, z+1, 12, 12);
        world.setBlockState(new BlockPos(x+4,  y+6,  z+2),  leaves);
        this.setBlockMetadataWithNotify(x+4, y+6, z+2, 12, 12);
        world.setBlockState(new BlockPos(x+5,  y+6,  z+2),  leaves);
        this.setBlockMetadataWithNotify(x+5, y+6, z+2, 12, 12);
        world.setBlockState(new BlockPos(x+6,  y+6,  z+2),  leaves);
        this.setBlockMetadataWithNotify(x+6, y+6, z+2, 12, 12);
        world.setBlockState(new BlockPos(x+8,  y+6,  z+2),  leaves);
        this.setBlockMetadataWithNotify(x+8, y+6, z+2, 12, 12);
        world.setBlockState(new BlockPos(x+2,  y+6,  z+3),  leaves);
        this.setBlockMetadataWithNotify(x+2, y+6, z+3, 12, 12);
        world.setBlockState(new BlockPos(x+5,  y+6,  z+3),  this.logBlock);
        this.setBlockMetadataWithNotify(x+5, y+6, z+3, 12, 12);
        world.setBlockState(new BlockPos(x+6,  y+6,  z+3),  leaves);
        this.setBlockMetadataWithNotify(x+6, y+6, z+3, 12, 12);
        world.setBlockState(new BlockPos(x+8,  y+6,  z+3),  this.logBlock);
        this.setBlockMetadataWithNotify(x+8, y+6, z+3, 12, 12);
        world.setBlockState(new BlockPos(x+9,  y+6,  z+3),  leaves);
        this.setBlockMetadataWithNotify(x+9, y+6, z+3, 12, 12);
        world.setBlockState(new BlockPos(x+10,  y+6,  z+3),  leaves);
        this.setBlockMetadataWithNotify(x+10, y+6, z+3, 12, 12);
        world.setBlockState(new BlockPos(x+2,  y+6,  z+4),  leaves);
        this.setBlockMetadataWithNotify(x+2, y+6, z+4, 12, 12);
        world.setBlockState(new BlockPos(x+3,  y+6,  z+4),  leaves);
        this.setBlockMetadataWithNotify(x+3, y+6, z+4, 12, 12);
        world.setBlockState(new BlockPos(x+4,  y+6,  z+4),  leaves);
        this.setBlockMetadataWithNotify(x+4, y+6, z+4, 12, 12);
        world.setBlockState(new BlockPos(x+5,  y+6,  z+4),  leaves);
        this.setBlockMetadataWithNotify(x+5, y+6, z+4, 12, 12);
        world.setBlockState(new BlockPos(x+6,  y+6,  z+4),  leaves);
        this.setBlockMetadataWithNotify(x+6, y+6, z+4, 12, 12);
        world.setBlockState(new BlockPos(x+8,  y+6,  z+4),  leaves);
        this.setBlockMetadataWithNotify(x+8, y+6, z+4, 12, 12);
        world.setBlockState(new BlockPos(x+9,  y+6,  z+4),  leaves);
        this.setBlockMetadataWithNotify(x+9, y+6, z+4, 12, 12);
        world.setBlockState(new BlockPos(x+1,  y+6,  z+5),  leaves);
        this.setBlockMetadataWithNotify(x+1, y+6, z+5, 12, 12);
        world.setBlockState(new BlockPos(x+2,  y+6,  z+5),  this.logBlock);
        this.setBlockMetadataWithNotify(x+2, y+6, z+5, 12, 12);
        world.setBlockState(new BlockPos(x+3,  y+6,  z+5),  leaves);
        this.setBlockMetadataWithNotify(x+3, y+6, z+5, 12, 12);
        world.setBlockState(new BlockPos(x+4,  y+6,  z+5),  leaves);
        this.setBlockMetadataWithNotify(x+4, y+6, z+5, 12, 12);
        world.setBlockState(new BlockPos(x+5,  y+6,  z+5),  this.logBlock);
        this.setBlockMetadataWithNotify(x+5, y+6, z+5, 12, 12);
        world.setBlockState(new BlockPos(x+8,  y+6,  z+5),  leaves);
        this.setBlockMetadataWithNotify(x+8, y+6, z+5, 12, 12);
        world.setBlockState(new BlockPos(x+9,  y+6,  z+5),  leaves);
        this.setBlockMetadataWithNotify(x+9, y+6, z+5, 12, 12);
        world.setBlockState(new BlockPos(x+0,  y+6,  z+6),  leaves);
        this.setBlockMetadataWithNotify(x+0, y+6, z+6, 12, 12);
        world.setBlockState(new BlockPos(x+1,  y+6,  z+6),  leaves);
        this.setBlockMetadataWithNotify(x+1, y+6, z+6, 12, 12);
        world.setBlockState(new BlockPos(x+2,  y+6,  z+6),  leaves);
        this.setBlockMetadataWithNotify(x+2, y+6, z+6, 12, 12);
        world.setBlockState(new BlockPos(x+4,  y+6,  z+6),  leaves);
        this.setBlockMetadataWithNotify(x+4, y+6, z+6, 12, 12);
        world.setBlockState(new BlockPos(x+5,  y+6,  z+6),  leaves);
        this.setBlockMetadataWithNotify(x+5, y+6, z+6, 12, 12);
        world.setBlockState(new BlockPos(x+6,  y+6,  z+6),  this.logBlock);
        this.setBlockMetadataWithNotify(x+6, y+6, z+6, 12, 12);
        world.setBlockState(new BlockPos(x+2,  y+6,  z+7),  leaves);
        this.setBlockMetadataWithNotify(x+2, y+6, z+7, 12, 12);
        world.setBlockState(new BlockPos(x+3,  y+6,  z+7),  leaves);
        this.setBlockMetadataWithNotify(x+3, y+6, z+7, 12, 12);
        world.setBlockState(new BlockPos(x+7,  y+6,  z+7),  leaves);
        this.setBlockMetadataWithNotify(x+7, y+6, z+7, 12, 12);
        world.setBlockState(new BlockPos(x+8,  y+6,  z+7),  leaves);
        this.setBlockMetadataWithNotify(x+8, y+6, z+7, 12, 12);
        world.setBlockState(new BlockPos(x+3,  y+6,  z+8),  leaves);
        this.setBlockMetadataWithNotify(x+3, y+6, z+8, 12, 12);
        world.setBlockState(new BlockPos(x+4,  y+6,  z+8),  leaves);
        this.setBlockMetadataWithNotify(x+4, y+6, z+8, 4, 4);
        world.setBlockState(new BlockPos(x+5,  y+6,  z+8),  leaves);
        this.setBlockMetadataWithNotify(x+5, y+6, z+8, 4, 4);
        world.setBlockState(new BlockPos(x+5,  y+6,  z+9),  leaves);
        this.setBlockMetadataWithNotify(x+5, y+6, z+9, 4, 4);
        world.setBlockState(new BlockPos(x+4,  y+6,  z+10),  leaves);
        this.setBlockMetadataWithNotify(x+4, y+6, z+10, 4, 4);
        world.setBlockState(new BlockPos(x+5,  y+6,  z+10),  leaves);
        this.setBlockMetadataWithNotify(x+5, y+6, z+10, 4, 4);
        world.setBlockState(new BlockPos(x+5,  y+7,  z+0),  leaves);
        this.setBlockMetadataWithNotify(x+5, y+7, z+0, 12, 12);
        world.setBlockState(new BlockPos(x+3,  y+7,  z+1),  leaves);
        this.setBlockMetadataWithNotify(x+3, y+7, z+1, 12, 12);
        world.setBlockState(new BlockPos(x+6,  y+7,  z+1),  leaves);
        this.setBlockMetadataWithNotify(x+6, y+7, z+1, 12, 12);
        world.setBlockState(new BlockPos(x+3,  y+7,  z+2),  leaves);
        this.setBlockMetadataWithNotify(x+3, y+7, z+2, 12, 12);
        world.setBlockState(new BlockPos(x+4,  y+7,  z+2),  leaves);
        this.setBlockMetadataWithNotify(x+4, y+7, z+2, 12, 12);
        world.setBlockState(new BlockPos(x+5,  y+7,  z+2),  this.logBlock);
        this.setBlockMetadataWithNotify(x+5, y+7, z+2, 12, 12);
        world.setBlockState(new BlockPos(x+7,  y+7,  z+2),  leaves);
        this.setBlockMetadataWithNotify(x+7, y+7, z+2, 12, 12);
        world.setBlockState(new BlockPos(x+8,  y+7,  z+2),  leaves);
        this.setBlockMetadataWithNotify(x+8, y+7, z+2, 12, 12);
        world.setBlockState(new BlockPos(x+1,  y+7,  z+3),  leaves);
        this.setBlockMetadataWithNotify(x+1, y+7, z+3, 12, 12);
        world.setBlockState(new BlockPos(x+2,  y+7,  z+3),  leaves);
        this.setBlockMetadataWithNotify(x+2, y+7, z+3, 12, 12);
        world.setBlockState(new BlockPos(x+4,  y+7,  z+3),  leaves);
        this.setBlockMetadataWithNotify(x+4, y+7, z+3, 12, 12);
        world.setBlockState(new BlockPos(x+6,  y+7,  z+3),  leaves);
        this.setBlockMetadataWithNotify(x+6, y+7, z+3, 12, 12);
        world.setBlockState(new BlockPos(x+7,  y+7,  z+3),  leaves);
        this.setBlockMetadataWithNotify(x+7, y+7, z+3, 12, 12);
        world.setBlockState(new BlockPos(x+8,  y+7,  z+3),  leaves);
        this.setBlockMetadataWithNotify(x+8, y+7, z+3, 12, 12);
        world.setBlockState(new BlockPos(x+10,  y+7,  z+3),  leaves);
        this.setBlockMetadataWithNotify(x+10, y+7, z+3, 12, 12);
        world.setBlockState(new BlockPos(x+8,  y+7,  z+4),  leaves);
        this.setBlockMetadataWithNotify(x+8, y+7, z+4, 12, 12);
        world.setBlockState(new BlockPos(x+1,  y+7,  z+5),  leaves);
        this.setBlockMetadataWithNotify(x+1, y+7, z+5, 12, 12);
        world.setBlockState(new BlockPos(x+5,  y+7,  z+5),  this.logBlock);
        this.setBlockMetadataWithNotify(x+5, y+7, z+5, 12, 12);
        world.setBlockState(new BlockPos(x+7,  y+7,  z+5),  leaves);
        this.setBlockMetadataWithNotify(x+7, y+7, z+5, 12, 12);
        world.setBlockState(new BlockPos(x+8,  y+7,  z+5),  leaves);
        this.setBlockMetadataWithNotify(x+8, y+7, z+5, 12, 12);
        world.setBlockState(new BlockPos(x+9,  y+7,  z+5),  leaves);
        this.setBlockMetadataWithNotify(x+9, y+7, z+5, 12, 12);
        world.setBlockState(new BlockPos(x+1,  y+7,  z+6),  leaves);
        this.setBlockMetadataWithNotify(x+1, y+7, z+6, 12, 12);
        world.setBlockState(new BlockPos(x+2,  y+7,  z+6),  leaves);
        this.setBlockMetadataWithNotify(x+2, y+7, z+6, 12, 12);
        world.setBlockState(new BlockPos(x+4,  y+7,  z+6),  this.logBlock);
        this.setBlockMetadataWithNotify(x+4, y+7, z+6, 12, 12);
        world.setBlockState(new BlockPos(x+5,  y+7,  z+6),  leaves);
        this.setBlockMetadataWithNotify(x+5, y+7, z+6, 12, 12);
        world.setBlockState(new BlockPos(x+1,  y+7,  z+7),  leaves);
        this.setBlockMetadataWithNotify(x+1, y+7, z+7, 12, 12);
        world.setBlockState(new BlockPos(x+3,  y+7,  z+7),  leaves);
        this.setBlockMetadataWithNotify(x+3, y+7, z+7, 12, 12);
        world.setBlockState(new BlockPos(x+5,  y+7,  z+7),  leaves);
        this.setBlockMetadataWithNotify(x+5, y+7, z+7, 12, 12);
        world.setBlockState(new BlockPos(x+6,  y+7,  z+7),  this.logBlock);
        this.setBlockMetadataWithNotify(x+6, y+7, z+7, 12, 12);
        world.setBlockState(new BlockPos(x+7,  y+7,  z+7),  leaves);
        this.setBlockMetadataWithNotify(x+7, y+7, z+7, 12, 12);
        world.setBlockState(new BlockPos(x+8,  y+7,  z+7),  leaves);
        this.setBlockMetadataWithNotify(x+8, y+7, z+7, 12, 12);
        world.setBlockState(new BlockPos(x+2,  y+7,  z+8),  leaves);
        this.setBlockMetadataWithNotify(x+2, y+7, z+8, 12, 12);
        world.setBlockState(new BlockPos(x+3,  y+7,  z+8),  leaves);
        this.setBlockMetadataWithNotify(x+3, y+7, z+8, 12, 12);
        world.setBlockState(new BlockPos(x+5,  y+7,  z+8),  leaves);
        this.setBlockMetadataWithNotify(x+5, y+7, z+8, 4, 4);
        world.setBlockState(new BlockPos(x+7,  y+7,  z+8),  leaves);
        this.setBlockMetadataWithNotify(x+7, y+7, z+8, 12, 12);
        world.setBlockState(new BlockPos(x+6,  y+7,  z+9),  leaves);
        this.setBlockMetadataWithNotify(x+6, y+7, z+9, 4, 4);
        world.setBlockState(new BlockPos(x+5,  y+8,  z+0),  leaves);
        this.setBlockMetadataWithNotify(x+5, y+8, z+0, 12, 12);
        world.setBlockState(new BlockPos(x+6,  y+8,  z+0),  leaves);
        this.setBlockMetadataWithNotify(x+6, y+8, z+0, 12, 12);
        world.setBlockState(new BlockPos(x+4,  y+8,  z+1),  leaves);
        this.setBlockMetadataWithNotify(x+4, y+8, z+1, 12, 12);
        world.setBlockState(new BlockPos(x+5,  y+8,  z+1),  leaves);
        this.setBlockMetadataWithNotify(x+5, y+8, z+1, 12, 12);
        world.setBlockState(new BlockPos(x+6,  y+8,  z+1),  leaves);
        this.setBlockMetadataWithNotify(x+6, y+8, z+1, 12, 12);
        world.setBlockState(new BlockPos(x+7,  y+8,  z+1),  leaves);
        this.setBlockMetadataWithNotify(x+7, y+8, z+1, 12, 12);
        world.setBlockState(new BlockPos(x+4,  y+8,  z+2),  leaves);
        this.setBlockMetadataWithNotify(x+4, y+8, z+2, 12, 12);
        world.setBlockState(new BlockPos(x+5,  y+8,  z+2),  this.logBlock);
        this.setBlockMetadataWithNotify(x+5, y+8, z+2, 12, 12);
        world.setBlockState(new BlockPos(x+7,  y+8,  z+2),  leaves);
        this.setBlockMetadataWithNotify(x+7, y+8, z+2, 12, 12);
        world.setBlockState(new BlockPos(x+4,  y+8,  z+3),  leaves);
        this.setBlockMetadataWithNotify(x+4, y+8, z+3, 12, 12);
        world.setBlockState(new BlockPos(x+6,  y+8,  z+3),  leaves);
        this.setBlockMetadataWithNotify(x+6, y+8, z+3, 12, 12);
        world.setBlockState(new BlockPos(x+7,  y+8,  z+3),  leaves);
        this.setBlockMetadataWithNotify(x+7, y+8, z+3, 12, 12);
        world.setBlockState(new BlockPos(x+9,  y+8,  z+3),  leaves);
        this.setBlockMetadataWithNotify(x+9, y+8, z+3, 12, 12);
        world.setBlockState(new BlockPos(x+2,  y+8,  z+4),  leaves);
        this.setBlockMetadataWithNotify(x+2, y+8, z+4, 12, 12);
        world.setBlockState(new BlockPos(x+2,  y+8,  z+5),  leaves);
        this.setBlockMetadataWithNotify(x+2, y+8, z+5, 12, 12);
        world.setBlockState(new BlockPos(x+3,  y+8,  z+5),  leaves);
        this.setBlockMetadataWithNotify(x+3, y+8, z+5, 12, 12);
        world.setBlockState(new BlockPos(x+5,  y+8,  z+5),  this.logBlock);
        this.setBlockMetadataWithNotify(x+5, y+8, z+5, 12, 12);
        world.setBlockState(new BlockPos(x+2,  y+8,  z+6),  leaves);
        this.setBlockMetadataWithNotify(x+2, y+8, z+6, 12, 12);
        world.setBlockState(new BlockPos(x+3,  y+8,  z+6),  leaves);
        this.setBlockMetadataWithNotify(x+3, y+8, z+6, 12, 12);
        world.setBlockState(new BlockPos(x+4,  y+8,  z+6),  leaves);
        this.setBlockMetadataWithNotify(x+4, y+8, z+6, 12, 12);
        world.setBlockState(new BlockPos(x+5,  y+8,  z+6),  leaves);
        this.setBlockMetadataWithNotify(x+5, y+8, z+6, 12, 12);
        world.setBlockState(new BlockPos(x+6,  y+8,  z+6),  leaves);
        this.setBlockMetadataWithNotify(x+6, y+8, z+6, 12, 12);
        world.setBlockState(new BlockPos(x+7,  y+8,  z+6),  leaves);
        this.setBlockMetadataWithNotify(x+7, y+8, z+6, 12, 12);
        world.setBlockState(new BlockPos(x+1,  y+8,  z+7),  leaves);
        this.setBlockMetadataWithNotify(x+1, y+8, z+7, 12, 12);
        world.setBlockState(new BlockPos(x+2,  y+8,  z+7),  leaves);
        this.setBlockMetadataWithNotify(x+2, y+8, z+7, 12, 12);
        world.setBlockState(new BlockPos(x+3,  y+8,  z+7),  this.logBlock);
        this.setBlockMetadataWithNotify(x+3, y+8, z+7, 12, 12);
        world.setBlockState(new BlockPos(x+5,  y+8,  z+7),  leaves);
        this.setBlockMetadataWithNotify(x+5, y+8, z+7, 12, 12);
        world.setBlockState(new BlockPos(x+6,  y+8,  z+7),  leaves);
        this.setBlockMetadataWithNotify(x+6, y+8, z+7, 12, 12);
        world.setBlockState(new BlockPos(x+7,  y+8,  z+7),  this.logBlock);
        this.setBlockMetadataWithNotify(x+7, y+8, z+7, 12, 12);
        world.setBlockState(new BlockPos(x+8,  y+8,  z+7),  leaves);
        this.setBlockMetadataWithNotify(x+8, y+8, z+7, 12, 12);
        world.setBlockState(new BlockPos(x+9,  y+8,  z+7),  leaves);
        this.setBlockMetadataWithNotify(x+9, y+8, z+7, 12, 12);
        world.setBlockState(new BlockPos(x+4,  y+8,  z+8),  leaves);
        this.setBlockMetadataWithNotify(x+4, y+8, z+8, 12, 12);
        world.setBlockState(new BlockPos(x+7,  y+8,  z+8),  leaves);
        this.setBlockMetadataWithNotify(x+7, y+8, z+8, 12, 12);
        world.setBlockState(new BlockPos(x+9,  y+8,  z+8),  leaves);
        this.setBlockMetadataWithNotify(x+9, y+8, z+8, 12, 12);
        world.setBlockState(new BlockPos(x+3,  y+8,  z+9),  leaves);
        this.setBlockMetadataWithNotify(x+3, y+8, z+9, 12, 12);
        world.setBlockState(new BlockPos(x+6,  y+8,  z+9),  leaves);
        this.setBlockMetadataWithNotify(x+6, y+8, z+9, 12, 12);
        world.setBlockState(new BlockPos(x+7,  y+8,  z+9),  leaves);
        this.setBlockMetadataWithNotify(x+7, y+8, z+9, 12, 12);
        world.setBlockState(new BlockPos(x+8,  y+8,  z+9),  leaves);
        this.setBlockMetadataWithNotify(x+8, y+8, z+9, 12, 12);
        world.setBlockState(new BlockPos(x+4,  y+9,  z+1),  leaves);
        this.setBlockMetadataWithNotify(x+4, y+9, z+1, 12, 12);
        world.setBlockState(new BlockPos(x+5,  y+9,  z+1),  leaves);
        this.setBlockMetadataWithNotify(x+5, y+9, z+1, 12, 12);
        world.setBlockState(new BlockPos(x+4,  y+9,  z+2),  leaves);
        this.setBlockMetadataWithNotify(x+4, y+9, z+2, 12, 12);
        world.setBlockState(new BlockPos(x+4,  y+9,  z+3),  leaves);
        this.setBlockMetadataWithNotify(x+4, y+9, z+3, 12, 12);
        world.setBlockState(new BlockPos(x+4,  y+9,  z+4),  leaves);
        this.setBlockMetadataWithNotify(x+4, y+9, z+4, 12, 12);
        world.setBlockState(new BlockPos(x+5,  y+9,  z+4),  leaves);
        this.setBlockMetadataWithNotify(x+5, y+9, z+4, 12, 12);
        world.setBlockState(new BlockPos(x+6,  y+9,  z+4),  leaves);
        this.setBlockMetadataWithNotify(x+6, y+9, z+4, 12, 12);
        world.setBlockState(new BlockPos(x+4,  y+9,  z+5),  leaves);
        this.setBlockMetadataWithNotify(x+4, y+9, z+5, 12, 12);
        world.setBlockState(new BlockPos(x+5,  y+9,  z+5),  this.logBlock);
        this.setBlockMetadataWithNotify(x+5, y+9, z+5, 12, 12);
        world.setBlockState(new BlockPos(x+6,  y+9,  z+5),  leaves);
        this.setBlockMetadataWithNotify(x+6, y+9, z+5, 12, 12);
        world.setBlockState(new BlockPos(x+2,  y+9,  z+6),  leaves);
        this.setBlockMetadataWithNotify(x+2, y+9, z+6, 12, 12);
        world.setBlockState(new BlockPos(x+4,  y+9,  z+6),  leaves);
        this.setBlockMetadataWithNotify(x+4, y+9, z+6, 12, 12);
        world.setBlockState(new BlockPos(x+6,  y+9,  z+6),  leaves);
        this.setBlockMetadataWithNotify(x+6, y+9, z+6, 12, 12);
        world.setBlockState(new BlockPos(x+7,  y+9,  z+6),  leaves);
        this.setBlockMetadataWithNotify(x+7, y+9, z+6, 12, 12);
        world.setBlockState(new BlockPos(x+2,  y+9,  z+7),  leaves);
        this.setBlockMetadataWithNotify(x+2, y+9, z+7, 12, 12);
        world.setBlockState(new BlockPos(x+6,  y+9,  z+7),  leaves);
        this.setBlockMetadataWithNotify(x+6, y+9, z+7, 12, 12);
        world.setBlockState(new BlockPos(x+7,  y+9,  z+7),  leaves);
        this.setBlockMetadataWithNotify(x+7, y+9, z+7, 12, 12);
        world.setBlockState(new BlockPos(x+8,  y+9,  z+7),  leaves);
        this.setBlockMetadataWithNotify(x+8, y+9, z+7, 12, 12);
        world.setBlockState(new BlockPos(x+9,  y+9,  z+7),  leaves);
        this.setBlockMetadataWithNotify(x+9, y+9, z+7, 12, 12);
        world.setBlockState(new BlockPos(x+2,  y+9,  z+8),  leaves);
        this.setBlockMetadataWithNotify(x+2, y+9, z+8, 12, 12);
        world.setBlockState(new BlockPos(x+3,  y+9,  z+8),  leaves);
        this.setBlockMetadataWithNotify(x+3, y+9, z+8, 12, 12);
        world.setBlockState(new BlockPos(x+7,  y+9,  z+8),  leaves);
        this.setBlockMetadataWithNotify(x+7, y+9, z+8, 12, 12);
        world.setBlockState(new BlockPos(x+8,  y+9,  z+8),  leaves);
        this.setBlockMetadataWithNotify(x+8, y+9, z+8, 12, 12);
        world.setBlockState(new BlockPos(x+3,  y+9,  z+9),  leaves);
        this.setBlockMetadataWithNotify(x+3, y+9, z+9, 12, 12);
        world.setBlockState(new BlockPos(x+7,  y+9,  z+9),  leaves);
        this.setBlockMetadataWithNotify(x+7, y+9, z+9, 12, 12);
        world.setBlockState(new BlockPos(x+5,  y+10,  z+1),  leaves);
        this.setBlockMetadataWithNotify(x+5, y+10, z+1, 12, 12);
        world.setBlockState(new BlockPos(x+5,  y+10,  z+2),  leaves);
        this.setBlockMetadataWithNotify(x+5, y+10, z+2, 12, 12);
        world.setBlockState(new BlockPos(x+4,  y+10,  z+3),  leaves);
        this.setBlockMetadataWithNotify(x+4, y+10, z+3, 12, 12);
        world.setBlockState(new BlockPos(x+5,  y+10,  z+3),  leaves);
        this.setBlockMetadataWithNotify(x+5, y+10, z+3, 12, 12);
        world.setBlockState(new BlockPos(x+6,  y+10,  z+3),  leaves);
        this.setBlockMetadataWithNotify(x+6, y+10, z+3, 12, 12);
        world.setBlockState(new BlockPos(x+3,  y+10,  z+4),  leaves);
        this.setBlockMetadataWithNotify(x+3, y+10, z+4, 12, 12);
        world.setBlockState(new BlockPos(x+4,  y+10,  z+5),  leaves);
        this.setBlockMetadataWithNotify(x+4, y+10, z+5, 12, 12);
        world.setBlockState(new BlockPos(x+5,  y+10,  z+5),  this.logBlock);
        world.setBlockState(new BlockPos(x+7,  y+10,  z+5),  leaves);
        this.setBlockMetadataWithNotify(x+7, y+10, z+5, 12, 12);
        world.setBlockState(new BlockPos(x+3,  y+10,  z+6),  leaves);
        this.setBlockMetadataWithNotify(x+3, y+10, z+6, 12, 12);
        world.setBlockState(new BlockPos(x+7,  y+10,  z+6),  leaves);
        this.setBlockMetadataWithNotify(x+7, y+10, z+6, 12, 12);
        world.setBlockState(new BlockPos(x+3,  y+10,  z+7),  leaves);
        this.setBlockMetadataWithNotify(x+3, y+10, z+7, 12, 12);
        world.setBlockState(new BlockPos(x+4,  y+10,  z+7),  leaves);
        this.setBlockMetadataWithNotify(x+4, y+10, z+7, 12, 12);
        world.setBlockState(new BlockPos(x+6,  y+10,  z+7),  leaves);
        this.setBlockMetadataWithNotify(x+6, y+10, z+7, 12, 12);
        world.setBlockState(new BlockPos(x+7,  y+10,  z+7),  leaves);
        this.setBlockMetadataWithNotify(x+7, y+10, z+7, 12, 12);
        world.setBlockState(new BlockPos(x+2,  y+10,  z+8),  leaves);
        this.setBlockMetadataWithNotify(x+2, y+10, z+8, 12, 12);
        world.setBlockState(new BlockPos(x+4,  y+10,  z+8),  leaves);
        this.setBlockMetadataWithNotify(x+4, y+10, z+8, 12, 12);
        world.setBlockState(new BlockPos(x+6,  y+10,  z+8),  leaves);
        this.setBlockMetadataWithNotify(x+6, y+10, z+8, 12, 12);
        world.setBlockState(new BlockPos(x+7,  y+10,  z+8),  leaves);
        this.setBlockMetadataWithNotify(x+7, y+10, z+8, 12, 12);
        world.setBlockState(new BlockPos(x+4,  y+11,  z+3),  leaves);
        this.setBlockMetadataWithNotify(x+4, y+11, z+3, 12, 12);
        world.setBlockState(new BlockPos(x+5,  y+11,  z+3),  leaves);
        this.setBlockMetadataWithNotify(x+5, y+11, z+3, 12, 12);
        world.setBlockState(new BlockPos(x+3,  y+11,  z+5),  leaves);
        this.setBlockMetadataWithNotify(x+3, y+11, z+5, 12, 12);
        world.setBlockState(new BlockPos(x+5,  y+11,  z+5),  this.logBlock);
        world.setBlockState(new BlockPos(x+6,  y+11,  z+5),  leaves);
        this.setBlockMetadataWithNotify(x+6, y+11, z+5, 12, 12);
        world.setBlockState(new BlockPos(x+7,  y+11,  z+5),  leaves);
        this.setBlockMetadataWithNotify(x+7, y+11, z+5, 12, 12);
        world.setBlockState(new BlockPos(x+3,  y+11,  z+6),  leaves);
        this.setBlockMetadataWithNotify(x+3, y+11, z+6, 12, 12);
        world.setBlockState(new BlockPos(x+5,  y+11,  z+6),  leaves);
        this.setBlockMetadataWithNotify(x+5, y+11, z+6, 12, 12);
        world.setBlockState(new BlockPos(x+6,  y+11,  z+6),  leaves);
        this.setBlockMetadataWithNotify(x+6, y+11, z+6, 12, 12);
        world.setBlockState(new BlockPos(x+4,  y+11,  z+7),  leaves);
        this.setBlockMetadataWithNotify(x+4, y+11, z+7, 12, 12);
        world.setBlockState(new BlockPos(x+5,  y+12,  z+3),  leaves);
        this.setBlockMetadataWithNotify(x+5, y+12, z+3, 4, 4);
        world.setBlockState(new BlockPos(x+3,  y+12,  z+4),  leaves);
        this.setBlockMetadataWithNotify(x+3, y+12, z+4, 4, 4);
        world.setBlockState(new BlockPos(x+5,  y+12,  z+4),  leaves);
        this.setBlockMetadataWithNotify(x+5, y+12, z+4, 4, 4);
        world.setBlockState(new BlockPos(x+3,  y+12,  z+5),  leaves);
        this.setBlockMetadataWithNotify(x+3, y+12, z+5, 4, 4);
        world.setBlockState(new BlockPos(x+5,  y+12,  z+5),  leaves);
        this.setBlockMetadataWithNotify(x+5, y+12, z+5, 4, 4);
        world.setBlockState(new BlockPos(x+6,  y+12,  z+5),  leaves);
        this.setBlockMetadataWithNotify(x+6, y+12, z+5, 4, 4);
        world.setBlockState(new BlockPos(x+6,  y+12,  z+6),  leaves);
        this.setBlockMetadataWithNotify(x+6, y+12, z+6, 4, 4);
        world.setBlockState(new BlockPos(x+4,  y+12,  z+7),  leaves);
        this.setBlockMetadataWithNotify(x+4, y+12, z+7, 4, 4);
        world.setBlockState(new BlockPos(x+5,  y+13,  z+5),  leaves);
        this.setBlockMetadataWithNotify(x+5, y+13, z+5, 4, 4);

        return true;
    }

    private void setBlockMetadataWithNotify(int x, int y, int z, int meta1, int meta2)
    {
        
    }
}
